Workbook

Sheet insprint pivot
H1: Insprint Yes/No | I1: Yes | L1: Insprint Yes/No | M1: (Multiple Items) | O1: Module count for Mar 28 insprint
H2: PT Lead | I2: (All) | O2: PT lead | P2: No of US for insprint | Q2: Modules Count | R2: Module names | S2: ETA for pipeline readiness for Prod | T2: Excluded code from
A3: Count of Parent Title | B3: Column Labels | L3: Row Labels | M3: Count of Parent Title | O3: Pirtheebaa | P3: 20 | Q3: 11 | R3: PCAT Dashboard Learn SA Team manager View MMS Details Opportunity Workflow Manage SA Review Approval Transition To Delivery Define Team WRWS Estimators/Calculators | S3: completed
A4: Row Labels | B4: No | C4: Yes | D4: Grand Total | I4: Values | L4: Prompt related testing | M4: 86 | O4: Himanshu | P4: 9 | Q4: 1 | R4: PLD | T4: no
A5: Anand | B5: 5 | C5: 4 | D5: 9 | H5: Insprint Tester | I5: Count of Parent Title | J5: Average of If insprint YES - % of completion | L5: Email functionality | M5: 43 | O5: Shini | P5: 46 | Q5: 2 | R5: BPMS and DCSO | S5: Mar 24 EOD | T5: no
A6: Devika | B6: 26 | D6: 26 | H6: Mary.jacob | I6: 2 | J6: 1 | L6: Excel functionality | M6: 36 | O6: Anand | P6: 4 | Q6: 1 | R6: SI Online | S6: completed
A7: Hajara | B7: 79 | C7: 8 | D7: 87 | H7: sagarika.a.singh | I7: 6 | J7: 1 | L7: IMS BAU | M7: 28 | O7: Nandini | P7: 10 | Q7: 4 | R7: Estimator Calculator Workflow, Value Shaping, Asset Calculator,Automation Calculator | S7: PR pending
A8: Himanshu | B8: 28 | C8: 9 | D8: 37 | H8: pavithra.b.palani | I8: 2 | J8: 1 | L8: PBI report validation | M8: 27 | O8: Hajara | P8: 11 | Q8: 1 | R8: GEN AI | S8: Mar 26 EOD
A9: Jaya | B9: 34 | C9: 8 | D9: 42 | H9: abhijit.a.nandi | I9: 1 | J9: 1 | L9: External Team Integration | M9: 25 | O9: Leena | P9: 21 | Q9: 1 | R9: DSP | S9: In progress
A10: Kavi | B10: 11 | C10: 3 | D10: 14 | H10: v.b.sivakumar | I10: 2 | J10: 1 | L10: PPT/PDF Validation | M10: 21 | O10: Jaya | P10: 6 | Q10: 1 | R10: AMS_OCP_DCTA | S10: completed
A11: Leena | B11: 53 | C11: 21 | D11: 74 | H11: amresh.l.kumar | I11: 1 | J11: 1 | L11: Too many screen validation involved and complex to automate within insprint timeline | M11: 21 | O11: Kavi | P11: 3 | Q11: 2 | R11: SI OCP, DCTA-MMP | S11: completed | T11: pending 2 stories will not be considered . They can be run stand alone by insprint testers
A12: Nandini | B12: 15 | C12: 10 | D12: 25 | H12: navya.majji | I12: 4 | J12: 1 | L12: OBM (GEN AI) Not possible to automate | M12: 18 | O12: Devika | P12: 0 | Q12: 0
A13: Omkar | B13: 1 | D13: 1 | H13: Anitha.a.ramesh | I13: 3 | J13: 1 | L13: Full regression required | M13: 15 | O13: Raji | P13: 0 | Q13: 0
A14: Pirtheebaa | B14: 25 | C14: 18 | D14: 43 | H14: s.af.natarajan | I14: 1 | J14: 1 | L14: BPMS BAU | M14: 13
A15: Rajeswari | B15: 18 | D15: 18 | H15: anusha.goriparthi | I15: 1 | J15: 1 | L15: One time update related | M15: 9
A16: Shini | B16: 18 | C16: 41 | D16: 59 | H16: sathya.senthilkumar | I16: 1 | J16: 1 | L16: UI alignment and Font related | M16: 6
A17: Surbhi | B17: 12 | D17: 12 | H17: arun.thangapandian | I17: 4 | J17: 1 | L17: Story added Last 7 days of release | M17: 5
A18: Vaidheki | B18: 28 | D18: 28 | H18: a.nanditha.uddaraju | I18: 1 | J18: 1 | L18: (blank)
A19: Grand Total | B19: 353 | C19: 122 | D19: 475 | H19: ayush.ad.singh | I19: 1 | J19: 1 | L19: Grand Total | M19: 353
H20: nalluri.vishnupriya | I20: 1 | J20: 1
H21: bandi.sunanda | I21: 1 | J21: 1
H22: nitish.kumar.prusty | I22: 6 | J22: 1
H23: Bhavana.reddy.alla | I23: 2 | J23: 1
H24: r.yuvanitharsana | I24: 1 | J24: 1
H25: divya.belli | I25: 2 | J25: 1
H26: s.manmit.vanarase | I26: 3 | J26: 1
H27: divya.sree.chatla | I27: 1 | J27: 1
H28: sangeetha.pandian | I28: 1 | J28: 1
H29: ganga.m.reddy.padala | I29: 4 | J29: 1
H30: ShaliniB.Pandey | I30: 3 | J30: 1
H31: gayatri.korikana | I31: 3 | J31: 1
... H68: Grand Total | I68: 122 | J68: 0.99590164

Sheet Milestone
A1: User story Freeze Date | B1: Cut off for PT hand over | C1: Cut off for UAT hand over | D1: UAT Completion | E1: Functional Bug closure | F1: Regression | G1: Regression bug Closure | H1: Code Freeze | I1: Initial GNG decision | J1: Final Go/No Go Decision | K1: Final Go-Live
A2: 46078 | B2: 46092 | C2: 46098 | D2: 46105 | E2: 46105 | F2: 19-Mar to 23-Mar | G2: 46106 | H2: 46107 | I2: 46105 | J2: 46108 | K2: 46109

Sheet PT status
A1: Module (TextVerification) | B1: Parent Title | C1: Feature ID | D1: PT Lead | E1: Title | F1: ID | G1: Primary Tester | H1: Secondary Tester | J1: Insprint Tester | K1: Insprint Yes/No | L1: If Insprint NO - Reason | M1: Pre defined No Reason | N1: Complexity | O1: In sprint test case count | P1: If insprint YES - % of completion | Q1: Automated cases generated from GHC | R1: Useful Automated cases from GHC | S1: Tester created automated count (not given by GHC) | T1: Reviwed Final automation count | U1: Coverage for automated test case from GHC% | V1: Accuracy of Automated Test case from GHC% | W1: Test Planning | X1: BA Review | Y1: TFS upload | Z1: PT Status | AA1: Manual Test cases generated from GHC | AB1: Useful Test cases from GHC | AC1: Tester Created test case count | AD1: Reviwed Final Test case count | AE1: Coverage for Manual Test cases from GHC% | AF1: Accuracy for Manual test cases from GHC% | AG1: TFS state | AH1: Passed | AI1: Failed | AJ1: Blocked | AK1: Not Run | AL1: Total | AM1: Execution % | AN1: Pass % | AO1: Comments | AP1: Node Name | AQ1: MPOC
A2: =_xlfn.XLOOKUP(F2,'TFS Details'!F:F,'TFS Details'!D:D) -> Value Shaping | B2: =_xlfn.XLOOKUP(F2,'TFS Details'!F:F,'TFS Details'!A:A) -> Value Shaping –Enhancements | C2: =_xlfn.XLOOKUP(F2,'TFS Details'!F:F,'TFS Details'!E:E) -> 4330994 | D2: Nandini | E2: Value Shaping - As a myISP user, I want to introduce a new role "V2V Configurator" that lands on the dashboard with an action available in the Tools section, so that SMEs can navigate to the Configurator Value Tree link and configure Value Tree templates | F2: 4315785 | G2: Pawan | H2: Yasin | J2: pawan.m.kumar.singh | K2: Yes | N2: Medium | P2: 1 | Q2: 11 | R2: 3 | S2: 0 | T2: 3 | U2: 1 | V2: 0.77 | W2: Completed | X2: Completed | Y2: Completed | Z2: Completed | AA2: 27 | AB2: 21 | AC2: 0 | AD2: 21 | AE2: 1 | AF2: 0.85 | AG2: =_xlfn.XLOOKUP(F2,'TFS Details'!F:F,'TFS Details'!H:H) -> Test Complete | AH2: 21 | AI2: 0 | AJ2: 0 | AK2: 0 | AL2: =SUM(AH2:AK2) -> 21 | AM2: =IF(AH2+AI2=0,0,SUM(AH2:AI2)/AL2) -> 1 | AN2: =IF(AH2=0,0,AH2/(SUM(AH2:AJ2))) -> 1 | AP2: =_xlfn.XLOOKUP(F2,'TFS Details'!F:F,'TFS Details'!I:I) -> NGTransformers | AQ2: =_xlfn.XLOOKUP(AP2,'TFS Details'!I:I,'TFS Details'!AE:AE) -> sowjanya.kari
A3: =_xlfn.XLOOKUP(F3,'TFS Details'!F:F,'TFS Details'!D:D) -> Estimator and Calculator | B3: =_xlfn.XLOOKUP(F3,'TFS Details'!F:F,'TFS Details'!A:A) -> Estimator/Calculator - Expand-Collapse icon Type and Position | C3: =_xlfn.XLOOKUP(F3,'TFS Details'!F:F,'TFS Details'!E:E) -> 4174547 | D3: Nandini | E3: As a myISP user I should be able to see expand and collapse icon in Estimator and calculator screen as per UI revamp standards | F3: 4174533 | G3: Yuvani | H3: Sunanda | J3: bandi.sunanda | K3: Yes | N3: Medium | P3: 1 | Q3: 10 | R3: 1 | S3: 0 | T3: 1 | U3: 0.7 | V3: 1 | W3: Completed | X3: Completed | Y3: Completed | Z3: Completed | AA3: 50 | AB3: 15 | AC3: 0 | AD3: 15 | AE3: 1 | AF3: 1 | AG3: =_xlfn.XLOOKUP(F3,'TFS Details'!F:F,'TFS Details'!H:H) -> Test Complete | AH3: 15 | AI3: 0 | AJ3: 0 | AK3: 0 | AL3: 15 | AM3: =IF(AH3+AI3=0,0,SUM(AH3:AI3)/AL3) -> 1 | AN3: =IF(AH3=0,0,AH3/(SUM(AH3:AJ3))) -> 1 | AO3: bugid :4427095 | AP3: =_xlfn.XLOOKUP(F3,'TFS Details'!F:F,'TFS Details'!I:I) -> TechWarriors | AQ3: =_xlfn.XLOOKUP(AP3,'TFS Details'!I:I,'TFS Details'!AE:AE) -> sowjanya.kari
A4: =_xlfn.XLOOKUP(F4,'TFS Details'!F:F,'TFS Details'!D:D) -> Value Shaping | B4: =_xlfn.XLOOKUP(F4,'TFS Details'!F:F,'TFS Details'!A:A) -> Value Shaping –Enhancements | C4: =_xlfn.XLOOKUP(F4,'TFS Details'!F:F,'TFS Details'!E:E) -> 4330994 | D4: Nandini | E4: Value Shaping -As a myISP User - V2V Configurator - I want to access the Estimators/Calculators in read-only mode and navigate using the fixed breadcrumb path so that I can maintain workflow continuity. | F4: 4364563 | G4: Srilekha | H4: Yasin/Reshmi | J4: guddeti.srilekha | K4: Yes | N4: Complex | P4: 1 | Q4: 22 | R4: 5 | S4: 0 | T4: 5 | U4: 1 | V4: 0.7 | W4: Completed | X4: Completed | Y4: Completed | Z4: Completed | AA4: 50 | AB4: 19 | AC4: 0 | AD4: 19 | AE4: 1 | AF4: 0.7 | AG4: =_xlfn.XLOOKUP(F4,'TFS Details'!F:F,'TFS Details'!H:H) -> Test Complete | AH4: 19 | AI4: 0 | AJ4: 0 | AK4: 0 | AL4: =SUM(AH4:AK4) -> 19 | AM4: =IF(AH4+AI4=0,0,SUM(AH4:AI4)/AL4) -> 1 | AN4: =IF(AH4=0,0,AH4/(SUM(AH4:AJ4))) -> 1 | AP4: =_xlfn.XLOOKUP(F4,'TFS Details'!F:F,'TFS Details'!I:I) -> TechWarriors | AQ4: =_xlfn.XLOOKUP(AP4,'TFS Details'!I:I,'TFS Details'!AE:AE) -> sowjanya.kari
A5: =_xlfn.XLOOKUP(F5,'TFS Details'!F:F,'TFS Details'!D:D) -> Automation Calculator | B5: =_xlfn.XLOOKUP(F5,'TFS Details'!F:F,'TFS Details'!A:A) -> ROI - Automation Calculator - Default Logic | C5: =_xlfn.XLOOKUP(F5,'TFS Details'!F:F,'TFS Details'!E:E) -> 4366165 | D5: Nandini | E5: As a myISP user working on automation ROI section I want AD and AM views to mirror the Productivity Assessment layout (lever/sub-lever grid with Y1H1-Y5H5 periods) and auto-populate values based on PA completion status | F5: 4364929 | G5: Soundhar | H5: Yuvani/Sunanda | K5: No | L5: Data validation is highly complex because the required information is integrated directly from the R2 (PA) screen, to Calc ROI screen ,Specific SG‑based criteria, scenario‑dependent, | M5: Too many screen validation involved and complex to automate within insprint timeline | W5: Completed | X5: Completed | Y5: Completed | Z5: Completed | AA5: 50 | AB5: 28 | AC5: 0 | AD5: 28 | AE5: =AB5/AD5 -> 1 | AF5: 1 | AG5: =_xlfn.XLOOKUP(F5,'TFS Details'!F:F,'TFS Details'!H:H) -> Test Complete | AH5: 28 | AI5: 0 | AJ5: 0 | AK5: 0 | AL5: =SUM(AH5:AK5) -> 28 | AM5: =IF(AH5+AI5=0,0,SUM(AH5:AI5)/AL5) -> 1 | AN5: =IF(AH5=0,0,AH5/(SUM(AH5:AJ5))) -> 1 | AP5: =_xlfn.XLOOKUP(F5,'TFS Details'!F:F,'TFS Details'!I:I) -> CrazyCoders | AQ5: =_xlfn.XLOOKUP(AP5,'TFS Details'!I:I,'TFS Details'!AE:AE) -> nityanand.giri
A6: =_xlfn.XLOOKUP(F6,'TFS Details'!F:F,'TFS Details'!D:D) -> Automation Calculator | B6: =_xlfn.XLOOKUP(F6,'TFS Details'!F:F,'TFS Details'!A:A) -> ROI & Summary (Tab 8) will be as is in automation calculator with Split of GEN AI, Opera and Agentic and Ux upgrade | C6: =_xlfn.XLOOKUP(F6,'TFS Details'!F:F,'TFS Details'!E:E) -> 4405953 | D6: Nandini | E6: As a myISP user, I want all sections in the Summary tab to be displayed as accordions with expand and collapse functionality, So that I can easily navigate and review specific sections without clutter. | F6: 4364996 | G6: Soundhar | H6: Yuvani/Sunanda | J6: s.af.natarajan | K6: Yes | N6: Medium | P6: 1 | Q6: 6 | R6: 1 | S6: 0 | T6: 1 | U6: 0.7 | V6: 0.7 | W6: Completed | X6: Completed | Y6: Completed | Z6: Completed | AA6: 60 | AB6: 29 | AC6: 0 | AD6: 29 | AE6: =AB6/AA6 -> 0.48333333 | AF6: 0.4833 | AG6: =_xlfn.XLOOKUP(F6,'TFS Details'!F:F,'TFS Details'!H:H) -> Test Complete | AH6: 29 | AI6: 0 | AJ6: 0 | AK6: 0 | AL6: =SUM(AH6:AK6) -> 29 | AM6: =IF(AH6+AI6=0,0,SUM(AH6:AI6)/AL6) -> 1 | AN6: =IF(AH6=0,0,AH6/(SUM(AH6:AJ6))) -> 1 | AP6: =_xlfn.XLOOKUP(F6,'TFS Details'!F:F,'TFS Details'!I:I) -> Codeplayers | AQ6: =_xlfn.XLOOKUP(AP6,'TFS Details'!I:I,'TFS Details'!AE:AE) -> nityanand.giri
A7: =_xlfn.XLOOKUP(F7,'TFS Details'!F:F,'TFS Details'!D:D) -> Value Shaping | B7: =_xlfn.XLOOKUP(F7,'TFS Details'!F:F,'TFS Details'!A:A) -> Value Shaping –Enhancements | C7: =_xlfn.XLOOKUP(F7,'TFS Details'!F:F,'TFS Details'!E:E) -> 4330994 | D7: Nandini | E7: Value Shaping � As a myISP user, I want to be navigated to the Configurator Dashboard landing page when I click on the Tools link, so that I can continue creating the Value Tree. | F7: 4373517 | G7: Reshmi | H7: Yasin | J7: reshmi.doddi | K7: Yes | N7: Medium | P7: 1 | Q7: 10 | R7: 1 | S7: 0 | T7: 1 | U7: 0.7 | V7: 0.7 | W7: Completed | X7: Completed | Y7: Completed | Z7: Completed | AA7: 63 | AB7: 14 | AC7: 0 | AD7: 14 | AE7: 1 | AF7: 0.8 | AG7: =_xlfn.XLOOKUP(F7,'TFS Details'!F:F,'TFS Details'!H:H) -> Test Complete | AH7: 14 | AI7: 0 | AJ7: 0 | AK7: 0 | AL7: =SUM(AH7:AK7) -> 14 | AM7: =IF(AH7+AI7=0,0,SUM(AH7:AI7)/AL7) -> 1 | AN7: =IF(AH7=0,0,AH7/(SUM(AH7:AJ7))) -> 1 | AP7: =_xlfn.XLOOKUP(F7,'TFS Details'!F:F,'TFS Details'!I:I) -> Spartans | AQ7: =_xlfn.XLOOKUP(AP7,'TFS Details'!I:I,'TFS Details'!AE:AE) -> nityanand.giri
A8: =_xlfn.XLOOKUP(F8,'TFS Details'!F:F,'TFS Details'!D:D) -> Automation Calculator | B8: =_xlfn.XLOOKUP(F8,'TFS Details'!F:F,'TFS Details'!A:A) -> ROI & Summary (Tab 8) will be as is in automation calculator with Split of GEN AI, Opera and Agentic and Ux upgrade | C8: =_xlfn.XLOOKUP(F8,'TFS Details'!F:F,'TFS Details'!E:E) -> 4405953 | D8: Nandini | E8: As a myISP user I want the revamped Summary screen to include an overall summary and a ROI section that is a replica of the ROI screen with all sections So that the Summary PDF download contains all newly introduced revamp changes without missing data. | F8: 4373570 | G8: Sunanda | H8: Yuvani | K8: No | L8: Data validation is highly complex because the required information is integrated directly from the R2 (PA) screen, to Calc ROI screen ,Specific SG‑based criteria, scenario‑dependent, | M8: Too many screen validation involved and complex to automate within insprint timeline | W8: Completed | X8: Completed | Y8: Completed | Z8: Completed | AA8: 8 | AB8: 8 | AC8: 3 | AD8: 11 | AE8: 0.72 | AF8: 1 | AG8: =_xlfn.XLOOKUP(F8,'TFS Details'!F:F,'TFS Details'!H:H) -> Test Complete | AH8: 11 | AI8: 0 | AJ8: 0 | AK8: 0 | AL8: =SUM(AH8:AK8) -> 11 | AM8: =IF(AH8+AI8=0,0,SUM(AH8:AI8)/AL8) -> 1 | AN8: =IF(AH8=0,0,AH8/(SUM(AH8:AJ8))) -> 1 | AP8: =_xlfn.XLOOKUP(F8,'TFS Details'!F:F,'TFS Details'!I:I) -> Codeplayers | AQ8: =_xlfn.XLOOKUP(AP8,'TFS Details'!I:I,'TFS Details'!AE:AE) -> nityanand.giri
A9: =_xlfn.XLOOKUP(F9,'TFS Details'!F:F,'TFS Details'!D:D) -> Value Shaping | B9: =_xlfn.XLOOKUP(F9,'TFS Details'!F:F,'TFS Details'!A:A) -> Value Shaping –Enhancements | C9: =_xlfn.XLOOKUP(F9,'TFS Details'!F:F,'TFS Details'!E:E) -> 4330994 | D9: Nandini | E9: Value Shaping - [SVP] As a myISP user, I want SOP Input values linked in configurator link to be automatically populated for KPIs across a value tree , so that usability is improved and manual effort is reduced. | F9: 4376380 | G9: Yasin | H9: Reshmi | J9: shaik.yasin | K9: Yes | N9: Complex | P9: 1 | Q9: 11 | R9: 5 | W9: Completed | X9: Completed | Y9: Completed | Z9: In Progress | AA9: 10 | AB9: 7 | AC9: 4 | AD9: 11 | AE9: 0.65 | AF9: 0.7 | AG9: =_xlfn.XLOOKUP(F9,'TFS Details'!F:F,'TFS Details'!H:H) -> UAT In Test | AH9: 10 | AI9: 1 | AJ9: 0 | AK9: 0 | AL9: =SUM(AH9:AK9) -> 11 | AM9: =IF(AH9+AI9=0,0,SUM(AH9:AI9)/AL9) -> 1 | AN9: =IF(AH9=0,0,AH9/(SUM(AH9:AJ9))) -> 0.90909091 | AP9: =_xlfn.XLOOKUP(F9,'TFS Details'!F:F,'TFS Details'!I:I) -> Spartans | AQ9: =_xlfn.XLOOKUP(AP9,'TFS Details'!I:I,'TFS Details'!AE:AE) -> nityanand.giri
A10: =_xlfn.XLOOKUP(F10,'TFS Details'!F:F,'TFS Details'!D:D) -> Automation Calculator | B10: =_xlfn.XLOOKUP(F10,'TFS Details'!F:F,'TFS Details'!A:A) -> ROI - Automation Calculator - Default Logic | C10: =_xlfn.XLOOKUP(F10,'TFS Details'!F:F,'TFS Details'!E:E) -> 4366165 | D10: Nandini | E10: As a myISP user, I want the system to automatically calculate AD and AM Assessment productivity values using a default tech stack split of 50% Custom and 50% Package in the ROI tab | F10: 4362465 | G10: Soundhar | H10: Sunanda | K10: No | L10: ramya | M10: Too many screen validation involved and complex to automate within insprint timeline | W10: Completed | X10: Completed | Y10: Completed | Z10: Completed | AA10: 60 | AB10: 32 | AC10: 6 | AD10: 36 | AE10: 0.73 | AF10: 0.63 | AG10: =_xlfn.XLOOKUP(F10,'TFS Details'!F:F,'TFS Details'!H:H) -> Test Complete | AH10: 38 | AI10: 0 | AJ10: 0 | AK10: 0 | AL10: 38 | AM10: =IF(AH10+AI10=0,0,SUM(AH10:AI10)/AL10) -> 1 | AN10: =IF(AH10=0,0,AH10/(SUM(AH10:AJ10))) -> 1 | AP10: =_xlfn.XLOOKUP(F10,'TFS Details'!F:F,'TFS Details'!I:I) -> CrazyCoders | AQ10: =_xlfn.XLOOKUP(AP10,'TFS Details'!I:I,'TFS Details'!AE:AE) -> nityanand.giri
A11: =_xlfn.XLOOKUP(F11,'TFS Details'!F:F,'TFS Details'!D:D) -> Automation Calculator | B11: =_xlfn.XLOOKUP(F11,'TFS Details'!F:F,'TFS Details'!A:A) -> ROI & Summary (Tab 8) will be as is in automation calculator with Split of GEN AI, Opera and Agentic and Ux upgrade | C11: =_xlfn.XLOOKUP(F11,'TFS Details'!F:F,'TFS Details'!E:E) -> 4405953 | D11: Nandini | E11: As a myISP user, I want to view a new Overall Summary section that consolidates key cost metrics, So that I can quickly review the overall financial view before validation or submission. | F11: 4362711 | G11: Rohitha | H11: Yuvani | K11: No | L11: Data validation is highly complex because the required information is integrated directly from the R2 (PA) screen, to Calc ROI screen ,Specific SG‑based criteria, scenario‑dependent, | M11: Too many screen validation involved and complex to automate within insprint timeline | W11: Completed | X11: Completed | Y11: Completed | Z11: Completed | AA11: 8 | AB11: 7 | AC11: 4 | AD11: 11 | AE11: 0.73 | AF11: 0.97 | AG11: =_xlfn.XLOOKUP(F11,'TFS Details'!F:F,'TFS Details'!H:H) -> Test Complete | AH11: 11 | AI11: 0 | AJ11: 0 | AK11: 0 | AL11: =SUM(AH11:AK11) -> 11 | AM11: =IF(AH11+AI11=0,0,SUM(AH11:AI11)/AL11) -> 1 | AN11: =IF(AH11=0,0,AH11/(SUM(AH11:AJ11))) -> 1 | AP11: =_xlfn.XLOOKUP(F11,'TFS Details'!F:F,'TFS Details'!I:I) -> Codeplayers | AQ11: =_xlfn.XLOOKUP(AP11,'TFS Details'!I:I,'TFS Details'!AE:AE) -> nityanand.giri
A12: =_xlfn.XLOOKUP(F12,'TFS Details'!F:F,'TFS Details'!D:D) -> Automation Calculator | B12: =_xlfn.XLOOKUP(F12,'TFS Details'!F:F,'TFS Details'!A:A) -> ROI - Automation Calculator - Default Logic | C12: =_xlfn.XLOOKUP(F12,'TFS Details'!F:F,'TFS Details'!E:E) -> 4366165 | D12: Nandini | E12: As a myISP user viewing the ROI screen in the Automation Calculator I want to see Agentic AI productivity as a separate lever alongside Opera and Gen AI with a combined yearly breakdown view | F12: 4363958 | G12: Yuvani | H12: Sunanda | K12: No | L12: Data validation is highly complex because the required information is integrated directly from the R2 (PA) screen, to Calc ROI screen ,Specific SG‑based criteria, scenario‑dependent, | M12: Too many screen validation involved and complex to automate within insprint timeline | W12: Completed | X12: Completed | Y12: Completed | Z12: Completed | AA12: 60 | AB12: 27 | AC12: 5 | AD12: 32 | AE12: 0.53 | AF12: 0.45 | AG12: =_xlfn.XLOOKUP(F12,'TFS Details'!F:F,'TFS Details'!H:H) -> Test Complete | AH12: 27 | AI12: 0 | AJ12: 0 | AK12: 0 | AL12: =SUM(AH12:AK12) -> 27 | AM12: =IF(AH12+AI12=0,0,SUM(AH12:AI12)/AL12) -> 1 | AN12: =IF(AH12=0,0,AH12/(SUM(AH12:AJ12))) -> 1 | AP12: =_xlfn.XLOOKUP(F12,'TFS Details'!F:F,'TFS Details'!I:I) -> CrazyCoders | AQ12: =_xlfn.XLOOKUP(AP12,'TFS Details'!I:I,'TFS Details'!AE:AE) -> nityanand.giri
A13: =_xlfn.XLOOKUP(F13,'TFS Details'!F:F,'TFS Details'!D:D) -> Value Shaping | B13: =_xlfn.XLOOKUP(F13,'TFS Details'!F:F,'TFS Details'!A:A) -> Value Shaping –Enhancements | C13: =_xlfn.XLOOKUP(F13,'TFS Details'!F:F,'TFS Details'!E:E) -> 4330994 | D13: Nandini | E13: Value Shaping - As a myISP User - V2V Configurator - I want to access the Value Shaping tile in read-only mode and navigate using the fixed breadcrumb path so that I can maintain workflow continuity. | F13: 4364558 | G13: Samreen | H13: Yasin/Reshmi | J13: mohammad.samreen | K13: Yes | N13: Medium | P13: 1 | Q13: 17 | R13: 10 | S13: 0 | T13: 10 | U13: 1 | V13: 0.8 | W13: Completed | X13: Completed | Y13: Completed | Z13: Completed | AA13: 50 | AB13: 17 | AC13: 0 | AD13: 17 | AE13: 1 | AF13: 0.7 | AG13: =_xlfn.XLOOKUP(F13,'TFS Details'!F:F,'TFS Details'!H:H) -> Test Complete | AH13: 17 | AI13: 0 | AJ13: 0 | AK13: 0 | AL13: =SUM(AH13:AK13) -> 17 | AM13: =IF(AH13+AI13=0,0,SUM(AH13:AI13)/AL13) -> 1 | AN13: =IF(AH13=0,0,AH13/(SUM(AH13:AJ13))) -> 1 | AP13: =_xlfn.XLOOKUP(F13,'TFS Details'!F:F,'TFS Details'!I:I) -> Spartans | AQ13: =_xlfn.XLOOKUP(AP13,'TFS Details'!I:I,'TFS Details'!AE:AE) -> nityanand.giri
A14: =_xlfn.XLOOKUP(F14,'TFS Details'!F:F,'TFS Details'!D:D) -> Automation Calculator | B14: =_xlfn.XLOOKUP(F14,'TFS Details'!F:F,'TFS Details'!A:A) -> ROI - Automation Calculator - Default Logic | C14: =_xlfn.XLOOKUP(F14,'TFS Details'!F:F,'TFS Details'!E:E) -> 4366165 | D14: Nandini | E14: As a myISP user I want to see a clear system message when Productivity Assessment is not submitted for an eligible deal So that I understand that default productivity values are being applied | F14: 4361791 | G14: Sunanda | H14: Rohitha | K14: No | L14: Data validation is highly complex because the required information is integrated directly from the R2 (PA) screen, to Calc ROI screen ,Specific SG‑based criteria, scenario‑dependent, | M14: Too many screen validation involved and complex to automate within insprint timeline | W14: Completed | X14: Completed | Y14: Completed | Z14: Completed | AA14: 22 | AB14: 17 | AC14: 0 | AD14: 17 | AE14: =AB14/AA14 -> 0.77272727 | AF14: 0.77 | AG14: =_xlfn.XLOOKUP(F14,'TFS Details'!F:F,'TFS Details'!H:H) -> Test Complete | AH14: 17 | AI14: 0 | AJ14: 0 | AK14: 0 | AL14: =SUM(AH14:AK14) -> 17 | AM14: =IF(AH14+AI14=0,0,SUM(AH14:AI14)/AL14) -> 1 | AN14: =IF(AH14=0,0,AH14/(SUM(AH14:AJ14))) -> 1 | AP14: =_xlfn.XLOOKUP(F14,'TFS Details'!F:F,'TFS Details'!I:I) -> CrazyCoders | AQ14: =_xlfn.XLOOKUP(AP14,'TFS Details'!I:I,'TFS Details'!AE:AE) -> nityanand.giri
A15: =_xlfn.XLOOKUP(F15,'TFS Details'!F:F,'TFS Details'!D:D) -> Value Shaping | B15: =_xlfn.XLOOKUP(F15,'TFS Details'!F:F,'TFS Details'!A:A) -> Value Shaping –Enhancements | C15: =_xlfn.XLOOKUP(F15,'TFS Details'!F:F,'TFS Details'!E:E) -> 4330994 | D15: Nandini | E15: Value Shaping - As a myISP user, I should be able to download output (Benchmark and size of prize View) as PDF from summary screen of SVP page, so that it can be used for other purposes | F15: 4318918 | G15: Srilekha | H15: Yasin/Reshmi | K15: No | L15: cannot automate, verifying downloaded PDF sheet data with UI | M15: PPT/PDF Validation | W15: Completed | X15: Completed | Y15: Completed | Z15: Completed | AA15: 50 | AB15: 23 | AC15: 0 | AD15: 23 | AE15: 1 | AF15: 0.7 | AG15: =_xlfn.XLOOKUP(F15,'TFS Details'!F:F,'TFS Details'!H:H) -> UAT In Test | AH15: 23 | AI15: 0 | AJ15: 0 | AK15: 0 | AL15: =SUM(AH15:AK15) -> 23 | AM15: =IF(AH15+AI15=0,0,SUM(AH15:AI15)/AL15) -> 1 | AN15: =IF(AH15=0,0,AH15/(SUM(AH15:AJ15))) -> 1 | AP15: =_xlfn.XLOOKUP(F15,'TFS Details'!F:F,'TFS Details'!I:I) -> Spartans | AQ15: =_xlfn.XLOOKUP(AP15,'TFS Details'!I:I,'TFS Details'!AE:AE) -> nityanand.giri
A16: =_xlfn.XLOOKUP(F16,'TFS Details'!F:F,'TFS Details'!D:D) -> Calculator | B16: =_xlfn.XLOOKUP(F16,'TFS Details'!F:F,'TFS Details'!A:A) -> Asset Calculator - Asset accordions to be added in Asset Catalog | C16: =_xlfn.XLOOKUP(F16,'TFS Details'!F:F,'TFS Details'!E:E) -> 4331001 | D16: Nandini | E16: [Asset Calculator] - As a myISP User I want to implement Platform Asset Blueprint � Oracle & Platform Asset Blueprint � SAP Assets as taggable assets so that it aligns with business changes and the new design reframe | F16: 4328732 | G16: Yuvani | H16: Yuvani/Soundhar | J16: r.yuvanitharsana | K16: Yes | N16: Complex | P16: 1 | Q16: 19 | R16: 1 | S16: 0 | T16: 1 | U16: 0.75 | V16: 0.75 | W16: Completed | X16: Completed | Y16: Completed | Z16: Completed | AA16: 90 | AB16: 28 | AC16: 3 | AD16: 31 | AE16: =AB16/AD16 -> 0.90322581 | AF16: 0.95 | AG16: =_xlfn.XLOOKUP(F16,'TFS Details'!F:F,'TFS Details'!H:H) -> Test Complete | AH16: 31 | AI16: 0 | AJ16: 0 | AK16: 0 | AL16: =SUM(AH16:AK16) -> 31 | AM16: =IF(AH16+AI16=0,0,SUM(AH16:AI16)/AL16) -> 1 | AN16: =IF(AH16=0,0,AH16/(SUM(AH16:AJ16))) -> 1 | AP16: =_xlfn.XLOOKUP(F16,'TFS Details'!F:F,'TFS Details'!I:I) -> TitansPlus | AQ16: =_xlfn.XLOOKUP(AP16,'TFS Details'!I:I,'TFS Details'!AE:AE) -> nityanand.giri
A17: =_xlfn.XLOOKUP(F17,'TFS Details'!F:F,'TFS Details'!D:D) -> Value Shaping | B17: =_xlfn.XLOOKUP(F17,'TFS Details'!F:F,'TFS Details'!A:A) -> Value Shaping –Enhancements | C17: =_xlfn.XLOOKUP(F17,'TFS Details'!F:F,'TFS Details'!E:E) -> 4330994 | D17: Nandini | E17: Value Shaping - As a myISP user, I should be able to download output (Global View) as PDF from summary screen of SVP page, so that it can be used for other purposes | F17: 4100102 | G17: Reshmi | H17: Yasin | K17: No | L17: cannot automate, verifying downloaded PDF data with UI | M17: PPT/PDF Validation | W17: Completed | X17: Completed | Y17: Completed | Z17: Completed | AA17: 97 | AB17: 21 | AC17: 0 | AD17: 21 | AE17: 1 | AF17: 0.8 | AG17: =_xlfn.XLOOKUP(F17,'TFS Details'!F:F,'TFS Details'!H:H) -> Test Complete | AH17: 21 | AI17: 0 | AJ17: 0 | AK17: 0 | AL17: =SUM(AH17:AK17) -> 21 | AM17: =IF(AH17+AI17=0,0,SUM(AH17:AI17)/AL17) -> 1 | AN17: =IF(AH17=0,0,AH17/(SUM(AH17:AJ17))) -> 1 | AP17: =_xlfn.XLOOKUP(F17,'TFS Details'!F:F,'TFS Details'!I:I) -> Spartans | AQ17: =_xlfn.XLOOKUP(AP17,'TFS Details'!I:I,'TFS Details'!AE:AE) -> nityanand.giri
A18: =_xlfn.XLOOKUP(F18,'TFS Details'!F:F,'TFS Details'!D:D) -> Value Shaping | B18: =_xlfn.XLOOKUP(F18,'TFS Details'!F:F,'TFS Details'!A:A) -> Value Shaping –Enhancements | C18: =_xlfn.XLOOKUP(F18,'TFS Details'!F:F,'TFS Details'!E:E) -> 4330994 | D18: Nandini | E18: Value Shaping - As a myISP user, I want to export the current benchmark table data So that I can perform bulk updates efficiently while preserving data integrity and validation rules. | F18: 4368404 | G18: Pawan | H18: Yasin/Reshmi | K18: No | L18: cannot automate, verifying downloaded PDF sheet data with UI | M18: PPT/PDF Validation | W18: Completed | X18: Completed | Y18: Completed | Z18: Completed | AA18: 70 | AB18: 48 | AC18: 0 | AD18: 48 | AE18: 1 | AF18: 0.85 | AG18: UAT In Test | AH18: 48 | AI18: 0 | AJ18: 0 | AK18: 0 | AL18: 48 | AM18: =IF(AH18+AI18=0,0,SUM(AH18:AI18)/AL18) -> 1 | AN18: =IF(AH18=0,0,AH18/(SUM(AH18:AJ18))) -> 1 | AP18: =_xlfn.XLOOKUP(F18,'TFS Details'!F:F,'TFS Details'!I:I) -> Spartans | AQ18: =_xlfn.XLOOKUP(AP18,'TFS Details'!I:I,'TFS Details'!AE:AE) -> nityanand.giri
A19: =_xlfn.XLOOKUP(F19,'TFS Details'!F:F,'TFS Details'!D:D) -> Value Shaping | B19: =_xlfn.XLOOKUP(F19,'TFS Details'!F:F,'TFS Details'!A:A) -> Value Shaping –Enhancements | C19: =_xlfn.XLOOKUP(F19,'TFS Details'!F:F,'TFS Details'!E:E) -> 4330994 | D19: Nandini | E19: Value Shaping - As a myISP user, I want to enable import benchmark functionality so that I can import updated records back into Configurator Link for SA to update and modify the data efficiently based on changing requirements. | F19: 4368405 | G19: Yasin | H19: Reshmi | K19: No | L19: cannot automate, verifying downloaded excel sheet data with UI | M19: Excel functionality | W19: Completed | X19: Completed | Y19: Completed | Z19: Completed | AA19: 10 | AB19: 8 | AC19: 20 | AD19: 28 | AE19: =AB19/AD19 -> 0.28571429 | AF19: 0.6 | AG19: =_xlfn.XLOOKUP(F19,'TFS Details'!F:F,'TFS Details'!H:H) -> UAT In Test | AH19: 28 | AI19: 0 | AJ19: 0 | AK19: 0 | AL19: =SUM(AH19:AK19) -> 28 | AM19: =IF(AH19+AI19=0,0,SUM(AH19:AI19)/AL19) -> 1 | AN19: =IF(AH19=0,0,AH19/(SUM(AH19:AJ19))) -> 1 | AP19: =_xlfn.XLOOKUP(F19,'TFS Details'!F:F,'TFS Details'!I:I) -> Spartans | AQ19: =_xlfn.XLOOKUP(AP19,'TFS Details'!I:I,'TFS Details'!AE:AE) -> nityanand.giri
A20: =_xlfn.XLOOKUP(F20,'TFS Details'!F:F,'TFS Details'!D:D) -> Value Shaping | B20: =_xlfn.XLOOKUP(F20,'TFS Details'!F:F,'TFS Details'!A:A) -> Value Shaping –Enhancements | C20: =_xlfn.XLOOKUP(F20,'TFS Details'!F:F,'TFS Details'!E:E) -> 4330994 | D20: Nandini | E20: Value Shaping - [Configurator Link ]As a myISP user, I want to link the SOP inputs with client baseline and benchmark values so that user configuring value tree is improved | F20: 4368508 | G20: Yasin | H20: Reshmi | J20: shaik.yasin | K20: Yes | N20: Medium | P20: 1 | Q20: 10 | R20: 4 | W20: Completed | X20: Completed | Y20: Completed | Z20: In Progress | AA20: 10 | AB20: 10 | AC20: 0 | AD20: 10 | AE20: 1 | AF20: 1 | AG20: =_xlfn.XLOOKUP(F20,'TFS Details'!F:F,'TFS Details'!H:H) -> UAT In Test | AH20: 8 | AI20: 2 | AJ20: 0 | AK20: 0 | AL20: =SUM(AH20:AK20) -> 10 | AM20: =IF(AH20+AI20=0,0,SUM(AH20:AI20)/AL20) -> 1 | AN20: =IF(AH20=0,0,AH20/(SUM(AH20:AJ20))) -> 0.8 | AP20: =_xlfn.XLOOKUP(F20,'TFS Details'!F:F,'TFS Details'!I:I) -> Spartans | AQ20: =_xlfn.XLOOKUP(AP20,'TFS Details'!I:I,'TFS Details'!AE:AE) -> nityanand.giri
A21: =_xlfn.XLOOKUP(F21,'TFS Details'!F:F,'TFS Details'!D:D) -> Asset Calculator | B21: =_xlfn.XLOOKUP(F21,'TFS Details'!F:F,'TFS Details'!A:A) -> Asset Calculator - Asset accordions to be added in Asset Catalog | C21: =_xlfn.XLOOKUP(F21,'TFS Details'!F:F,'TFS Details'!E:E) -> 4331001 | D21: Nandini | E21: [Asset Calculator] As a myISP ,I want to implement Other Assets Accordion in Asset Catalog as taggable asset so that Asset Calculator can have this as taggable asset | F21: 4372603 | G21: Soundhar | H21: Yuvani/Sunanda | K21: No | L21: This US needs to be validated for all SG and we will have to cover multiple combinations to achieve 100% automation which is very complex | M21: Too many screen validation involved and complex to automate within insprint timeline | W21: Completed | X21: Completed | Y21: Completed | Z21: Completed | AA21: 80 | AB21: 25 | AC21: 6 | AD21: 31 | AE21: 0.8 | AF21: 0.85 | AG21: =_xlfn.XLOOKUP(F21,'TFS Details'!F:F,'TFS Details'!H:H) -> Test Complete | AH21: 31 | AI21: 0 | AJ21: 0 | AK21: 0 | AL21: =SUM(AH21:AK21) -> 31 | AM21: =IF(AH21+AI21=0,0,SUM(AH21:AI21)/AL21) -> 1 | AN21: =IF(AH21=0,0,AH21/(SUM(AH21:AJ21))) -> 1 | AP21: =_xlfn.XLOOKUP(F21,'TFS Details'!F:F,'TFS Details'!I:I) -> TitansPlus | AQ21: =_xlfn.XLOOKUP(AP21,'TFS Details'!I:I,'TFS Details'!AE:AE) -> nityanand.giri
A22: =_xlfn.XLOOKUP(F22,'TFS Details'!F:F,'TFS Details'!D:D) -> Differentiation | B22: =_xlfn.XLOOKUP(F22,'TFS Details'!F:F,'TFS Details'!A:A) -> Differentiation asset de-tagging- March | C22: =_xlfn.XLOOKUP(F22,'TFS Details'!F:F,'TFS Details'!E:E) -> 4352723 | D22: Nandini | E22: As a myIntegrated Solution Planner User, I want to de-tag the GenWizard Assets and Platforms under differentiation in SI so that acceptance criteria are achieved. | F22: 4352719 | G22: Yuvani | H22: Sunanda/Soundhar | K22: No | L22: Need to compare the data in two excel file | M22: Excel functionality | W22: Completed | X22: Completed | Y22: Completed | Z22: Completed | AA22: 40 | AB22: 10 | AC22: 0 | AD22: 10 | AE22: 1 | AF22: 1 | AG22: =_xlfn.XLOOKUP(F22,'TFS Details'!F:F,'TFS Details'!H:H) -> Test Complete | AH22: 10 | AI22: 0 | AJ22: 0 | AK22: 0 | AL22: 10 | AM22: =IF(AH22+AI22=0,0,SUM(AH22:AI22)/AL22) -> 1 | AN22: =IF(AH22=0,0,AH22/(SUM(AH22:AJ22))) -> 1 | AP22: =_xlfn.XLOOKUP(F22,'TFS Details'!F:F,'TFS Details'!I:I) -> TechCoders | AQ22: =_xlfn.XLOOKUP(AP22,'TFS Details'!I:I,'TFS Details'!AE:AE) -> Francis.Deepak
A23: =_xlfn.XLOOKUP(F23,'TFS Details'!F:F,'TFS Details'!D:D) -> Value Shaping | B23: =_xlfn.XLOOKUP(F23,'TFS Details'!F:F,'TFS Details'!A:A) -> Value Shaping –Enhancements | C23: =_xlfn.XLOOKUP(F23,'TFS Details'!F:F,'TFS Details'!E:E) -> 4330994 | D23: Nandini | E23: Value Shaping - (MFHost)As a myISP User - Configurator V2V - I want to access all myISP screens as per SME role, read-only mode and navigate using the fixed breadcrumb path so that I can maintain workflow continuity | F23: 4381608 | G23: Samreen | H23: Yasin/Reshmi | K23: No | L23: This US includes Navigation to all tiles | M23: Too many screen validation involved and complex to automate within insprint timeline | N23: Complex | W23: Completed | X23: Completed | Y23: Completed | Z23: Completed | AA23: 50 | AB23: 16 | AC23: 0 | AD23: 16 | AE23: 1 | AF23: 0.7 | AG23: PT In Test | AH23: 16 | AI23: 0 | AJ23: 0 | AK23: 0 | AL23: =SUM(AH23:AK23) -> 16 | AM23: =IF(AH23+AI23=0,0,SUM(AH23:AI23)/AL23) -> 1 | AN23: =IF(AH23=0,0,AH23/(SUM(AH23:AJ23))) -> 1 | AP23: =_xlfn.XLOOKUP(F23,'TFS Details'!F:F,'TFS Details'!I:I) -> MYISP_Revamp_UI | AQ23: =_xlfn.XLOOKUP(AP23,'TFS Details'!I:I,'TFS Details'!AE:AE) -> vikrant.r.mohite
A24: =_xlfn.XLOOKUP(F24,'TFS Details'!F:F,'TFS Details'!D:D) -> Automation Calculator | B24: =_xlfn.XLOOKUP(F24,'TFS Details'!F:F,'TFS Details'!A:A) -> ROI & Summary (Tab 8) will be as is in automation calculator with Split of GEN AI, Opera and Agentic and Ux upgrade | C24: =_xlfn.XLOOKUP(F24,'TFS Details'!F:F,'TFS Details'!E:E) -> 4405953 | D24: Nandini | E24: As a myISP user, I want the ROI section in the Summary tab to include all subsections from the ROI screen, So that I can review Agentic, Opera AI, and Gen AI percentage breakdowns across years and contract duration, along with the graphical representation | F24: 4365001 | G24: Sunanda | H24: Yuvani/Soundhar | K24: No | L24: Data validation is highly complex because the required information is integrated directly from the R2 (PA) screen, to Calc ROI screen ,Specific SG‑based criteria, scenario‑dependent, | M24: Too many screen validation involved and complex to automate within insprint timeline | W24: Completed | X24: Completed | Y24: Completed | Z24: Completed | AA24: 22 | AB24: 21 | AC24: 1 | AD24: 22 | AE24: 0.9 | AF24: 0.95 | AG24: =_xlfn.XLOOKUP(F24,'TFS Details'!F:F,'TFS Details'!H:H) -> Test Complete | AH24: 22 | AI24: 0 | AJ24: 0 | AK24: 0 | AL24: =SUM(AH24:AK24) -> 22 | AM24: =IF(AH24+AI24=0,0,SUM(AH24:AI24)/AL24) -> 1 | AN24: =IF(AH24=0,0,AH24/(SUM(AH24:AJ24))) -> 1 | AP24: =_xlfn.XLOOKUP(F24,'TFS Details'!F:F,'TFS Details'!I:I) -> Codeplayers | AQ24: =_xlfn.XLOOKUP(AP24,'TFS Details'!I:I,'TFS Details'!AE:AE) -> nityanand.giri
A25: =_xlfn.XLOOKUP(F25,'TFS Details'!F:F,'TFS Details'!D:D) -> Role Rename | B25: =_xlfn.XLOOKUP(F25,'TFS Details'!F:F,'TFS Details'!A:A) -> March Release NextGen Enhancements | C25: =_xlfn.XLOOKUP(F25,'TFS Details'!F:F,'TFS Details'!E:E) -> 4365826 | D25: Nandini | E25: Impact Check: As a Myisp user, I want the role "Enterprise SA" to be renamed to "Market Maker ESA" in myISP So that the role name clearly reflects the Market Make ESA in Value Shaping module. | F25: 4391344 | G25: Reshmi | H25: Yasin | K25: No | L25: Roles are getting deactivated which cant be automatable | M25: Full regression required | W25: Completed | X25: Completed | Y25: Completed | Z25: Completed | AA25: 65 | AB25: 5 | AC25: 0 | AD25: 5 | AE25: 1 | AF25: 0.8 | AG25: =_xlfn.XLOOKUP(F25,'TFS Details'!F:F,'TFS Details'!H:H) -> Test Complete | AH25: 5 | AI25: 0 | AJ25: 0 | AK25: 0 | AL25: =SUM(AH25:AK25) -> 5 | AM25: =IF(AH25+AI25=0,0,SUM(AH25:AI25)/AL25) -> 1 | AN25: =IF(AH25=0,0,AH25/(SUM(AH25:AJ25))) -> 1 | AP25: =_xlfn.XLOOKUP(F25,'TFS Details'!F:F,'TFS Details'!I:I) -> Spartans | AQ25: =_xlfn.XLOOKUP(AP25,'TFS Details'!I:I,'TFS Details'!AE:AE) -> nityanand.giri
A26: =_xlfn.XLOOKUP(F26,'TFS Details'!F:F,'TFS Details'!D:D) -> Advisory SA - Song | B26: =_xlfn.XLOOKUP(F26,'TFS Details'!F:F,'TFS Details'!A:A) -> PLD - Advisory SA Role | C26: =_xlfn.XLOOKUP(F26,'TFS Details'!F:F,'TFS Details'!E:E) -> 4386527 | D26: Nandini | E26: As an Advisory song SA, I want to access the Value Shaping tile in read-only mode so that I can maintain and view workflow continuity. | F26: 4373065 | G26: Srilekha | H26: Yasin | J26: guddeti.srilekha | K26: Yes | N26: Complex | P26: 1 | Q26: 25 | R26: 6 | S26: 0 | T26: 6 | U26: 1 | V26: 0.7 | W26: Completed | X26: Completed | Y26: Completed | Z26: Completed | AA26: 55 | AB26: 19 | AC26: 0 | AD26: 19 | AE26: 1 | AF26: 0.6 | AG26: =_xlfn.XLOOKUP(F26,'TFS Details'!F:F,'TFS Details'!H:H) -> UAT In Test | AH26: 19 | AI26: 0 | AJ26: 0 | AK26: 0 | AL26: =SUM(AH26:AK26) -> 19 | AM26: =IF(AH26+AI26=0,0,SUM(AH26:AI26)/AL26) -> 1 | AN26: =IF(AH26=0,0,AH26/(SUM(AH26:AJ26))) -> 1 | AP26: =_xlfn.XLOOKUP(F26,'TFS Details'!F:F,'TFS Details'!I:I) -> Spartans | AQ26: =_xlfn.XLOOKUP(AP26,'TFS Details'!I:I,'TFS Details'!AE:AE) -> nityanand.giri
A27: =_xlfn.XLOOKUP(F27,'TFS Details'!F:F,'TFS Details'!D:D) -> Drop 2 - Angular upgrade v19 to v21 | B27: =_xlfn.XLOOKUP(F27,'TFS Details'!F:F,'TFS Details'!A:A) -> Angular upgrade version 19 to version 21 - 28th March | C27: =_xlfn.XLOOKUP(F27,'TFS Details'!F:F,'TFS Details'!E:E) -> 4358702 | D27: Pirtheebaa | E27: As a myISP Solution Architect, I want to see the What Are We Solving For - MFE App migrated to Angular 21 | F27: 4358750 | G27: Vinayak | H27: Sadhik | K27: No | L27: Angular Upgrade can be covered in regression testing. | M27: Full regression required | W27: Completed | X27: Completed | Y27: Completed | Z27: Completed | AA27: 6 | AB27: 6 | AC27: 0 | AD27: 6 | AE27: 1 | AF27: 1 | AG27: =_xlfn.XLOOKUP(F27,'TFS Details'!F:F,'TFS Details'!H:H) -> Test Complete | AH27: 6 | AI27: 0 | AJ27: 0 | AK27: 0 | AL27: =SUM(AH27:AK27) -> 6 | AM27: =IF(AH27+AI27=0,0,SUM(AH27:AI27)/AL27) -> 1 | AN27: =IF(AH27=0,0,AH27/(SUM(AH27:AJ27))) -> 1 | AP27: =_xlfn.XLOOKUP(F27,'TFS Details'!F:F,'TFS Details'!I:I) -> MYISP_Revamp_UI | AQ27: =_xlfn.XLOOKUP(AP27,'TFS Details'!I:I,'TFS Details'!AE:AE) -> vikrant.r.mohite
A28: =_xlfn.XLOOKUP(F28,'TFS Details'!F:F,'TFS Details'!D:D) -> Drop 2 - Angular upgrade v19 to v21 | B28: =_xlfn.XLOOKUP(F28,'TFS Details'!F:F,'TFS Details'!A:A) -> Angular upgrade version 19 to version 21 - 28th March | C28: =_xlfn.XLOOKUP(F28,'TFS Details'!F:F,'TFS Details'!E:E) -> 4358702 | D28: Pirtheebaa | E28: As a myISP Solution Architect, I want to see the Revamp Assessment App migrated to Angular 21 | F28: 4358752 | G28: Mary | H28: Sadhik | K28: No | L28: Angular Migration | M28: Full regression required | W28: Completed | X28: Completed | Y28: Completed | Z28: Completed | AA28: 50 | AB28: 10 | AC28: 2 | AD28: 12 | AE28: 0.9 | AF28: 0.9 | AG28: =_xlfn.XLOOKUP(F28,'TFS Details'!F:F,'TFS Details'!H:H) -> Test Complete | AH28: 12 | AI28: 0 | AJ28: 0 | AK28: 0 | AL28: =SUM(AH28:AK28) -> 12 | AM28: =IF(AH28+AI28=0,0,SUM(AH28:AI28)/AL28) -> 1 | AN28: =IF(AH28=0,0,AH28/(SUM(AH28:AJ28))) -> 1 | AP28: =_xlfn.XLOOKUP(F28,'TFS Details'!F:F,'TFS Details'!I:I) -> MYISP_Revamp_UI | AQ28: =_xlfn.XLOOKUP(AP28,'TFS Details'!I:I,'TFS Details'!AE:AE) -> vikrant.r.mohite
A29: =_xlfn.XLOOKUP(F29,'TFS Details'!F:F,'TFS Details'!D:D) -> Opportunities | B29: =_xlfn.XLOOKUP(F29,'TFS Details'!F:F,'TFS Details'!A:A) -> Opportunities sorting | C29: =_xlfn.XLOOKUP(F29,'TFS Details'!F:F,'TFS Details'!E:E) -> 4364046 | D29: Pirtheebaa | E29: As a mysp user, I want to view the newly assigned MMS IDs at the top on the opportunities Table so that acceptance criteria are achieved. | F29: 4342359 | G29: Shalini | H29: Bhavana | K29: No | L29: Session Timeout Check | M29: Full regression required | W29: Completed | X29: Completed | Y29: Not Started | Z29: Completed | AA29: 30 | AB29: 8 | AC29: 2 | AD29: 8 | AE29: 0.7 | AF29: 0.7 | AG29: =_xlfn.XLOOKUP(F29,'TFS Details'!F:F,'TFS Details'!H:H) -> Test Complete | AH29: 8 | AI29: 0 | AJ29: 0 | AK29: 0 | AL29: =SUM(AH29:AK29) -> 8 | AM29: =IF(AH29+AI29=0,0,SUM(AH29:AI29)/AL29) -> 1 | AN29: =IF(AH29=0,0,AH29/(SUM(AH29:AJ29))) -> 1 | AP29: =_xlfn.XLOOKUP(F29,'TFS Details'!F:F,'TFS Details'!I:I) -> NGTransformers | AQ29: =_xlfn.XLOOKUP(AP29,'TFS Details'!I:I,'TFS Details'!AE:AE) -> sowjanya.kari
A30: Opportunity Workflow | B30: =_xlfn.XLOOKUP(F30,'TFS Details'!F:F,'TFS Details'!A:A) -> Song Updates in Reporting & Compliance | C30: =_xlfn.XLOOKUP(F30,'TFS Details'!F:F,'TFS Details'!E:E) -> 4226586 | D30: Pirtheebaa | E30: As a myISP User, I should be able to see the timestamp for the "Updated On" field in the View History of the Status Update screen so that I can accurately track when changes were made | F30: 4187518 | G30: Namrata | H30: Manisha | J30: namrata.g.umardand | K30: yes | N30: Complex | O30: 2 | P30: 1 | Q30: 10 | R30: 6 | S30: 0 | T30: 6 | U30: 0.7 | V30: 0.7 | W30: Completed | X30: Completed | Y30: In Progress | Z30: Completed | AG30: =_xlfn.XLOOKUP(F30,'TFS Details'!F:F,'TFS Details'!H:H) -> Test Complete | AH30: 24 | AI30: 0 | AJ30: 0 | AK30: 0 | AL30: =SUM(AH30:AK30) -> 24 | AM30: =IF(AH30+AI30=0,0,SUM(AH30:AI30)/AL30) -> 1 | AN30: =IF(AH30=0,0,AH30/(SUM(AH30:AJ30))) -> 1 | AP30: =_xlfn.XLOOKUP(F30,'TFS Details'!F:F,'TFS Details'!I:I) -> NGTransformers | AQ30: =_xlfn.XLOOKUP(AP30,'TFS Details'!I:I,'TFS Details'!AE:AE) -> sowjanya.kari
A31: =_xlfn.XLOOKUP(F31,'TFS Details'!F:F,'TFS Details'!D:D) -> Learn | B31: =_xlfn.XLOOKUP(F31,'TFS Details'!F:F,'TFS Details'!A:A) -> Services - Learn & Launch enhancements | C31: =_xlfn.XLOOKUP(F31,'TFS Details'!F:F,'TFS Details'!E:E) -> 4369027 | D31: Pirtheebaa | E31: As a myISP user, I want the ability to search content using hashtags and information from inside pages, so that I can quickly locate relevant learning materials and resources without having to navigate through multiple pages. | F31: 4258549 | G31: Shalini | H31: Saranya | J31: ShaliniB.Pandey | K31: Yes | N31: Medium | O31: 1 | P31: 1 | Q31: 14 | R31: 5 | S31: 0 | T31: 1 | U31: 0.7 | V31: 0.4 | W31: Completed | X31: Completed | Y31: Not Started | Z31: Completed | AA31: 28 | AB31: 2 | AC31: 5 | AD31: 7 | AE31: 0.4 | AF31: 0.4 | AG31: =_xlfn.XLOOKUP(F31,'TFS Details'!F:F,'TFS Details'!H:H) -> Test Complete | AH31: 7 | AI31: 0 | AJ31: 0 | AK31: 0 | AL31: =SUM(AH31:AK31) -> 7 | AM31: =IF(AH31+AI31=0,0,SUM(AH31:AI31)/AL31) -> 1 | AN31: =IF(AH31=0,0,AH31/(SUM(AH31:AJ31))) -> 1 | AP31: =_xlfn.XLOOKUP(F31,'TFS Details'!F:F,'TFS Details'!I:I) -> NGTransformers | AQ31: =_xlfn.XLOOKUP(AP31,'TFS Details'!I:I,'TFS Details'!AE:AE) -> sowjanya.kari
A32: =_xlfn.XLOOKUP(F32,'TFS Details'!F:F,'TFS Details'!D:D) -> SA Team manager | B32: =_xlfn.XLOOKUP(F32,'TFS Details'!F:F,'TFS Details'!A:A) -> SA Team manager User Registration Fields update and Mail POC changes | C32: =_xlfn.XLOOKUP(F32,'TFS Details'!F:F,'TFS Details'!E:E) -> 4282653 | D32: Pirtheebaa | E32: As a my Solution planner Solution Architect, I want the Alignment field to be enabled for Operations deployment in Register now pop up with an updated dropdown list , so that user can select specific alignment | F32: 4285630 | G32: Vinayak | H32: Bhavana | K32: No | L32: Email Functionality , register now popup | M32: Email functionality | W32: Completed | X32: Completed | Y32: Completed | Z32: Completed | AA32: 6 | AB32: 6 | AC32: 1 | AD32: 7 | AE32: 0.85 | AF32: 0.85 | AG32: =_xlfn.XLOOKUP(F32,'TFS Details'!F:F,'TFS Details'!H:H) -> Test Complete | AH32: 7 | AI32: 0 | AJ32: 0 | AK32: 0 | AL32: =SUM(AH32:AK32) -> 7 | AM32: =IF(AH32+AI32=0,0,SUM(AH32:AI32)/AL32) -> 1 | AN32: =IF(AH32=0,0,AH32/(SUM(AH32:AJ32))) -> 1 | AP32: =_xlfn.XLOOKUP(F32,'TFS Details'!F:F,'TFS Details'!I:I) -> GoRetro | AQ32: =_xlfn.XLOOKUP(AP32,'TFS Details'!I:I,'TFS Details'!AE:AE) -> sowjanya.kari
A33: =_xlfn.XLOOKUP(F33,'TFS Details'!F:F,'TFS Details'!D:D) -> SA Team manager | B33: =_xlfn.XLOOKUP(F33,'TFS Details'!F:F,'TFS Details'!A:A) -> SA Team manager User Registration Fields update and Mail POC changes | C33: =_xlfn.XLOOKUP(F33,'TFS Details'!F:F,'TFS Details'!E:E) -> 4282653 | D33: Pirtheebaa | E33: As a my Solution planner Solution Architect, I want the Alignment field to be enabled for Operations Deployment with an updated dropdown list in pending user requests tab, so that user can select specific alignment | F33: 4285636 | G33: Mary | H33: n.selvakumar | J33: Mary.jacob | K33: No | L33: One time update | M33: One time update related | N33: Medium | W33: Completed | X33: Completed | Y33: Completed | Z33: Completed | AA33: 30 | AB33: 6 | AC33: 2 | AD33: 8 | AE33: 0.9 | AF33: 0.9 | AG33: =_xlfn.XLOOKUP(F33,'TFS Details'!F:F,'TFS Details'!H:H) -> Test Complete | AH33: 8 | AI33: 0 | AJ33: 0 | AK33: 0 | AL33: =SUM(AH33:AK33) -> 8 | AM33: =IF(AH33+AI33=0,0,SUM(AH33:AI33)/AL33) -> 1 | AN33: =IF(AH33=0,0,AH33/(SUM(AH33:AJ33))) -> 1 | AP33: =_xlfn.XLOOKUP(F33,'TFS Details'!F:F,'TFS Details'!I:I) -> GoRetro | AQ33: =_xlfn.XLOOKUP(AP33,'TFS Details'!I:I,'TFS Details'!AE:AE) -> sowjanya.kari
A34: =_xlfn.XLOOKUP(F34,'TFS Details'!F:F,'TFS Details'!D:D) -> SA Team manager | B34: =_xlfn.XLOOKUP(F34,'TFS Details'!F:F,'TFS Details'!A:A) -> SA Team manager User Registration Fields update and Mail POC changes | C34: =_xlfn.XLOOKUP(F34,'TFS Details'!F:F,'TFS Details'!E:E) -> 4282653 | D34: Pirtheebaa | E34: As a my Solution planner Solution Architect, I want the POCs to be changed based on Deployment and Market in pending user requests tab, So that Approver/Rejection mail is sent to correct POCs | F34: 4275672 | G34: Namrata | H34: Manisha | K34: No | L34: One time update | M34: One time update related | W34: Completed | X34: Completed | Y34: In Progress | Z34: Completed | AA34: 24 | AB34: 10 | AC34: 11 | AD34: 12 | AE34: 1 | AF34: 1 | AG34: =_xlfn.XLOOKUP(F34,'TFS Details'!F:F,'TFS Details'!H:H) -> Test Complete | AH34: 24 | AI34: 0 | AJ34: 0 | AK34: 0 | AL34: =SUM(AH34:AK34) -> 24 | AM34: =IF(AH34+AI34=0,0,SUM(AH34:AI34)/AL34) -> 1 | AN34: =IF(AH34=0,0,AH34/(SUM(AH34:AJ34))) -> 1 | AP34: =_xlfn.XLOOKUP(F34,'TFS Details'!F:F,'TFS Details'!I:I) -> GoRetro | AQ34: =_xlfn.XLOOKUP(AP34,'TFS Details'!I:I,'TFS Details'!AE:AE) -> sowjanya.kari
A35: =_xlfn.XLOOKUP(F35,'TFS Details'!F:F,'TFS Details'!D:D) -> SA Team manager | B35: =_xlfn.XLOOKUP(F35,'TFS Details'!F:F,'TFS Details'!A:A) -> SA Team manager User Registration Fields update and Mail POC changes | C35: =_xlfn.XLOOKUP(F35,'TFS Details'!F:F,'TFS Details'!E:E) -> 4282653 | D35: Pirtheebaa | E35: As a my Solution planner Solution Architect, I want the POCs to be changed based on Deployment and Market in Register now pop up, So that Approver/Rejection mail is sent to correct POCs | F35: 4269089 | G35: Shalini | H35: Bhavana | K35: No | L35: Email Functionality , register now popup | M35: Email functionality | W35: Completed | X35: Completed | Y35: Not Started | Z35: Completed | AA35: 30 | AB35: 25 | AC35: 9 | AD35: 20 | AE35: 0.8 | AF35: 0.8 | AG35: =_xlfn.XLOOKUP(F35,'TFS Details'!F:F,'TFS Details'!H:H) -> Test Complete | AH35: 20 | AI35: 0 | AJ35: 0 | AK35: 0 | AL35: =SUM(AH35:AK35) -> 20 | AM35: =IF(AH35+AI35=0,0,SUM(AH35:AI35)/AL35) -> 1 | AN35: =IF(AH35=0,0,AH35/(SUM(AH35:AJ35))) -> 1 | AP35: =_xlfn.XLOOKUP(F35,'TFS Details'!F:F,'TFS Details'!I:I) -> GoRetro | AQ35: =_xlfn.XLOOKUP(AP35,'TFS Details'!I:I,'TFS Details'!AE:AE) -> sowjanya.kari
A36: =_xlfn.XLOOKUP(F36,'TFS Details'!F:F,'TFS Details'!D:D) -> SA Team manager | B36: =_xlfn.XLOOKUP(F36,'TFS Details'!F:F,'TFS Details'!A:A) -> SA Team manager User Registration Fields update and Mail POC changes | C36: =_xlfn.XLOOKUP(F36,'TFS Details'!F:F,'TFS Details'!E:E) -> 4282653 | D36: Pirtheebaa | E36: As a my Solution planner Solution Architect, I want the Registration pop-up to include the mentioned changes for Adding and updating fields ,so that users are able to see the required changes | F36: 4269111 | G36: Vinayak | H36: Bhavana | K36: No | L36: Email Functionality , register now popup | M36: Email functionality | W36: Completed | X36: Completed | Y36: Completed | Z36: Completed | AA36: 6 | AB36: 5 | AC36: 16 | AD36: 21 | AE36: 0.66 | AF36: 0.7 | AG36: =_xlfn.XLOOKUP(F36,'TFS Details'!F:F,'TFS Details'!H:H) -> Test Complete | AH36: 21 | AI36: 0 | AJ36: 0 | AK36: 0 | AL36: 21 | AM36: =IF(AH36+AI36=0,0,SUM(AH36:AI36)/AL36) -> 1 | AN36: =IF(AH36=0,0,AH36/(SUM(AH36:AJ36))) -> 1 | AP36: =_xlfn.XLOOKUP(F36,'TFS Details'!F:F,'TFS Details'!I:I) -> GoRetro | AQ36: =_xlfn.XLOOKUP(AP36,'TFS Details'!I:I,'TFS Details'!AE:AE) -> sowjanya.kari
A37: =_xlfn.XLOOKUP(F37,'TFS Details'!F:F,'TFS Details'!D:D) -> Common | B37: =_xlfn.XLOOKUP(F37,'TFS Details'!F:F,'TFS Details'!A:A) -> Comma formatting in all raise request emails | C37: =_xlfn.XLOOKUP(F37,'TFS Details'!F:F,'TFS Details'!E:E) -> 4387609 | D37: Pirtheebaa | E37: As a myISP User, I should be able to see the SG Revenue($M) value displayed in dollar millions with proper comma formatting in all raise request emails so that the recipients can quickly understand and interpret the revenue | F37: 4373609 | G37: Mary | H37: n.selvakumar | K37: No | L37: Email Functionality | M37: Email functionality | W37: Completed | X37: Completed | Y37: Completed | Z37: Completed | AA37: 36 | AB37: 7 | AC37: 0 | AD37: 7 | AE37: 1 | AF37: 1 | AG37: =_xlfn.XLOOKUP(F37,'TFS Details'!F:F,'TFS Details'!H:H) -> UAT In Test | AH37: 7 | AI37: 0 | AJ37: 0 | AK37: 0 | AL37: =SUM(AH37:AK37) -> 7 | AM37: =IF(AH37+AI37=0,0,SUM(AH37:AI37)/AL37) -> 1 | AN37: =IF(AH37=0,0,AH37/(SUM(AH37:AJ37))) -> 1 | AO37: Delivered for UAT | AP37: =_xlfn.XLOOKUP(F37,'TFS Details'!F:F,'TFS Details'!I:I) -> TechPhantoms | AQ37: =_xlfn.XLOOKUP(AP37,'TFS Details'!I:I,'TFS Details'!AE:AE) -> sowjanya.kari
A38: =_xlfn.XLOOKUP(F38,'TFS Details'!F:F,'TFS Details'!D:D) -> Learn | B38: =_xlfn.XLOOKUP(F38,'TFS Details'!F:F,'TFS Details'!A:A) -> Services - Learn & Launch enhancements | C38: =_xlfn.XLOOKUP(F38,'TFS Details'!F:F,'TFS Details'!E:E) -> 4369575 | D38: Pirtheebaa | E38: As a myISP user, I want to see new steps added under the Solution Components & Define team tabs when the Gen-AI toggle is enabled. | F38: 4372140 | G38: Shalini | H38: Saranya | J38: ShaliniB.Pandey | K38: Yes | N38: Medium | O38: 1 | P38: 1 | Q38: 14 | R38: 5 | S38: 0 | T38: 1 | U38: 0.7 | V38: 0.4 | W38: Completed | X38: Completed | Y38: Not Started | Z38: Completed | AA38: 30 | AB38: 20 | AC38: 4 | AD38: 23 | AE38: 0.9 | AF38: 0.9 | AG38: =_xlfn.XLOOKUP(F38,'TFS Details'!F:F,'TFS Details'!H:H) -> PT In Test | AH38: 23 | AI38: 0 | AJ38: 0 | AK38: 0 | AL38: =SUM(AH38:AK38) -> 23 | AM38: =IF(AH38+AI38=0,0,SUM(AH38:AI38)/AL38) -> 1 | AN38: =IF(AH38=0,0,AH38/(SUM(AH38:AJ38))) -> 1 | AP38: =_xlfn.XLOOKUP(F38,'TFS Details'!F:F,'TFS Details'!I:I) -> NGTransformers | AQ38: =_xlfn.XLOOKUP(AP38,'TFS Details'!I:I,'TFS Details'!AE:AE) -> sowjanya.kari
A39: View MMS Details | B39: =_xlfn.XLOOKUP(F39,'TFS Details'!F:F,'TFS Details'!A:A) -> Diel hierarchy - rolled up revenue | C39: =_xlfn.XLOOKUP(F39,'TFS Details'!F:F,'TFS Details'!E:E) -> 4378908 | D39: Pirtheebaa | E39: As a MyISP user reviewing MMS Details, I want to see a Rolled‑Up Revenue view by Service Group (AMS, IMS, etc.) under the Deal Hierarchy section, so that I can easily understand the combined revenue of parent and child for each service group | F39: 4378894 | G39: Vinayak | H39: Janardhan | J39: Vinayak.sangale | K39: Yes | N39: Complex | O39: 1 | P39: 1 | Q39: 7 | R39: 6 | S39: 0 | T39: 7 | U39: 0.85 | V39: 0.85 | W39: Completed | X39: Completed | Y39: Completed | Z39: Completed | AA39: 6 | AB39: 6 | AC39: 1 | AD39: 7 | AE39: 0.85 | AF39: 1 | AG39: =_xlfn.XLOOKUP(F39,'TFS Details'!F:F,'TFS Details'!H:H) -> Test Complete | AH39: 7 | AI39: 0 | AJ39: 0 | AK39: 0 | AL39: =SUM(AH39:AK39) -> 7 | AM39: =IF(AH39+AI39=0,0,SUM(AH39:AI39)/AL39) -> 1 | AN39: =IF(AH39=0,0,AH39/(SUM(AH39:AJ39))) -> 1 | AP39: =_xlfn.XLOOKUP(F39,'TFS Details'!F:F,'TFS Details'!I:I) -> GoRetro | AQ39: =_xlfn.XLOOKUP(AP39,'TFS Details'!I:I,'TFS Details'!AE:AE) -> sowjanya.kari
A40: =_xlfn.XLOOKUP(F40,'TFS Details'!F:F,'TFS Details'!D:D) -> myCalendar | B40: =_xlfn.XLOOKUP(F40,'TFS Details'!F:F,'TFS Details'!A:A) -> March Release NextGen Enhancements | C40: =_xlfn.XLOOKUP(F40,'TFS Details'!F:F,'TFS Details'!E:E) -> 4365826 | D40: Pirtheebaa | E40: As a MySP user, I want the "Add Event" button to be positioned in the top-right corner of the My Calendar screen popup So that I can quickly and intuitively create a new event without scrolling or searching for the action | F40: 4366103 | G40: Mary | H40: Bhavana | K40: No | L40: UI Design Change, can not be validated | M40: UI alignment and Font related | W40: Completed | X40: Completed | Y40: Completed | Z40: Completed | AA40: 30 | AB40: 9 | AC40: 1 | AD40: 10 | AE40: 0.95 | AF40: 0.95 | AG40: =_xlfn.XLOOKUP(F40,'TFS Details'!F:F,'TFS Details'!H:H) -> Test Complete | AH40: 10 | AI40: 0 | AJ40: 0 | AK40: 0 | AL40: =SUM(AH40:AK40) -> 10 | AM40: =IF(AH40+AI40=0,0,SUM(AH40:AI40)/AL40) -> 1 | AN40: =IF(AH40=0,0,AH40/(SUM(AH40:AJ40))) -> 1 | AP40: =_xlfn.XLOOKUP(F40,'TFS Details'!F:F,'TFS Details'!I:I) -> TechPhantoms | AQ40: =_xlfn.XLOOKUP(AP40,'TFS Details'!I:I,'TFS Details'!AE:AE) -> sowjanya.kari
...

Sheet Automation pocs
A1: Leads | B1: Functional POC to work with automation SME | C1: Automation POC
A2: Pirtheebaa | B2: Janardhan.veluri Saranya.datla n.selvakumar | C2: Kamali & Ashish | D2: 1. Maintainence of regression automated cases and running for each rls 2. Maintainence of insprint automated cases and running for each rls 3. From the P1 manual regression cases - we have to analyze and automate whatever possible 4. Code merge, head less execution and pipeline execution
A3: Himanshu | B3: logapriya.govindaraj k.p.palanisamy | C3: Sarthak
A4: Devika | B4: kristapati.v.reddy
A5: Anand | B5: k.tamilzharasu | C5: Ashish/pujitha/Suchitha/nathiya
A6: Raji | B6: shivaprasad.malekar
A7: Jaya | B7: Abhijit.a.nandi/sriram.a.karthikeyan | C7: Sanjana/Riya
A8: Kavi | B8: bhavana.pamidi/sathya.senthilkumar | C8: Ashish/Ruchitha
A9: Hajara/Leena | B9: rose.benedict and ritwik.sathishmohan | C9: Surabhi
A10: Nandini | B10: naga.v.pachipulusu r.maheen.abu.backer vadde.bindu | C10: Ruchitha

Sheet TFS Details
A1: Parent Title | B1: mySP Initiative | C1: Sub Initiative | D1: TextVerification | E1: Parent | F1: ID | G1: Title | H1: State | I1: Node Name | J1: Testing POC | K1: Planned for PT Date | L1: Actual PT Date | M1: Planned UAT Date | N1: Actual UAT Date | O1: Assigned To | P1: Production Deployment Date | Q1: Story Points | R1: Original Estimate | S1: Priority | T1: ETA | U1: UT Results Attached | V1: Code Review Completed | W1: Created By | X1: Created Date | Y1: Tags | Z1: Area Path | AA1: Iteration Path | AB1: Plan | AC1: Remaining | AD1: TextVerification1 | AE1: ExternalRef ID
A2: AMS SCA MVP2 March 28th Release Scope | B2: Rapid Soln | C2: GenAI | D2: AMS Solution Configuration Agent | E2: 4318876 | F2: 4330638 | G2: As a myISP AMS SCA Agent user, I want to configure multiple cost detail rows and use a clear and reliable profile/group name matching approach so that I can efficiently maintain solution standard cost configurations. | H2: UAT In Test | I2: agentcrafters | J2: Damodaran, J. <j.damodaran@accenture.com> | K2: 46087.229 | L2: 46091.901 | M2: 46091.021 | N2: 46092.91 | O2: Panchal, Dhwani <dhwani.panchal@accenture.com> | P2: 46109.229 | Q2: 1.5 | S2: 2 | U2: Yes | V2: Yes | W2: Pradhan, Kiran <kiran.pradhan@accenture.com> | X2: 46041.812 | Y2: Parallel UAT; SSA - SCA (MVP2) | Z2: AutomationProcess_29697\mySPRapidSolutioning\agentcrafters | AA2: AutomationProcess_29697\mySolutionPlanner | AD2: AMS Solution flow | AE2: shwetha.shriyan
A3: AMS SCA MVP2 March 28th Release Scope | B3: Rapid Soln | C3: GenAI | D3: AMS Solution Configuration Agent | E3: 4318876 | F3: 4351206 | G3: As an AMS SCA agent user, I want to download the EID template, import a Named Resource Report (NRR), and include profiles into the Active tab so that profiles are created efficiently without manual entry. | H3: UAT In Test | I3: agentcrafters | J3: Damodaran, J. <j.damodaran@accenture.com> | K3: 46085.229 | L3: 46087.229 | M3: 46091.021 | N3: 46094.684 | O3: Panchal, Dhwani <dhwani.panchal@accenture.com> | P3: 46109.229 | Q3: 1.25 | S3: 2 | U3: Yes | V3: Yes | W3: Rani Agurla, Sowmya <sowmya.rani.agurla@accenture.com> | X3: 46055.93 | Y3: Parallel UAT; SSA - SCA (MVP2) | Z3: AutomationProcess_29697\mySPRapidSolutioning\agentcrafters | AA3: AutomationProcess_29697\mySolutionPlannerIntegratedSolutionPlatform | AD3: AMS Solution flow | AE3: shwetha.shriyan
A4: AMS SCA MVP2 March 28th Release Scope | B4: Rapid Soln | C4: GenAI | D4: AMS Solution Configuration Agent | E4: 4318876 | F4: 4351207 | G4: As a AMS SCA User I want to provide Generative AI details to an AI agent in natural language So that the Gen AI configuration is automatically saved to my solution version Without manually filling out the Gen AI screen fields | H4: UAT In Test | I4: agentcrafters | J4: Damodaran, J. <j.damodaran@accenture.com> | K4: 46085.229 | L4: 46086.861 | M4: 46091.021 | N4: 46090.822 | O4: Panchal, Dhwani <dhwani.panchal@accenture.com> | P4: 46109.229 | Q4: 0.75 | S4: 2 | U4: Yes | V4: Yes | W4: Rani Agurla, Sowmya <sowmya.rani.agurla@accenture.com> | X4: 46055.934 | Y4: Parallel UAT; SSA - SCA (MVP2) | Z4: AutomationProcess_29697\mySPRapidSolutioning\agentcrafters | AA4: AutomationProcess_29697\mySolutionPlannerIntegratedSolutionPlatform | AD4: AMS Solution flow | AE4: shwetha.shriyan
A5: AMS SCA MVP2 March 28th Release Scope | B5: Rapid Soln | C5: GenAI | D5: AMS Solution Configuration Agent | E5: 4318876 | F5: 4351271 | G5: As an AMS SCA Agent User, I want to configure Rate Cards via Agent‑based Excel Import/Export, so that rate card details can be configured without manual UI navigation. | H5: UAT In Test | I5: agentcrafters | J5: Damodaran, J. <j.damodaran@accenture.com> | K5: 46085.229 | L5: 46092.062 | M5: 46088.021 | N5: 46101.028 | O5: Panchal, Dhwani <dhwani.panchal@accenture.com> | P5: 46109.229 | Q5: 2.5 | S5: 2 | U5: Yes | V5: Yes | W5: Rani Agurla, Sowmya <sowmya.rani.agurla@accenture.com> | X5: 46055.976 | Y5: Parallel UAT; SSA - SCA (MVP2) | Z5: AutomationProcess_29697\mySPRapidSolutioning\agentcrafters | AA5: AutomationProcess_29697\mySolutionPlannerIntegratedSolutionPlatform | AD5: AMS Solution flow | AE5: shwetha.shriyan
A6: AMS SCA MVP2 March 28th Release Scope | B6: Rapid Soln | C6: GenAI | D6: AMS Solution Configuration Agent | E6: 4318876 | F6: 4351286 | G6: As a AMS SCA Agent user, I want to map and unmap, Delete, Copy, add Groups functionalities via agent, so that I can configure & do the actions via agnet by providing the prompt. | H6: UAT In Test | I6: agentcrafters | J6: Damodaran, J. <j.damodaran@accenture.com> | K6: 46085.229 | L6: 46087.011 | M6: 46088.021 | N6: 46091.957 | O6: Panchal, Dhwani <dhwani.panchal@accenture.com> | P6: 46109.229 | Q6: 1.25 | S6: 2 | U6: Yes | V6: Yes | W6: Rani Agurla, Sowmya <sowmya.rani.agurla@accenture.com> | X6: 46055.984 | Y6: parallel testing; SSA - SCA (MVP2) | Z6: AutomationProcess_29697\mySPRapidSolutioning\agentcrafters | AA6: AutomationProcess_29697\mySolutionPlannerIntegratedSolutionPlatform | AD6: AMS Solution flow | AE6: shwetha.shriyan
A7: AMS SCA MVP2 March 28th Release Scope | B7: Rapid Soln | C7: GenAI | D7: AMS Solution Configuration Agent | E7: 4318876 | F7: 4351288 | G7: As a myISP AMS SCA Agent user, I want to update the Costing screen PMO Tax configuration functionality in agent, so that I can perform PMO Tax configuration via agent without navigating UI screens. | H7: UAT In Test | I7: agentcrafters | J7: Damodaran, J. <j.damodaran@accenture.com> | K7: 46085.229 | L7: 46092.859 | M7: 46088.021 | N7: 46094.99 | O7: Panchal, Dhwani <dhwani.panchal@accenture.com> | P7: 46109.229 | Q7: 1.25 | S7: 2 | U7: Yes | V7: Yes | W7: Rani Agurla, Sowmya <sowmya.rani.agurla@accenture.com> | X7: 46055.987 | Y7: SSA - SCA (MVP2) | Z7: AutomationProcess_29697\mySPRapidSolutioning\agentcrafters | AA7: AutomationProcess_29697\mySolutionPlannerIntegratedSolutionPlatform | AD7: AMS Solution flow | AE7: shwetha.shriyan
