Workbook

Sheet Milestone
A1: User story Freeze Date | B1: Cut off for PT hand over | C1: Cut off for UAT hand over | D1: UAT Completion | E1: Functional Bug closure | F1: Code Freeze | G1: Initial GNG decision | H1: Final Go/No Go Decision | I1: Final Go-Live
A2: 46104 | B2: 46119 | C2: 46122 | D2: 46127 | E2: 46127 | F2: 46128 | G2: 46126 | H2: 46128 | I2: 46130

Sheet PT status
A1: Module (TextVerification) | B1: Parent Title | C1: Feature ID | D1: PT Lead | E1: Title | F1: ID | G1: Primary Tester | H1: Secondary Tester | I1: Test Planning | J1: BA Review | K1: TFS upload | L1: PT Status | M1: Manual Test cases generated from GHC | N1: Useful Test cases from GHC | O1: Tester Created test case count | P1: Reviwed Final Test case count | Q1: Coverage for Manual Test cases from GHC% | R1: Accuracy for Manual test cases from GHC% | S1: TFS state | T1: Passed | U1: Failed | V1: Blocked | W1: Not Run | X1: Total | Y1: Execution % | Z1: Pass % | AA1: Comments | AB1: Node Name | AC1: MPOC
A2: =_xlfn.XLOOKUP(F2,'TFS Details'!F:F,'TFS Details'!D:D) -> Drop 3 - Angular upgrade v19 to v21 | B2: =_xlfn.XLOOKUP(F2,'TFS Details'!F:F,'TFS Details'!A:A) -> Angular upgrade version 19 to version 21 - 18th April | C2: =_xlfn.XLOOKUP(F2,'TFS Details'!F:F,'TFS Details'!E:E) -> 4429397 | D2: Pirtheebaa | E2: As a myISP Solution Architect, I want to see the Solution Components (AMS) MFE App migrated to Angular 21 | F2: 4429413 | G2: Mary/Janardhan | I2: Completed | J2: Completed | K2: Completed | L2: Completed | M2: 48 | N2: 10 | O2: 14 | P2: 24 | Q2: 0.4 | R2: 0.4 | T2: 20 | U2: 0 | V2: 0 | W2: 0 | X2: =SUM(T2:W2) -> 20 | Y2: =IF(T2+U2=0,0,SUM(T2:U2)/X2) -> 1 | Z2: =IF(T2=0,0,T2/(SUM(T2:V2))) -> 1 | AB2: =_xlfn.XLOOKUP(F2,'TFS Details'!F:F,'TFS Details'!I:I) -> MYISP_Revamp_UI | AC2: =_xlfn.XLOOKUP(AB2,'TFS Details'!I:I,'TFS Details'!AE:AE) -> vikrant.r.mohite
A3: =_xlfn.XLOOKUP(F3,'TFS Details'!F:F,'TFS Details'!D:D) -> Drop 3 - Angular upgrade v19 to v21 | B3: =_xlfn.XLOOKUP(F3,'TFS Details'!F:F,'TFS Details'!A:A) -> Angular upgrade version 19 to version 21 - 18th April | C3: =_xlfn.XLOOKUP(F3,'TFS Details'!F:F,'TFS Details'!E:E) -> 4429397 | D3: Leena | E3: As a myISP Solution Architect, I want to see the Digital Documentation - MFE App migrated to Angular 21 | F3: 4429519 | G3: Harshitha | I3: Completed | J3: In Progress | K3: Not Started | L3: In Progress | M3: 15 | N3: 10 | O3: 0 | P3: 10 | Q3: 0.95 | R3: 0.95 | T3: 6 | U3: 0 | V3: 0 | W3: 4 | X3: 10 | Y3: =IF(T3+U3=0,0,SUM(T3:U3)/X3) -> 0.6 | Z3: =IF(T3=0,0,T3/(SUM(T3:V3))) -> 1 | AB3: =_xlfn.XLOOKUP(F3,'TFS Details'!F:F,'TFS Details'!I:I) -> MYISP_Revamp_UI | AC3: =_xlfn.XLOOKUP(AB3,'TFS Details'!I:I,'TFS Details'!AE:AE) -> vikrant.r.mohite
A4: =_xlfn.XLOOKUP(F4,'TFS Details'!F:F,'TFS Details'!D:D) -> Drop 3 - Angular upgrade v19 to v21 | B4: =_xlfn.XLOOKUP(F4,'TFS Details'!F:F,'TFS Details'!A:A) -> Angular upgrade version 19 to version 21 - 18th April | C4: =_xlfn.XLOOKUP(F4,'TFS Details'!F:F,'TFS Details'!E:E) -> 4429397 | D4: Rajeswari | E4: As a myISP Solution Architect, I want to see the CDAT - MFE App migrated to Angular 21 | F4: 4429521 | G4: PavithraJabeen | H4: Agnes | I4: Completed | J4: Completed | K4: In Progress | L4: In Progress | M4: 40 | N4: 40 | O4: 0 | P4: 40 | Q4: 1 | R4: 1 | T4: 28 | U4: 0 | V4: 0 | W4: 12 | X4: 40 | Y4: =IF(T4+U4=0,0,SUM(T4:U4)/X4) -> 0.7 | Z4: =IF(T4=0,0,T4/(SUM(T4:V4))) -> 1 | AB4: =_xlfn.XLOOKUP(F4,'TFS Details'!F:F,'TFS Details'!I:I) -> MYISP_Revamp_UI | AC4: =_xlfn.XLOOKUP(AB4,'TFS Details'!I:I,'TFS Details'!AE:AE) -> vikrant.r.mohite
A5: =_xlfn.XLOOKUP(F5,'TFS Details'!F:F,'TFS Details'!D:D) -> Drop 3 - Angular upgrade v19 to v21 | B5: =_xlfn.XLOOKUP(F5,'TFS Details'!F:F,'TFS Details'!A:A) -> Angular upgrade version 19 to version 21 - 18th April | C5: =_xlfn.XLOOKUP(F5,'TFS Details'!F:F,'TFS Details'!E:E) -> 4429397 | D5: Jaya | E5: As a myISP Solution Architect, I want to see the Cost Price Engine UI App migrated to Angular 21 | F5: 4429530 | G5: Anu | H5: Sriram | I5: Completed | J5: Completed | K5: Not Started | L5: In Progress | M5: 26 | N5: 17 | O5: 17 | P5: 17 | Q5: 0.9 | R5: 0.9 | T5: 13 | U5: 0 | V5: 0 | W5: 4 | X5: =SUM(T5:W5) -> 17 | Y5: =IF(T5+U5=0,0,SUM(T5:U5)/X5) -> 0.76470588 | Z5: =IF(T5=0,0,T5/(SUM(T5:V5))) -> 1 | AB5: =_xlfn.XLOOKUP(F5,'TFS Details'!F:F,'TFS Details'!I:I) -> MYISP_Revamp_UI | AC5: =_xlfn.XLOOKUP(AB5,'TFS Details'!I:I,'TFS Details'!AE:AE) -> vikrant.r.mohite
A6: =_xlfn.XLOOKUP(F6,'TFS Details'!F:F,'TFS Details'!D:D) -> AMS | B6: =_xlfn.XLOOKUP(F6,'TFS Details'!F:F,'TFS Details'!A:A) -> Available Hours OU Report | C6: =_xlfn.XLOOKUP(F6,'TFS Details'!F:F,'TFS Details'!E:E) -> 4439196 | D6: Jaya | E6: AMS OCP/DCTA: As a mySolutionPlanner developer, I should be able to get the Export/Import status tab in Available Hours screen | F6: 4439199 | G6: Anu | H6: Ihsana | I6: Completed | J6: Completed | K6: Not Started | L6: Not Started | T6: 0 | U6: 0 | V6: 0 | W6: 15 | X6: =SUM(T6:W6) -> 15 | Y6: =IF(T6+U6=0,0,SUM(T6:U6)/X6) -> 0 | Z6: =IF(T6=0,0,T6/(SUM(T6:V6))) -> 0
A7: =_xlfn.XLOOKUP(F7,'TFS Details'!F:F,'TFS Details'!D:D) -> AMS | B7: =_xlfn.XLOOKUP(F7,'TFS Details'!F:F,'TFS Details'!A:A) -> Available Hours OU Report | C7: =_xlfn.XLOOKUP(F7,'TFS Details'!F:F,'TFS Details'!E:E) -> 4439196 | D7: Jaya | E7: AMS OCP/DCTA: As a mySolutionPlanner developer, I should be able to get the Export option in Available Hours template for Staffing | F7: 4439323 | G7: Anu | H7: Ihsana | I7: Completed | J7: Completed | K7: Not Started | L7: Not Started | T7: 0 | U7: 0 | V7: 0 | W7: 17 | X7: =SUM(T7:W7) -> 17 | Y7: =IF(T7+U7=0,0,SUM(T7:U7)/X7) -> 0 | Z7: =IF(T7=0,0,T7/(SUM(T7:V7))) -> 0
A8: =_xlfn.XLOOKUP(F8,'TFS Details'!F:F,'TFS Details'!D:D) -> AMS | B8: =_xlfn.XLOOKUP(F8,'TFS Details'!F:F,'TFS Details'!A:A) -> Available Hours OU Report | C8: =_xlfn.XLOOKUP(F8,'TFS Details'!F:F,'TFS Details'!E:E) -> 4439196 | D8: Jaya | E8: AMS OCP/DCTA: As a mySolutionPlanner developer, I should be able to get the Export option in Available Hours template for PMO | F8: 4439343 | G8: Anu | H8: Ihsana | I8: Completed | J8: Completed | K8: Not Started | L8: Not Started | T8: 0 | U8: 0 | V8: 0 | W8: 7 | X8: =SUM(T8:W8) -> 7 | Y8: =IF(T8+U8=0,0,SUM(T8:U8)/X8) -> 0 | Z8: =IF(T8=0,0,T8/(SUM(T8:V8))) -> 0
A9: =_xlfn.XLOOKUP(F9,'TFS Details'!F:F,'TFS Details'!D:D) -> AMS | B9: =_xlfn.XLOOKUP(F9,'TFS Details'!F:F,'TFS Details'!A:A) -> Available Hours OU Report | C9: =_xlfn.XLOOKUP(F9,'TFS Details'!F:F,'TFS Details'!E:E) -> 4439196 | D9: Jaya | E9: AMS OCP/DCTA: As a mySolutionPlanner developer, I should be able to get the Import option in Available Hours template for Staffing | F9: 4439357 | G9: Anu | H9: Ihsana | I9: Completed | J9: Completed | K9: Not Started | L9: Not Started | T9: 0 | U9: 0 | V9: 0 | W9: 7 | X9: =SUM(T9:W9) -> 7 | Y9: =IF(T9+U9=0,0,SUM(T9:U9)/X9) -> 0 | Z9: =IF(T9=0,0,T9/(SUM(T9:V9))) -> 0
A10: =_xlfn.XLOOKUP(F10,'TFS Details'!F:F,'TFS Details'!D:D) -> AMS | B10: =_xlfn.XLOOKUP(F10,'TFS Details'!F:F,'TFS Details'!A:A) -> Available Hours OU Report | C10: =_xlfn.XLOOKUP(F10,'TFS Details'!F:F,'TFS Details'!E:E) -> 4439196 | D10: Jaya | E10: AMS OCP/DCTA: As a mySolutionPlanner developer, I should be able to get the Import option in Available Hours template for PMO | F10: 4439362 | G10: Anu | H10: Ihsana | I10: Completed | J10: Completed | K10: Not Started | L10: Not Started | T10: 0 | U10: 0 | V10: 0 | W10: 10 | X10: =SUM(T10:W10) -> 10 | Y10: =IF(T10+U10=0,0,SUM(T10:U10)/X10) -> 0 | Z10: =IF(T10=0,0,T10/(SUM(T10:V10))) -> 0
A11: =_xlfn.XLOOKUP(F11,'TFS Details'!F:F,'TFS Details'!D:D) -> DCSO | B11: =_xlfn.XLOOKUP(F11,'TFS Details'!F:F,'TFS Details'!A:A) -> myISP - Digital DCSO | C11: =_xlfn.XLOOKUP(F11,'TFS Details'!F:F,'TFS Details'!E:E) -> 4278081 | D11: Shini | E11: As a myisp Solution Architect, I want the DCSO tab to be removed from the SI KDA/Reports screen So that users do not access or generate DCSO information from the KDA / Reports interface. | F11: 4362582 | G11: Jeba | I11: Completed | J11: Completed | K11: Completed | L11: Completed | T11: 3 | U11: 0 | V11: 0 | W11: 0 | X11: =SUM(T11:W11) -> 3 | Y11: =IF(T11+U11=0,0,SUM(T11:U11)/X11) -> 1 | Z11: =IF(T11=0,0,T11/(SUM(T11:V11))) -> 1 | AB11: =_xlfn.XLOOKUP(F11,'TFS Details'!F:F,'TFS Details'!I:I) -> Insurgents | AC11: =_xlfn.XLOOKUP(AB11,'TFS Details'!I:I,'TFS Details'!AE:AE) -> K.devaraj
A12: =_xlfn.XLOOKUP(F12,'TFS Details'!F:F,'TFS Details'!D:D) -> DCSO | B12: =_xlfn.XLOOKUP(F12,'TFS Details'!F:F,'TFS Details'!A:A) -> myISP - Digital DCSO | C12: =_xlfn.XLOOKUP(F12,'TFS Details'!F:F,'TFS Details'!E:E) -> 4278081 | D12: Shini | E12: As a myisp Solution Architect, I want the DCSO tab to be removed from the AMS KDA/Reports screen So that users do not access or generate DCSO information from the KDA / Reports interface. | F12: 4362592 | G12: Jeba | I12: Completed | J12: Completed | K12: Completed | L12: Completed | T12: 3 | U12: 0 | V12: 0 | W12: 0 | X12: =SUM(T12:W12) -> 3 | Y12: =IF(T12+U12=0,0,SUM(T12:U12)/X12) -> 1 | Z12: =IF(T12=0,0,T12/(SUM(T12:V12))) -> 1 | AB12: =_xlfn.XLOOKUP(F12,'TFS Details'!F:F,'TFS Details'!I:I) -> Insurgents | AC12: =_xlfn.XLOOKUP(AB12,'TFS Details'!I:I,'TFS Details'!AE:AE) -> K.devaraj
A13: =_xlfn.XLOOKUP(F13,'TFS Details'!F:F,'TFS Details'!D:D) -> MMP FFP | B13: =_xlfn.XLOOKUP(F13,'TFS Details'!F:F,'TFS Details'!A:A) -> MMP FFP Export update - April release | C13: =_xlfn.XLOOKUP(F13,'TFS Details'!F:F,'TFS Details'!E:E) -> 4389877 | D13: Kavi | E13: As a myISP SA, I want to change the logic to populate "Role Type" and "Accenture Role/Rate" in MMP FFP so that it is aligned with Dynamic Target Pricing implementation | F13: 4391224 | G13: Manisa | H13: Sathya | I13: Completed | J13: Completed | K13: Completed | L13: In Progress | M13: 39 | N13: 27 | O13: 0 | P13: 27 | Q13: =N13/P13 -> 1 | R13: 0.8 | T13: 11 | U13: 7 | V13: 0 | W13: 9 | X13: =SUM(T13:W13) -> 27 | Y13: =IF(T13+U13=0,0,SUM(T13:U13)/X13) -> 0.66666667 | Z13: =IF(T13=0,0,T13/(SUM(T13:V13))) -> 0.61111111 | AA13: Delivered UAT for parallel testing with open bugs-4467554(H),4462668(M),4462709(M) | AB13: =_xlfn.XLOOKUP(F13,'TFS Details'!F:F,'TFS Details'!I:I) -> DevStormers | AC13: =_xlfn.XLOOKUP(AB13,'TFS Details'!I:I,'TFS Details'!AE:AE) -> mervinkumar.manickam
A14: =_xlfn.XLOOKUP(F14,'TFS Details'!F:F,'TFS Details'!D:D) -> SI DCTA | B14: =_xlfn.XLOOKUP(F14,'TFS Details'!F:F,'TFS Details'!A:A) -> Standard Role Implementation in PCW & Online SI - April Release | C14: =_xlfn.XLOOKUP(F14,'TFS Details'!F:F,'TFS Details'!E:E) -> 4373911 | D14: Kavi | E14: As a myISP SA, I want to apply filter FFP Visible = False in addition to other filters while displaying Standard Role in staffing so that it is aligned with MMP standards | F14: 4393527 | G14: Manisa | H14: Sathya | I14: Completed | J14: Completed | K14: Completed | L14: In Progress | M14: 41 | N14: 27 | O14: 0 | P14: 27 | Q14: =N14/P14 -> 1 | R14: 0.75 | T14: 13 | U14: 0 | V14: 0 | W14: 14 | X14: =SUM(T14:W14) -> 27 | Y14: =IF(T14+U14=0,0,SUM(T14:U14)/X14) -> 0.48148148 | Z14: =IF(T14=0,0,T14/(SUM(T14:V14))) -> 1 | AB14: =_xlfn.XLOOKUP(F14,'TFS Details'!F:F,'TFS Details'!I:I) -> TechSprinters | AC14: =_xlfn.XLOOKUP(AB14,'TFS Details'!I:I,'TFS Details'!AE:AE) -> mervinkumar.manickam
A15: =_xlfn.XLOOKUP(F15,'TFS Details'!F:F,'TFS Details'!D:D) -> SI DCTA | B15: =_xlfn.XLOOKUP(F15,'TFS Details'!F:F,'TFS Details'!A:A) -> Standard Role Implementation in PCW & Online SI - April Release | C15: =_xlfn.XLOOKUP(F15,'TFS Details'!F:F,'TFS Details'!E:E) -> 4373911 | D15: Kavi | E15: As a myISP SA, I want to add new columns in the DCTA JSON file so that dynamic target pricing can be computed | F15: 4377948 | G15: Manisa | H15: Sathya | I15: Completed | J15: Completed | K15: Completed | L15: In Progress | M15: 53 | N15: 27 | O15: 0 | P15: 27 | Q15: =N15/P15 -> 1 | R15: 0.85 | T15: 7 | U15: 0 | V15: 0 | W15: 20 | X15: =SUM(T15:W15) -> 27 | Y15: =IF(T15+U15=0,0,SUM(T15:U15)/X15) -> 0.25925926 | Z15: =IF(T15=0,0,T15/(SUM(T15:V15))) -> 1 | AB15: =_xlfn.XLOOKUP(F15,'TFS Details'!F:F,'TFS Details'!I:I) -> TechSprinters | AC15: =_xlfn.XLOOKUP(AB15,'TFS Details'!I:I,'TFS Details'!AE:AE) -> mervinkumar.manickam
A16: =_xlfn.XLOOKUP(F16,'TFS Details'!F:F,'TFS Details'!D:D) -> STD Role | B16: =_xlfn.XLOOKUP(F16,'TFS Details'!F:F,'TFS Details'!A:A) -> Standard Role Implementation in PCW & Online SI - April Release | C16: =_xlfn.XLOOKUP(F16,'TFS Details'!F:F,'TFS Details'!E:E) -> 4373911 | D16: Kavi | E16: As a SA,I want the Profile city Tier field to auto-populate from the Rate Type column in the Staffing Baseline screen | F16: 4359188 | G16: Manisa | H16: Sathya | I16: Completed | J16: Completed | K16: Completed | L16: In Progress | M16: 51 | N16: 35 | O16: 0 | P16: 35 | Q16: =N16/P16 -> 1 | R16: 0.8 | T16: 25 | U16: 0 | V16: 0 | W16: 10 | X16: =SUM(T16:W16) -> 35 | Y16: =IF(T16+U16=0,0,SUM(T16:U16)/X16) -> 0.71428571 | Z16: =IF(T16=0,0,T16/(SUM(T16:V16))) -> 1 | AB16: =_xlfn.XLOOKUP(F16,'TFS Details'!F:F,'TFS Details'!I:I) -> TechWizards | AC16: =_xlfn.XLOOKUP(AB16,'TFS Details'!I:I,'TFS Details'!AE:AE) -> mervinkumar.manickam
A17: =_xlfn.XLOOKUP(F17,'TFS Details'!F:F,'TFS Details'!D:D) -> STD Role | B17: =_xlfn.XLOOKUP(F17,'TFS Details'!F:F,'TFS Details'!A:A) -> Standard Role Implementation in PCW & Online SI - April Release | C17: =_xlfn.XLOOKUP(F17,'TFS Details'!F:F,'TFS Details'!E:E) -> 4373911 | D17: Kavi | E17: As a SA, add Role Type field in Staffing Baseline (auto-populated from Std Location Type & Service Group) | F17: 4359328 | G17: Sathya | H17: Manisa | I17: Completed | J17: Completed | K17: Completed | L17: In Progress | M17: 65 | N17: 51 | O17: 0 | P17: 51 | Q17: =N17/P17 -> 1 | R17: 0.8 | T17: 20 | U17: 5 | V17: 0 | W17: 26 | X17: =SUM(T17:W17) -> 51 | Y17: =IF(T17+U17=0,0,SUM(T17:U17)/X17) -> 0.49019608 | Z17: =IF(T17=0,0,T17/(SUM(T17:V17))) -> 0.8 | AA17: Bug-4462284(L),4462476(M),4465936(M) | AB17: =_xlfn.XLOOKUP(F17,'TFS Details'!F:F,'TFS Details'!I:I) -> TechWizards | AC17: =_xlfn.XLOOKUP(AB17,'TFS Details'!I:I,'TFS Details'!AE:AE) -> mervinkumar.manickam
A18: =_xlfn.XLOOKUP(F18,'TFS Details'!F:F,'TFS Details'!D:D) -> STD Role | B18: =_xlfn.XLOOKUP(F18,'TFS Details'!F:F,'TFS Details'!A:A) -> Standard Role Implementation in PCW & Online SI - April Release | C18: =_xlfn.XLOOKUP(F18,'TFS Details'!F:F,'TFS Details'!E:E) -> 4373911 | D18: Kavi | E18: As a SA I want to select standard role from an SSG-specific dropdown selection | F18: 4359507 | G18: Sathya | H18: Manisa | I18: Completed | J18: Completed | K18: Completed | L18: In Progress | M18: 54 | N18: 38 | O18: 0 | P18: 38 | Q18: =N18/P18 -> 1 | R18: 0.75 | T18: 28 | U18: 0 | V18: 0 | W18: 10 | X18: =SUM(T18:W18) -> 38 | Y18: =IF(T18+U18=0,0,SUM(T18:U18)/X18) -> 0.73684211 | Z18: =IF(T18=0,0,T18/(SUM(T18:V18))) -> 1 | AB18: =_xlfn.XLOOKUP(F18,'TFS Details'!F:F,'TFS Details'!I:I) -> TechWizards | AC18: =_xlfn.XLOOKUP(AB18,'TFS Details'!I:I,'TFS Details'!AE:AE) -> mervinkumar.manickam
A19: =_xlfn.XLOOKUP(F19,'TFS Details'!F:F,'TFS Details'!D:D) -> PCW | B19: =_xlfn.XLOOKUP(F19,'TFS Details'!F:F,'TFS Details'!A:A) -> MMP FFP Export update - April release | C19: =_xlfn.XLOOKUP(F19,'TFS Details'!F:F,'TFS Details'!E:E) -> 4389877 | D19: Anand | E19: API - Enhance the defaulting logics to populate 'Accenture Role/Rate' in offline MMP FFP Export | F19: 4368135 | G19: Sairam | H19: Sneha | I19: Completed | J19: Completed | K19: In Progress | L19: In Progress | M19: 10 | N19: 3 | O19: 3 | P19: 3 | Q19: 1 | R19: 0.8 | T19: 2 | U19: 0 | V19: 0 | W19: 1 | X19: =SUM(T19:W19) -> 3 | Y19: =IF(T19+U19=0,0,SUM(T19:U19)/X19) -> 0.66666667 | Z19: =IF(T19=0,0,T19/(SUM(T19:V19))) -> 1 | AA19: Delivered to Parallol UAT | AB19: =_xlfn.XLOOKUP(F19,'TFS Details'!F:F,'TFS Details'!I:I) -> TechAvatar | AC19: =_xlfn.XLOOKUP(AB19,'TFS Details'!I:I,'TFS Details'!AE:AE) -> suraj.sukumaran
A20: =_xlfn.XLOOKUP(F20,'TFS Details'!F:F,'TFS Details'!D:D) -> SI - PCW | B20: =_xlfn.XLOOKUP(F20,'TFS Details'!F:F,'TFS Details'!A:A) -> Standard Role Implementation in PCW & Online SI - April Release | C20: =_xlfn.XLOOKUP(F20,'TFS Details'!F:F,'TFS Details'!E:E) -> 4373911 | D20: Anand | E20: API - Save the Technology Tier, Profile City Tier, Role Type, Technology Role and Standard Role from Staffing Baseline | F20: 4368224 | G20: Viji | H20: Naveen S | I20: Completed | J20: Completed | K20: In Progress | L20: In Progress | M20: 44 | N20: 11 | O20: 8 | P20: 11 | Q20: 1 | R20: 1 | T20: 6 | U20: 2 | V20: 0 | W20: 2 | X20: =SUM(T20:W20) -> 10 | Y20: =IF(T20+U20=0,0,SUM(T20:U20)/X20) -> 0.8 | Z20: =IF(T20=0,0,T20/(SUM(T20:V20))) -> 0.75 | AA20: Bug id : 4462520(M),4462534(M), Delivered to UAT for Parallel Testing | AB20: =_xlfn.XLOOKUP(F20,'TFS Details'!F:F,'TFS Details'!I:I) -> TechAvatar | AC20: =_xlfn.XLOOKUP(AB20,'TFS Details'!I:I,'TFS Details'!AE:AE) -> suraj.sukumaran
A21: =_xlfn.XLOOKUP(F21,'TFS Details'!F:F,'TFS Details'!D:D) -> STD Role | B21: =_xlfn.XLOOKUP(F21,'TFS Details'!F:F,'TFS Details'!A:A) -> Standard Role Implementation in PCW & Online SI - April Release | C21: =_xlfn.XLOOKUP(F21,'TFS Details'!F:F,'TFS Details'!E:E) -> 4373911 | D21: Kavi | E21: As a SA, add Role Type field in Staffing Baseline (auto-populated from Std Location Type & Service Group) - OU changes | F21: 4368812 | G21: Sathya | H21: Manisa | I21: Completed | J21: Completed | K21: Completed | L21: In Progress | M21: 61 | N21: 42 | O21: 0 | P21: 42 | Q21: =N21/P21 -> 1 | R21: 0.8 | T21: 15 | U21: 3 | V21: 0 | W21: 24 | X21: =SUM(T21:W21) -> 42 | Y21: =IF(T21+U21=0,0,SUM(T21:U21)/X21) -> 0.42857143 | Z21: =IF(T21=0,0,T21/(SUM(T21:V21))) -> 0.83333333 | AA21: Bug-4461770(M) | AB21: =_xlfn.XLOOKUP(F21,'TFS Details'!F:F,'TFS Details'!I:I) -> TechWizards | AC21: =_xlfn.XLOOKUP(AB21,'TFS Details'!I:I,'TFS Details'!AE:AE) -> mervinkumar.manickam
A22: =_xlfn.XLOOKUP(F22,'TFS Details'!F:F,'TFS Details'!D:D) -> STD Role | B22: =_xlfn.XLOOKUP(F22,'TFS Details'!F:F,'TFS Details'!A:A) -> Standard Role Implementation in PCW & Online SI - April Release | C22: =_xlfn.XLOOKUP(F22,'TFS Details'!F:F,'TFS Details'!E:E) -> 4373911 | D22: Anand | E22: As a SA I want to select standard role from an SSG-specific dropdown selection- OU changes | F22: 4368862 | G22: Viji | H22: Sneha | I22: Completed | J22: Completed | K22: In Progress | L22: In Progress | M22: 42 | N22: 12 | O22: 8 | P22: 8 | Q22: 1 | R22: 0.9 | T22: 5 | U22: 0 | V22: 0 | W22: 3 | X22: =SUM(T22:W22) -> 8 | Y22: =IF(T22+U22=0,0,SUM(T22:U22)/X22) -> 0.625 | Z22: =IF(T22=0,0,T22/(SUM(T22:V22))) -> 1 | AA22: Delivered to UAT for Parallel testing | AB22: =_xlfn.XLOOKUP(F22,'TFS Details'!F:F,'TFS Details'!I:I) -> TechWizards | AC22: =_xlfn.XLOOKUP(AB22,'TFS Details'!I:I,'TFS Details'!AE:AE) -> mervinkumar.manickam
A23: =_xlfn.XLOOKUP(F23,'TFS Details'!F:F,'TFS Details'!D:D) -> SDL | B23: =_xlfn.XLOOKUP(F23,'TFS Details'!F:F,'TFS Details'!A:A) -> Standard Role Implementation in SI Staffing Baseline - Analysis | C23: =_xlfn.XLOOKUP(F23,'TFS Details'!F:F,'TFS Details'!E:E) -> 4277501 | D23: Anand | E23: As a Solution Architect, I want to see dynamic target pricing parameters in SDL SI DL regardless of rate card configuration | F23: 4371046 | G23: Sneha | H23: Viji | I23: Completed | J23: Completed | K23: Not Started | L23: In Progress | M23: 30 | N23: 8 | O23: 13 | P23: 13 | Q23: 0.7 | R23: 0.7 | T23: 7 | U23: 1 | V23: 0 | W23: 3 | X23: =SUM(T23:W23) -> 11 | Y23: =IF(T23+U23=0,0,SUM(T23:U23)/X23) -> 0.72727273 | Z23: =IF(T23=0,0,T23/(SUM(T23:V23))) -> 0.875 | AA23: Delivered for parallel testing, Bug : 4465941 (M) | AB23: =_xlfn.XLOOKUP(F23,'TFS Details'!F:F,'TFS Details'!I:I) -> DevStormers | AC23: =_xlfn.XLOOKUP(AB23,'TFS Details'!I:I,'TFS Details'!AE:AE) -> mervinkumar.manickam
A24: =_xlfn.XLOOKUP(F24,'TFS Details'!F:F,'TFS Details'!D:D) -> STD Role | B24: =_xlfn.XLOOKUP(F24,'TFS Details'!F:F,'TFS Details'!A:A) -> Standard Role Implementation in PCW & Online SI - April Release | C24: =_xlfn.XLOOKUP(F24,'TFS Details'!F:F,'TFS Details'!E:E) -> 4373911 | D24: Anand | E24: As a SA, add Technology & Standard Role columns in Staffing Baseline for auto-population/selection based on Tech Group & SSG. | F24: 4372847 | G24: Sneha | H24: Naveen S | I24: Completed | J24: Completed | K24: Not Started | L24: In Progress | M24: 43 | N24: 30 | O24: 24 | P24: 24 | Q24: 0.7 | R24: 0.7 | T24: 8 | U24: 8 | V24: 0 | W24: 8 | X24: =SUM(T24:W24) -> 24 | Y24: =IF(T24+U24=0,0,SUM(T24:U24)/X24) -> 0.66666667 | Z24: =IF(T24=0,0,T24/(SUM(T24:V24))) -> 0.5 | AA24: Bug 4462287(M),Bug 4462311(L), Bug: 4462289 (H), Delivered for parallel testing | AB24: =_xlfn.XLOOKUP(F24,'TFS Details'!F:F,'TFS Details'!I:I) -> TechWizards | AC24: =_xlfn.XLOOKUP(AB24,'TFS Details'!I:I,'TFS Details'!AE:AE) -> mervinkumar.manickam
A25: =_xlfn.XLOOKUP(F25,'TFS Details'!F:F,'TFS Details'!D:D) -> PCW | B25: =_xlfn.XLOOKUP(F25,'TFS Details'!F:F,'TFS Details'!A:A) -> MMP FFP Export update - April release | C25: =_xlfn.XLOOKUP(F25,'TFS Details'!F:F,'TFS Details'!E:E) -> 4389877 | D25: Anand | E25: PCW - Pass Role Type column to API as an input filter parameter for defaulting logics of offline MMP FFP Export | F25: 4395067 | G25: Sairam | H25: Naveen S | I25: Completed | J25: Completed | K25: In Progress | L25: In Progress | M25: 11 | N25: 2 | O25: 8 | P25: 10 | Q25: 0.7 | R25: 0.7 | T25: 8 | U25: 0 | V25: 0 | W25: 2 | X25: =SUM(T25:W25) -> 10 | Y25: =IF(T25+U25=0,0,SUM(T25:U25)/X25) -> 0.8 | Z25: =IF(T25=0,0,T25/(SUM(T25:V25))) -> 1 | AA25: Delivered to Parallol UAT | AB25: =_xlfn.XLOOKUP(F25,'TFS Details'!F:F,'TFS Details'!I:I) -> Tech Ensemble | AC25: =_xlfn.XLOOKUP(AB25,'TFS Details'!I:I,'TFS Details'!AE:AE) -> suraj.sukumaran
A26: =_xlfn.XLOOKUP(F26,'TFS Details'!F:F,'TFS Details'!D:D) -> Online SI | B26: =_xlfn.XLOOKUP(F26,'TFS Details'!F:F,'TFS Details'!A:A) -> Standard Role Implementation in PCW & Online SI - April Release | C26: =_xlfn.XLOOKUP(F26,'TFS Details'!F:F,'TFS Details'!E:E) -> 4373911 | D26: Anand | E26: Rename existing 'Role Type' column in Staffing OU Template | F26: 4411451 | G26: Sairam | H26: Sneha | I26: Completed | J26: Completed | K26: In Progress | L26: Completed | M26: 10 | N26: 3 | O26: 1 | P26: 4 | Q26: 1 | R26: 0.9 | T26: 3 | U26: 0 | V26: 0 | W26: 0 | X26: =SUM(T26:W26) -> 3 | Y26: =IF(T26+U26=0,0,SUM(T26:U26)/X26) -> 1 | Z26: =IF(T26=0,0,T26/(SUM(T26:V26))) -> 1 | AA26: Delivered to UAT | AB26: =_xlfn.XLOOKUP(F26,'TFS Details'!F:F,'TFS Details'!I:I) -> TechAvengers | AC26: =_xlfn.XLOOKUP(AB26,'TFS Details'!I:I,'TFS Details'!AE:AE) -> mervinkumar.manickam
A27: =_xlfn.XLOOKUP(F27,'TFS Details'!F:F,'TFS Details'!D:D) -> SI - PCW | B27: =_xlfn.XLOOKUP(F27,'TFS Details'!F:F,'TFS Details'!A:A) -> Standard Role Implementation in PCW & Online SI - April Release | C27: =_xlfn.XLOOKUP(F27,'TFS Details'!F:F,'TFS Details'!E:E) -> 4373911 | D27: Anand | E27: PCW - Add Technology Role and Standard Role Column in Staffing Baseline to populate the Roles of SI, CON-CAS | F27: 4381707 | G27: Naveen S | H27: Viji | I27: Completed | J27: Completed | K27: Not Started | L27: Blocked | M27: 76 | N27: 12 | O27: 2 | P27: 14 | Q27: 0.8572 | R27: 1 | T27: 8 | U27: 3 | V27: 3 | W27: 0 | X27: =SUM(T27:W27) -> 14 | Y27: =IF(T27+U27=0,0,SUM(T27:U27)/X27) -> 0.78571429 | Z27: =IF(T27=0,0,T27/(SUM(T27:V27))) -> 0.57142857 | AA27: Bug 4462540(H), Bug 4462512(M) | AB27: =_xlfn.XLOOKUP(F27,'TFS Details'!F:F,'TFS Details'!I:I) -> Tech Ensemble | AC27: =_xlfn.XLOOKUP(AB27,'TFS Details'!I:I,'TFS Details'!AE:AE) -> suraj.sukumaran
A28: =_xlfn.XLOOKUP(F28,'TFS Details'!F:F,'TFS Details'!D:D) -> SI - PCW | B28: =_xlfn.XLOOKUP(F28,'TFS Details'!F:F,'TFS Details'!A:A) -> Standard Role Implementation in PCW & Online SI - April Release | C28: =_xlfn.XLOOKUP(F28,'TFS Details'!F:F,'TFS Details'!E:E) -> 4373911 | D28: Anand | E28: PCW - Add Role Type Column in Staffing Baseline to populate the Role Types for SI, CON-CAS, AMS, IMS and BPMS | F28: 4386371 | G28: Naveen S | H28: Sairam | I28: Completed | J28: Completed | K28: Not Started | L28: In Progress | M28: 71 | N28: 17 | O28: 0 | P28: 17 | Q28: 1 | R28: 1 | T28: 9 | U28: 0 | V28: 0 | W28: 4 | X28: =SUM(T28:W28) -> 13 | Y28: =IF(T28+U28=0,0,SUM(T28:U28)/X28) -> 0.69230769 | Z28: =IF(T28=0,0,T28/(SUM(T28:V28))) -> 1 | AA28: Delivered to UAT for Parallel testing | AB28: =_xlfn.XLOOKUP(F28,'TFS Details'!F:F,'TFS Details'!I:I) -> Tech Ensemble | AC28: =_xlfn.XLOOKUP(AB28,'TFS Details'!I:I,'TFS Details'!AE:AE) -> suraj.sukumaran
A29: =_xlfn.XLOOKUP(F29,'TFS Details'!F:F,'TFS Details'!D:D) -> SI - PCW | B29: =_xlfn.XLOOKUP(F29,'TFS Details'!F:F,'TFS Details'!A:A) -> Standard Role Implementation in PCW & Online SI - April Release | C29: =_xlfn.XLOOKUP(F29,'TFS Details'!F:F,'TFS Details'!E:E) -> 4373911 | D29: Anand | E29: PCW - Add Profile City Tier Column in Staffing Baseline to populate the Profile City Tier value for all profiles | F29: 4386372 | G29: Sneha | H29: Viji | I29: Completed | J29: Completed | K29: Not Started | L29: Completed | M29: 37 | N29: 15 | O29: 20 | P29: 20 | Q29: 0.8 | R29: 0.8 | T29: 20 | U29: 0 | V29: 0 | W29: 0 | X29: =SUM(T29:W29) -> 20 | Y29: =IF(T29+U29=0,0,SUM(T29:U29)/X29) -> 1 | Z29: =IF(T29=0,0,T29/(SUM(T29:V29))) -> 1 | AA29: Delivered to UAT | AB29: =_xlfn.XLOOKUP(F29,'TFS Details'!F:F,'TFS Details'!I:I) -> Tech Ensemble | AC29: =_xlfn.XLOOKUP(AB29,'TFS Details'!I:I,'TFS Details'!AE:AE) -> suraj.sukumaran
A30: =_xlfn.XLOOKUP(F30,'TFS Details'!F:F,'TFS Details'!D:D) -> SI - PCW | B30: =_xlfn.XLOOKUP(F30,'TFS Details'!F:F,'TFS Details'!A:A) -> Standard Role Implementation in PCW & Online SI - April Release | C30: =_xlfn.XLOOKUP(F30,'TFS Details'!F:F,'TFS Details'!E:E) -> 4373911 | D30: Anand | E30: PCW - Rename existing 'Role Type' column in PCW 8.7 Template and Show a warning message in PCW 8.6 template | F30: 4386373 | G30: Naveen S | H30: Sairam | I30: Completed | J30: Completed | K30: Not Started | L30: In Progress | M30: 51 | N30: 12 | O30: 0 | P30: 12 | Q30: 1 | R30: 1 | T30: 11 | U30: 1 | V30: 0 | W30: 0 | X30: =SUM(T30:W30) -> 12 | Y30: =IF(T30+U30=0,0,SUM(T30:U30)/X30) -> 1 | Z30: =IF(T30=0,0,T30/(SUM(T30:V30))) -> 0.91666667 | AA30: Bug 4462585(M) Delivered to UAT for parallel testing | AB30: =_xlfn.XLOOKUP(F30,'TFS Details'!F:F,'TFS Details'!I:I) -> Tech Ensemble | AC30: =_xlfn.XLOOKUP(AB30,'TFS Details'!I:I,'TFS Details'!AE:AE) -> suraj.sukumaran
A31: =_xlfn.XLOOKUP(F31,'TFS Details'!F:F,'TFS Details'!D:D) -> STD Role | B31: =_xlfn.XLOOKUP(F31,'TFS Details'!F:F,'TFS Details'!A:A) -> Standard Role Implementation in PCW & Online SI - April Release | C31: =_xlfn.XLOOKUP(F31,'TFS Details'!F:F,'TFS Details'!E:E) -> 4373911 | D31: Anand | E31: As a SA, I want the Technology Tier field to auto-populate based on the selected Technology - OU Changes | F31: 4386942 | G31: Viji | H31: Naveen S | I31: Completed | J31: Completed | K31: In Progress | L31: In Progress | M31: 35 | N31: 11 | O31: 5 | P31: 8 | Q31: 1 | R31: 0.8 | T31: 7 | U31: 1 | V31: 0 | W31: 0 | X31: =SUM(T31:W31) -> 8 | Y31: =IF(T31+U31=0,0,SUM(T31:U31)/X31) -> 1 | Z31: =IF(T31=0,0,T31/(SUM(T31:V31))) -> 0.875 | AA31: Bug id : 4462256(M), 4462256(M), Delivered to UAT | AB31: =_xlfn.XLOOKUP(F31,'TFS Details'!F:F,'TFS Details'!I:I) -> TechAvengers | AC31: =_xlfn.XLOOKUP(AB31,'TFS Details'!I:I,'TFS Details'!AE:AE) -> mervinkumar.manickam
A32: =_xlfn.XLOOKUP(F32,'TFS Details'!F:F,'TFS Details'!D:D) -> STD Role | B32: =_xlfn.XLOOKUP(F32,'TFS Details'!F:F,'TFS Details'!A:A) -> Standard Role Implementation in PCW & Online SI - April Release | C32: =_xlfn.XLOOKUP(F32,'TFS Details'!F:F,'TFS Details'!E:E) -> 4373911 | D32: Anand | E32: As a SA, auto-populate Profile City Tier from Rate Type in Staffing Baseline-OU Changes | F32: 4386944 | G32: Viji | H32: Sneha | I32: Completed | J32: Completed | K32: In Progress | L32: Completed | M32: 40 | N32: 10 | O32: 5 | P32: 9 | Q32: 1 | R32: 1 | T32: 9 | U32: 0 | V32: 0 | W32: 0 | X32: =SUM(T32:W32) -> 9 | Y32: =IF(T32+U32=0,0,SUM(T32:U32)/X32) -> 1 | Z32: =IF(T32=0,0,T32/(SUM(T32:V32))) -> 1 | AA32: Delivered to UAT | AB32: =_xlfn.XLOOKUP(F32,'TFS Details'!F:F,'TFS Details'!I:I) -> TechAvengers | AC32: =_xlfn.XLOOKUP(AB32,'TFS Details'!I:I,'TFS Details'!AE:AE) -> mervinkumar.manickam
A33: =_xlfn.XLOOKUP(F33,'TFS Details'!F:F,'TFS Details'!D:D) -> STD Role | B33: =_xlfn.XLOOKUP(F33,'TFS Details'!F:F,'TFS Details'!A:A) -> Standard Role Implementation in PCW & Online SI - April Release | C33: =_xlfn.XLOOKUP(F33,'TFS Details'!F:F,'TFS Details'!E:E) -> 4373911 | D33: Anand | E33: As a SA, add Technology & Standard Role columns in Staffing Baseline for auto-population/selection based on Tech Group & SSG.- OU changes | F33: 4386945 | G33: Sneha | H33: Sairam | I33: Completed | J33: Completed | K33: Not Started | L33: In Progress | M33: 54 | N33: 20 | O33: 26 | P33: 26 | Q33: 0.8 | R33: 0.8 | T33: 16 | U33: 6 | V33: 0 | W33: 4 | X33: =SUM(T33:W33) -> 26 | Y33: =IF(T33+U33=0,0,SUM(T33:U33)/X33) -> 0.84615385 | Z33: =IF(T33=0,0,T33/(SUM(T33:V33))) -> 0.72727273 | AA33: Bug : 4465961 (H) | AB33: =_xlfn.XLOOKUP(F33,'TFS Details'!F:F,'TFS Details'!I:I) -> TechWizards | AC33: =_xlfn.XLOOKUP(AB33,'TFS Details'!I:I,'TFS Details'!AE:AE) -> mervinkumar.manickam
A34: =_xlfn.XLOOKUP(F34,'TFS Details'!F:F,'TFS Details'!D:D) -> STD Role | B34: =_xlfn.XLOOKUP(F34,'TFS Details'!F:F,'TFS Details'!A:A) -> Standard Role Implementation in PCW & Online SI - April Release | C34: =_xlfn.XLOOKUP(F34,'TFS Details'!F:F,'TFS Details'!E:E) -> 4373911 | D34: Anand | E34: As a SA, I want the Technology Tier field to auto-populate based on the selected Technology | F34: 4359294 | G34: Naveen S | H34: Viji | I34: Completed | J34: Completed | K34: Not Started | L34: In Progress | M34: 53 | N34: 10 | O34: 0 | P34: 10 | Q34: 1 | R34: 1 | T34: 5 | U34: 0 | V34: 0 | W34: 5 | X34: =SUM(T34:W34) -> 10 | Y34: =IF(T34+U34=0,0,SUM(T34:U34)/X34) -> 0.5 | Z34: =IF(T34=0,0,T34/(SUM(T34:V34))) -> 1 | AB34: =_xlfn.XLOOKUP(F34,'TFS Details'!F:F,'TFS Details'!I:I) -> TechWizards | AC34: =_xlfn.XLOOKUP(AB34,'TFS Details'!I:I,'TFS Details'!AE:AE) -> mervinkumar.manickam
A35: =_xlfn.XLOOKUP(F35,'TFS Details'!F:F,'TFS Details'!D:D) -> Manage screen AMS VT Report link | B35: =_xlfn.XLOOKUP(F35,'TFS Details'!F:F,'TFS Details'!A:A) -> Moving current AMSVT to PBI AMSVT. | C35: =_xlfn.XLOOKUP(F35,'TFS Details'!F:F,'TFS Details'!E:E) -> 4446745 | D35: Devika | E35: As a AMS VT user, I want the AMSVT production URL to be updated in the Manage screen, So that the system redirects me to the correct AMSVT Link.. | F35: 4446747 | G35: Alekhya | H35: Chaitanya | I35: Completed | J35: Completed | K35: Not Started | L35: Completed | M35: 11 | N35: 3 | O35: 2 | P35: 3 | Q35: 1 | R35: 1 | T35: 3 | U35: 0 | V35: 0 | W35: 0 | X35: =SUM(T35:W35) -> 3 | Y35: =IF(T35+U35=0,0,SUM(T35:U35)/X35) -> 1 | Z35: =IF(T35=0,0,T35/(SUM(T35:V35))) -> 1 | AB35: =_xlfn.XLOOKUP(F35,'TFS Details'!F:F,'TFS Details'!I:I) -> GoRetro | AC35: =_xlfn.XLOOKUP(AB35,'TFS Details'!I:I,'TFS Details'!AE:AE) -> sowjanya.kari
A36: =_xlfn.XLOOKUP(F36,'TFS Details'!F:F,'TFS Details'!D:D) -> PMO reporting Layer | B36: =_xlfn.XLOOKUP(F36,'TFS Details'!F:F,'TFS Details'!A:A) -> Addition of "Mergers and Acquisitions" column in PMO Reporting layer | C36: =_xlfn.XLOOKUP(F36,'TFS Details'!F:F,'TFS Details'!E:E) -> 4458987 | D36: Devika | E36: As a user of the PMO Reporting layer report, I want to add a new column as "Mergers and Acquisitions" in report, so that I can see the newly added column data directly in the report. | F36: 4459023 | G36: Alekhya | H36: Chaitanya | I36: Completed | J36: Completed | K36: Not Started | L36: Not Started | M36: 10 | N36: 5 | O36: 4 | P36: 5 | Q36: 1 | R36: 1 | T36: 0 | U36: 0 | V36: 0 | W36: 0 | X36: =SUM(T36:W36) -> 0 | Y36: =IF(T36+U36=0,0,SUM(T36:U36)/X36) -> 0 | Z36: =IF(T36=0,0,T36/(SUM(T36:V36))) -> 0 | AB36: =_xlfn.XLOOKUP(F36,'TFS Details'!F:F,'TFS Details'!I:I) -> Cognilytics | AC36: =_xlfn.XLOOKUP(AB36,'TFS Details'!I:I,'TFS Details'!AE:AE) -> anil.kadiri
A37: =_xlfn.XLOOKUP(F37,'TFS Details'!F:F,'TFS Details'!D:D) -> LCM COTS Enhancements | B37: =_xlfn.XLOOKUP(F37,'TFS Details'!F:F,'TFS Details'!A:A) -> LCM Infra - COTs App Replatform | C37: =_xlfn.XLOOKUP(F37,'TFS Details'!F:F,'TFS Details'!E:E) -> 4386341 | D37: Vaidheki | E37: SI KDA Enhancement - COTS App Replatform Support | F37: 4446805 | G37: Keerthana | H37: Liharshini | I37: In Progress | J37: Not Started | K37: Not Started | L37: Not Started | T37: 0 | U37: 0 | V37: 0 | W37: 0 | X37: =SUM(T37:W37) -> 0 | Y37: =IF(T37+U37=0,0,SUM(T37:U37)/X37) -> 0 | Z37: =IF(T37=0,0,T37/(SUM(T37:V37))) -> 0 | AB37: =_xlfn.XLOOKUP(F37,'TFS Details'!F:F,'TFS Details'!I:I) -> myISP_IMS | AC37: =_xlfn.XLOOKUP(AB37,'TFS Details'!I:I,'TFS Details'!AE:AE) -> supriya.a.dhingra
A38: =_xlfn.XLOOKUP(F38,'TFS Details'!F:F,'TFS Details'!D:D) -> LCM COTS Enhancements | B38: =_xlfn.XLOOKUP(F38,'TFS Details'!F:F,'TFS Details'!A:A) -> LCM Infra - COTs App Replatform | C38: =_xlfn.XLOOKUP(F38,'TFS Details'!F:F,'TFS Details'!E:E) -> 4386341 | D38: Vaidheki | E38: MMP FFP Resource Template - COTS App Replatform Handling | F38: 4446806 | G38: Keerthana | H38: Liharshini | I38: In Progress | J38: Not Started | K38: Not Started | L38: Not Started | T38: 0 | U38: 0 | V38: 0 | W38: 0 | X38: =SUM(T38:W38) -> 0 | Y38: =IF(T38+U38=0,0,SUM(T38:U38)/X38) -> 0 | Z38: =IF(T38=0,0,T38/(SUM(T38:V38))) -> 0 | AB38: =_xlfn.XLOOKUP(F38,'TFS Details'!F:F,'TFS Details'!I:I) -> myISP_IMS | AC38: =_xlfn.XLOOKUP(AB38,'TFS Details'!I:I,'TFS Details'!AE:AE) -> supriya.a.dhingra
A39: =_xlfn.XLOOKUP(F39,'TFS Details'!F:F,'TFS Details'!D:D) -> LCM COTS Enhancements | B39: =_xlfn.XLOOKUP(F39,'TFS Details'!F:F,'TFS Details'!A:A) -> LCM Infra - COTs App Replatform | C39: =_xlfn.XLOOKUP(F39,'TFS Details'!F:F,'TFS Details'!E:E) -> 4386341 | D39: Vaidheki | E39: PCW Integration - COTS App Replatform Support | F39: 4446807 | G39: Keerthana | H39: Liharshini | I39: In Progress | J39: Not Started | K39: Not Started | L39: Not Started | T39: 0 | U39: 0 | V39: 0 | W39: 0 | X39: =SUM(T39:W39) -> 0 | Y39: =IF(T39+U39=0,0,SUM(T39:U39)/X39) -> 0 | Z39: =IF(T39=0,0,T39/(SUM(T39:V39))) -> 0 | AB39: =_xlfn.XLOOKUP(F39,'TFS Details'!F:F,'TFS Details'!I:I) -> myISP_IMS | AC39: =_xlfn.XLOOKUP(AB39,'TFS Details'!I:I,'TFS Details'!AE:AE) -> supriya.a.dhingra
A40: =_xlfn.XLOOKUP(F40,'TFS Details'!F:F,'TFS Details'!D:D) -> LCM COTS Enhancements | B40: =_xlfn.XLOOKUP(F40,'TFS Details'!F:F,'TFS Details'!A:A) -> LCM Infra - COTs App Replatform | C40: =_xlfn.XLOOKUP(F40,'TFS Details'!F:F,'TFS Details'!E:E) -> 4386341 | D40: Vaidheki | E40: Reverse Order Logic - LCM Infrastructure Migration | F40: 4446808 | G40: Keerthana | H40: Liharshini | I40: In Progress | J40: Not Started | K40: Not Started | L40: Not Started | T40: 0 | U40: 0 | V40: 0 | W40: 0 | X40: =SUM(T40:W40) -> 0 | Y40: =IF(T40+U40=0,0,SUM(T40:U40)/X40) -> 0 | Z40: =IF(T40=0,0,T40/(SUM(T40:V40))) -> 0 | AB40: =_xlfn.XLOOKUP(F40,'TFS Details'!F:F,'TFS Details'!I:I) -> myISP_IMS | AC40: =_xlfn.XLOOKUP(AB40,'TFS Details'!I:I,'TFS Details'!AE:AE) -> supriya.a.dhingra
...

Sheet TFS Details
A1: Parent Title | B1: mySP Initiative | C1: Sub Initiative | D1: TextVerification | E1: Parent | F1: ID | G1: Title | H1: State | I1: Node Name | J1: Testing POC | K1: Planned for PT Date | L1: Actual PT Date | M1: Planned UAT Date | N1: Actual UAT Date | O1: Assigned To | P1: Production Deployment Date | Q1: Story Points | R1: Original Estimate | S1: Priority | T1: ETA | U1: UT Results Attached | V1: Code Review Completed | W1: Created By | X1: Created Date | Y1: Tags | Z1: Area Path | AA1: Iteration Path | AB1: Plan | AC1: Remaining | AD1: TextVerification1 | AE1: ExternalRef ID
A2: Standard Role Implementation in PCW & Online SI - April Release | B2: Rapid Soln | C2: NextGen SI | D2: STD Role | E2: 4373911 | F2: 4359294 | G2: As a SA, I want the Technology Tier field to auto-populate based on the selected Technology | H2: PT In Test | I2: TechWizards | J2: B Gadad, Anand <anand.b.gadad@accenture.com> | K2: 46104.852 | L2: 46104.229 | M2: 46120.229 | O2: Sargurunathan, Naveenkumar <n.sargurunathan@accenture.com> | P2: 46130.229 | S2: 2 | U2: Yes | V2: Yes | W2: Ganesan, Mathangi <mathangi.a.ganesan@accenture.com> | X2: 46063.499 | Y2: Standard Role Configuration | Z2: AutomationProcess_29697\mySPIntegratedSolutionPlatform\TechWizards | AA2: AutomationProcess_29697\mySolutionPlannerIntegratedSolutionPlatform\R58 and R59\Sprint148 | AD2: Tech Tier | AE2: mervinkumar.manickam
A3: Standard Role Implementation in PCW & Online SI - April Release | B3: Rapid Soln | C3: NextGen SI | D3: STD Role | E3: 4373911 | F3: 4368862 | G3: As a SA I want to select standard role from an SSG-specific dropdown selection- OU changes | H3: Ready for Test | I3: TechWizards | J3: B Gadad, Anand <anand.b.gadad@accenture.com> | K3: 46101.229 | L3: 46104.229 | M3: 46115.229 | O3: Sivakumar, Vijayalakshmi <v.b.sivakumar@accenture.com> | P3: 46130.229 | Q3: 13 | S3: 2 | U3: Yes | V3: Yes | W3: Ganesan, Mathangi <mathangi.a.ganesan@accenture.com> | X3: 46069.469 | Z3: AutomationProcess_29697\mySPIntegratedSolutionPlatform\TechWizards | AA3: AutomationProcess_29697\mySolutionPlannerIntegratedSolutionPlatform\R58 and R59\Sprint148 | AD3: OU | AE3: mervinkumar.manickam
A4: Standard Role Implementation in SI Staffing Baseline - Analysis | B4: Rapid Soln | C4: NextGen SI | D4: SDL | E4: 4277501 | F4: 4371046 | G4: As a Solution Architect, I want to see dynamic target pricing parameters in SDL SI DL regardless of rate card configuration | H4: Ready for Test | I4: DevStormers | J4: B Gadad, Anand <anand.b.gadad@accenture.com> | K4: 46101.229 | L4: 46104.229 | M4: 46115.229 | O4: Malapati, Sai Sneha Latha <sai.sneha.l.malapati@accenture.com> | P4: 46130.229 | Q4: 1 | S4: 2 | U4: Yes | V4: Yes | W4: Ganesan, Mathangi <mathangi.a.ganesan@accenture.com> | X4: 46070.446 | Y4: April-2026; Enhancement; Export; reporting; SDL; SI-DL; Staffing | Z4: AutomationProcess_29697\mySPRapidSolutioning\DevStormers | AA4: AutomationProcess_29697 | AD4: STD role | AE4: mervinkumar.manickam
A5: Standard Role Implementation in PCW & Online SI - April Release | B5: Rapid Soln | C5: NextGen SI | D5: STD Role | E5: 4373911 | F5: 4372847 | G5: As a SA, add Technology & Standard Role columns in Staffing Baseline for auto-population/selection based on Tech Group & SSG. | H5: Ready for Test | I5: TechWizards | J5: B Gadad, Anand <anand.b.gadad@accenture.com> | K5: 46101.229 | L5: 46104.229 | M5: 46118.229 | O5: Malapati, Sai Sneha Latha <sai.sneha.l.malapati@accenture.com> | P5: 46130.229 | Q5: 5 | S5: 2 | U5: Yes | V5: Yes | W5: Ganesan, Mathangi <mathangi.a.ganesan@accenture.com> | X5: 46071.572 | Y5: Standard Role Configuration | Z5: AutomationProcess_29697\mySPIntegratedSolutionPlatform\TechWizards | AA5: AutomationProcess_29697\mySolutionPlannerIntegratedSolutionPlatform\R61\Sprint154 | AD5: tr | AE5: mervinkumar.manickam
A6: Standard Role Implementation in PCW & Online SI - April Release | B6: Platform Consolidation | C6: NextGen | D6: SI - PCW | E6: 4373911 | F6: 4381707 | G6: PCW - Add Technology Role and Standard Role Column in Staffing Baseline to populate the Roles of SI, CON-CAS | H6: PT In Test | I6: Tech Ensemble | J6: B Gadad, Anand <anand.b.gadad@accenture.com> | K6: 46113.062 | L6: 46101.229 | M6: 46115.229 | O6: Sargurunathan, Naveenkumar <n.sargurunathan@accenture.com> | P6: 46130.229 | Q6: 7 | S6: 2 | U6: Yes | V6: Yes | W6: Akbar Basha, Musrath <musrath.akbar.basha@accenture.com> | X6: 46073.503 | Y6: PCW | Z6: AutomationProcess_29697\mySPIntegratedSolutionPlatform\Tech Ensemble | AA6: AutomationProcess_29697\mySolutionPlannerIntegratedSolutionPlatform | AD6: DCTA | AE6: suraj.sukumaran
A7: Standard Role Implementation in PCW & Online SI - April Release | B7: Platform Consolidation | C7: NextGen | D7: SI - PCW | E7: 4373911 | F7: 4386371 | G7: PCW - Add Role Type Column in Staffing Baseline to populate the Role Types for SI, CON-CAS, AMS, IMS and BPMS | H7: PT In Test | I7: Tech Ensemble | J7: B Gadad, Anand <anand.b.gadad@accenture.com> | K7: 46113.062 | L7: 46101.229 | M7: 46118.229 | O7: Sargurunathan, Naveenkumar <n.sargurunathan@accenture.com> | P7: 46130.229 | Q7: 5 | S7: 2 | U7: Yes | V7: Yes | W7: Akbar Basha, Musrath <musrath.akbar.basha@accenture.com> | X7: 46074.09 | Y7: PCW | Z7: AutomationProcess_29697\mySPIntegratedSolutionPlatform\Tech Ensemble | AA7: AutomationProcess_29697\mySolutionPlannerIntegratedSolutionPlatform | AD7: DCTA | AE7: suraj.sukumaran
A8: Standard Role Implementation in PCW & Online SI - April Release | B8: Platform Consolidation | C8: NextGen | D8: SI - PCW | E8: 4373911 | F8: 4386372 | G8: PCW - Add Profile City Tier Column in Staffing Baseline to populate the Profile City Tier value for all profiles | H8: Ready for Test | I8: Tech Ensemble | J8: B Gadad, Anand <anand.b.gadad@accenture.com> | K8: 46113.062 | L8: 46101.229 | M8: 46118.229 | O8: Malapati, Sai Sneha Latha <sai.sneha.l.malapati@accenture.com> | P8: 46130.229 | Q8: 3 | S8: 2 | U8: Yes | V8: NA | W8: Akbar Basha, Musrath <musrath.akbar.basha@accenture.com> | X8: 46074.106 | Y8: PCW | Z8: AutomationProcess_29697\mySPIntegratedSolutionPlatform\Tech Ensemble | AA8: AutomationProcess_29697\mySolutionPlannerIntegratedSolutionPlatform | AD8: DCTA | AE8: suraj.sukumaran
A9: Standard Role Implementation in PCW & Online SI - April Release | B9: Platform Consolidation | C9: NextGen | D9: SI - PCW | E9: 4373911 | F9: 4386373 | G9: PCW - Rename existing 'Role Type' column in PCW 8.7 Template and Show a warning message in PCW 8.6 template | H9: PT In Test | I9: Tech Ensemble | J9: B Gadad, Anand <anand.b.gadad@accenture.com> | K9: 46113.062 | L9: 46101.229 | M9: 46115.229 | O9: Sargurunathan, Naveenkumar <n.sargurunathan@accenture.com> | P9: 46130.229 | Q9: 2 | S9: 2 | U9: Yes | V9: NA | W9: Akbar Basha, Musrath <musrath.akbar.basha@accenture.com> | X9: 46074.118 | Y9: PCW | Z9: AutomationProcess_29697\mySPIntegratedSolutionPlatform\Tech Ensemble | AA9: AutomationProcess_29697\mySolutionPlannerIntegratedSolutionPlatform | AD9: DCTA | AE9: suraj.sukumaran
A10: Standard Role Implementation in PCW & Online SI - April Release | B10: Rapid Soln | C10: NextGen SI | D10: STD Role | E10: 4373911 | F10: 4386942 | G10: As a SA, I want the Technology Tier field to auto-populate based on the selected Technology - OU Changes | H10: Ready for Test | I10: TechAvengers | J10: B Gadad, Anand <anand.b.gadad@accenture.com> | K10: 46101.229 | L10: 46104.229 | M10: 46115.229 | O10: Sivakumar, Vijayalakshmi <v.b.sivakumar@accenture.com> | P10: 46130.229 | Q10: 5 | S10: 2 | U10: Yes | V10: Yes | W10: Ganesan, Mathangi <mathangi.a.ganesan@accenture.com> | X10: 46076.476 | Z10: AutomationProcess_29697\mySPIntegratedSolutionPlatform\TechAvengers | AA10: AutomationProcess_29697 | AD10: Online SI | AE10: mervinkumar.manickam
A11: Standard Role Implementation in PCW & Online SI - April Release | B11: Rapid Soln | C11: NextGen SI | D11: STD Role | E11: 4373911 | F11: 4386944 | G11: As a SA, auto-populate Profile City Tier from Rate Type in Staffing Baseline-OU Changes | H11: Ready for Test | I11: TechAvengers | J11: B Gadad, Anand <anand.b.gadad@accenture.com> | K11: 46101.229 | L11: 46104.229 | M11: 46118.229 | O11: Sivakumar, Vijayalakshmi <v.b.sivakumar@accenture.com> | P11: 46130.229 | Q11: 3 | S11: 2 | U11: Yes | V11: Yes | W11: Ganesan, Mathangi <mathangi.a.ganesan@accenture.com> | X11: 46076.476 | Z11: AutomationProcess_29697\mySPIntegratedSolutionPlatform\TechAvengers | AA11: AutomationProcess_29697 | AD11: Online SI | AE11: mervinkumar.manickam
A12: Standard Role Implementation in PCW & Online SI - April Release | B12: Rapid Soln | C12: NextGen SI | D12: STD Role | E12: 4373911 | F12: 4386945 | G12: As a SA, add Technology & Standard Role columns in Staffing Baseline for auto-population/selection based on Tech Group & SSG.- OU changes | H12: Ready for Test | I12: TechWizards | J12: B Gadad, Anand <anand.b.gadad@accenture.com> | K12: 46101.229 | L12: 46104.229 | M12: 46118.229 | O12: Malapati, Sai Sneha Latha <sai.sneha.l.malapati@accenture.com> | P12: 46130.229 | Q12: 5 | S12: 2 | U12: Yes | V12: Yes | W12: Ganesan, Mathangi <mathangi.a.ganesan@accenture.com> | X12: 46076.476 | Z12: AutomationProcess_29697\mySPIntegratedSolutionPlatform\TechWizards | AA12: AutomationProcess_29697 | AD12: OU | AE12: mervinkumar.manickam
A13: MMP FFP Export update - April release | B13: Platform Consolidation | C13: NextGen SI | D13: PCW | E13: 4389877 | F13: 4368135 | G13: API - Enhance the defaulting logics to populate 'Accenture Role/Rate' in offline MMP FFP Export | H13: In Test | I13: TechAvatar | J13: B Gadad, Anand <anand.b.gadad@accenture.com> | K13: 46114.062 | L13: 46114.756 | M13: 46115.229 | O13: Pamarthi, Sairam <sairam.pamarthi@accenture.com> | P13: 46130.229 | Q13: 3 | S13: 2 | U13: Yes | V13: Yes | W13: Akbar Basha, Musrath <musrath.akbar.basha@accenture.com> | X13: 46066.858 | Y13: PCW | Z13: AutomationProcess_29697\mySPIntegratedSolutionPlatform\TechAvatar | AA13: AutomationProcess_29697\mySolutionPlannerIntegratedSolutionPlatform\R52 | AD13: MMP FFP | AE13: suraj.sukumaran
A14: Standard Role Implementation in PCW & Online SI - April Release | B14: Platform Consolidation | C14: NextGen | D14: SI - PCW | E14: 4373911 | F14: 4368224 | G14: API - Save the Technology Tier, Profile City Tier, Role Type, Technology Role and Standard Role from Staffing Baseline | H14: PT In Test | I14: TechAvatar | J14: B Gadad, Anand <anand.b.gadad@accenture.com> | K14: 46113.062 | L14: 46105.004 | M14: 46115.229 | O14: Sivakumar, Vijayalakshmi <v.b.sivakumar@accenture.com> | P14: 46130.229 | Q14: 5 | S14: 2 | U14: Yes | V14: Yes | W14: Akbar Basha, Musrath <musrath.akbar.basha@accenture.com> | X14: 46066.922 | Y14: PCW | Z14: AutomationProcess_29697\mySPIntegratedSolutionPlatform\TechAvatar | AA14: AutomationProcess_29697\mySolutionPlannerIntegratedSolutionPlatform | AD14: DCTA | AE14: suraj.sukumaran
A15: MMP FFP Export update - April release | B15: Platform Consolidation | C15: NextGen SI | D15: PCW | E15: 4389877 | F15: 4395067 | G15: PCW - Pass Role Type column to API as an input filter parameter for defaulting logics of offline MMP FFP Export | H15: In Test | I15: Tech Ensemble | J15: B Gadad, Anand <anand.b.gadad@accenture.com> | K15: 46114.062 | L15: 46114.756 | M15: 46115.229 | O15: Pamarthi, Sairam <sairam.pamarthi@accenture.com> | P15: 46130.229 | Q15: 3 | S15: 2 | U15: Yes | V15: Yes | W15: Akbar Basha, Musrath <musrath.akbar.basha@accenture.com> | X15: 46081.115 | Y15: PCW | Z15: AutomationProcess_29697\mySPIntegratedSolutionPlatform\Tech Ensemble | AA15: AutomationProcess_29697\mySolutionPlannerIntegratedSolutionPlatform\R52 | AD15: MMP FFP | AE15: suraj.sukumaran
A16: Standard Role Implementation in PCW & Online SI - April Release | B16: Platform Consolidation | C16: NextGen | D16: Online SI | E16: 4373911 | F16: 4411451 | G16: Rename existing 'Role Type' column in Staffing OU Template | H16: In Test | I16: TechAvengers | J16: B Gadad, Anand <anand.b.gadad@accenture.com> | K16: 46101.229 | L16: 46104.229 | M16: 46115.229 | O16: Pamarthi, Sairam <sairam.pamarthi@accenture.com> | P16: 46130.229 | Q16: 3 | S16: 2 | U16: Yes | V16: Yes | W16: Parivallal, Aiswarya <aiswarya.parivallal@accenture.com> | X16: 46086.806 | Z16: AutomationProcess_29697\mySPIntegratedSolutionPlatform\TechAvengers | AA16: AutomationProcess_29697\mySolutionPlannerIntegratedSolutionPlatform | AD16: Staffing OU | AE16: mervinkumar.manickam
A17: Angular upgrade version 19 to version 21 - 18th April | B17: Rapid Soln | C17: NextGen | D17: Drop 3 - Angular upgrade v19 to v21 | E17: 4429397 | F17: 4429530 | G17: As a myISP Solution Architect, I want to see the Cost Price Engine UI App migrated to Angular 21 | H17: Ready for Test | I17: MYISP_Revamp_UI | J17: Damodaran, J. <j.damodaran@accenture.com> | K17: 46114.851 | L17: 46114.947 | M17: 46122.229 | O17: Nanditha Uddaraju, Anuradha <a.nanditha.uddaraju@accenture.com> | P17: 46130.229 | Q17: 3 | S17: 2 | U17: Yes | V17: Yes | W17: Kamble, Pallavi <pallavi.kamble@accenture.com> | X17: 46097.802 | Y17: Angular upgrade v19 to v21; Cost Price Engine UI; PT Regression; UAT Testing Not Required | Z17: AutomationProcess_29697\mySPIntegratedSolutionPlatform\MYISP_Revamp_UI | AA17: AutomationProcess_29697\mySolutionPlannerIntegratedSolutionPlatform | AD17: Cost Price Engine UI | AE17: vikrant.r.mohite
A18: Available Hours OU Report | B18: Rapid Soln | C18: OCP | D18: AMS | E18: 4439196 | F18: 4439199 | G18: AMS OCP/DCTA: As a mySolutionPlanner developer, I should be able to get the Export/Import status tab in Available Hours screen | H18: Active | I18: TechMavericks | J18: Damodaran, J. <j.damodaran@accenture.com> | K18: 46120.917 | M18: 46121.021 | O18: Jallipalli, Nikhila <nikhila.jallipalli@accenture.com> | P18: 46130.229 | Q18: 3 | S18: 2 | W18: Vijay Deshpande, Prajakta <p.vijay.deshpande@accenture.com> | X18: 46104.728 | Y18: CCB Approved | Z18: AutomationProcess_29697\mySPRapidSolutioning\TechMavericks | AA18: AutomationProcess_29697\mySolutionPlannerIntegratedSolutionPlatform | AD18: AMS - Available Hours | AE18: Francis.Deepak
A19: Available Hours OU Report | B19: Rapid Soln | C19: OCP | D19: AMS | E19: 4439196 | F19: 4439323 | G19: AMS OCP/DCTA: As a mySolutionPlanner developer, I should be able to get the Export option in Available Hours template for Staffing | H19: Active | I19: TechCoders | J19: Damodaran, J. <j.damodaran@accenture.com> | K19: 46120.917 | M19: 46121.021 | O19: Anirudh, Channagiri <channagiri.anirudh@accenture.com> | P19: 46130.229 | Q19: 3 | S19: 2 | W19: Vijay Deshpande, Prajakta <p.vijay.deshpande@accenture.com> | X19: 46104.791 | Y19: CCB Approved | Z19: AutomationProcess_29697\mySPRapidSolutioning\TechCoders | AA19: AutomationProcess_29697\mySolutionPlannerIntegratedSolutionPlatform | AD19: AMS - Available Hours | AE19: Francis.Deepak
A20: Available Hours OU Report | B20: Rapid Soln | C20: OCP | D20: AMS | E20: 4439196 | F20: 4439343 | G20: AMS OCP/DCTA: As a mySolutionPlanner developer, I should be able to get the Export option in Available Hours template for PMO | H20: Active | I20: TechCoders | J20: Damodaran, J. <j.damodaran@accenture.com> | K20: 46120.917 | M20: 46121.021 | O20: Anirudh, Channagiri <channagiri.anirudh@accenture.com> | P20: 46130.229 | Q20: 3 | S20: 2 | W20: Vijay Deshpande, Prajakta <p.vijay.deshpande@accenture.com> | X20: 46104.816 | Y20: CCB Approved | Z20: AutomationProcess_29697\mySPRapidSolutioning\TechCoders | AA20: AutomationProcess_29697\mySolutionPlannerIntegratedSolutionPlatform | AD20: AMS - Available Hours | AE20: Francis.Deepak
A21: Available Hours OU Report | B21: Rapid Soln | C21: OCP | D21: AMS | E21: 4439196 | F21: 4439357 | G21: AMS OCP/DCTA: As a mySolutionPlanner developer, I should be able to get the Import option in Available Hours template for Staffing | H21: Active | I21: TechMavericks | J21: Damodaran, J. <j.damodaran@accenture.com> | K21: 46120.958 | M21: 46121.021 | O21: Vasant Pawar, Deepti <deepti.vasant.pawar@accenture.com> | P21: 46130.229 | Q21: 3 | S21: 2 | W21: Vijay Deshpande, Prajakta <p.vijay.deshpande@accenture.com> | X21: 46104.827 | Y21: CCB Approved | Z21: AutomationProcess_29697\mySPRapidSolutioning\TechMavericks | AA21: AutomationProcess_29697\mySolutionPlannerIntegratedSolutionPlatform | AD21: AMS - Available Hours | AE21: Francis.Deepak
A22: Available Hours OU Report | B22: Rapid Soln | C22: OCP | D22: AMS | E22: 4439196 | F22: 4439362 | G22: AMS OCP/DCTA: As a mySolutionPlanner developer, I should be able to get the Import option in Available Hours template for PMO | H22: Active | I22: TechMavericks | J22: Damodaran, J. <j.damodaran@accenture.com> | K22: 46120.958 | M22: 46121.021 | O22: Vasant Pawar, Deepti <deepti.vasant.pawar@accenture.com> | P22: 46130.229 | Q22: 3 | S22: 2 | W22: Vijay Deshpande, Prajakta <p.vijay.deshpande@accenture.com> | X22: 46104.838 | Y22: CCB Approved | Z22: AutomationProcess_29697\mySPRapidSolutioning\TechMavericks | AA22: AutomationProcess_29697\mySolutionPlannerIntegratedSolutionPlatform | AD22: AMS - Available Hours | AE22: Francis.Deepak
A23: Angular upgrade version 19 to version 21 - 18th April | B23: Rapid Soln | C23: NextGen | D23: Drop 3 - Angular upgrade v19 to v21 | E23: 4429397 | F23: 4429519 | G23: As a myISP Solution Architect, I want to see the Digital Documentation - MFE App migrated to Angular 21 | H23: PT In Test | I23: MYISP_Revamp_UI | J23: Das, Leena <leena.a.das@accenture.com> | K23: 46114.85 | L23: 46114.229 | M23: 46115.787 | N23: 46115.787 | O23: Udhayakumar, Harshitha <h.udhayakumar@accenture.com> | P23: 46130.229 | Q23: 3 | S23: 2 | U23: Yes | V23: Yes | W23: Kamble, Pallavi <pallavi.kamble@accenture.com> | X23: 46097.8 | Y23: Angular upgrade v19 to v21; Digital Documentation - MFE; PT Regression; UAT Testing Not Required | Z23: AutomationProcess_29697\mySPIntegratedSolutionPlatform\MYISP_Revamp_UI | AA23: AutomationProcess_29697\mySolutionPlannerIntegratedSolutionPlatform | AD23: Digital Documentation - MFE | AE23: vikrant.r.mohite
A24: DFD - Reinvention Partner field addition in SA request | B24: Platform Consolidation | C24: DFD | D24: DFD | E24: 4458972 | F24: 4458973 | G24: As a DFD requestor, I should get a Reinvention Partner dropdown in all the SA request forms | H24: New | I24: BackDoorGuardians | J24: Jain, Himanshu <himanshu.m.jain@accenture.com> | K24: 46122.979 | M24: 46128.229 | O24: Singh, Sudhakar <sudhakar.a.singh@accenture.com> | P24: 46130.229 | Q24: 5 | S24: 2 | W24: Vijay Deshpande, Prajakta <p.vijay.deshpande@accenture.com> | X24: 46113.807 | Y24: CCB Approved; Po Input | Z24: AutomationProcess_29697\BackDoorGuardians | AA24: AutomationProcess_29697\mySolutionPlannerIntegratedSolutionPlatform | AD24: DFD Enhancement | AE24: sona.job
A25: DFD - Reinvention Partner field addition in SA request | B25: Platform Consolidation | C25: DFD | D25: DFD | E25: 4458972 | F25: 4458985 | G25: AS a DFD requestor, I should get Reinvention partner field value in the existing SA requests | H25: Active | I25: BackDoorGuardians | J25: Jain, Himanshu <himanshu.m.jain@accenture.com> | K25: 46122.979 | M25: 46127.229 | O25: Mishra, Alok E. <alok.e.mishra@accenture.com> | P25: 46130.229 | Q25: 3 | S25: 2 | W25: Vijay Deshpande, Prajakta <p.vijay.deshpande@accenture.com> | X25: 46113.813 | Y25: CCB Approved; Po Input | Z25: AutomationProcess_29697\BackDoorGuardians | AA25: AutomationProcess_29697\mySolutionPlannerIntegratedSolutionPlatform | AD25: DFD Enhancement | AE25: sona.job
A26: DFD - Reinvention Partner field addition in SA request | B26: Platform Consolidation | C26: DFD | D26: DFD | E26: 4458972 | F26: 4458995 | G26: As a DFD requestor, I should get Reinvention Partner field in SA mail templates when request is created/edited | H26: Active | I26: BackDoorGuardians | J26: Jain, Himanshu <himanshu.m.jain@accenture.com> | K26: 46122.979 | M26: 46127.229 | O26: Thirumanikumar, Sneha <sneha.thirumanikumar@accenture.com> | P26: 46130.229 | Q26: 3 | S26: 2 | W26: Vijay Deshpande, Prajakta <p.vijay.deshpande@accenture.com> | X26: 46113.819 | Y26: CCB Approved; Po Input | Z26: AutomationProcess_29697\BackDoorGuardians | AA26: AutomationProcess_29697\mySolutionPlannerIntegratedSolutionPlatform | AD26: DFD Enhancement | AE26: sona.job
A27: Moving current AMSVT to PBI AMSVT. | B27: Platform Consolidation | C27: Analytics | D27: Manage screen AMS VT Report link | E27: 4446745 | F27: 4446747 | G27: As a AMS VT user, I want the AMSVT production URL to be updated in the Manage screen, So that the system redirects me to the correct AMSVT Link.. | H27: In Test | I27: GoRetro | J27: Kalaivanan, Devika <devika.kalaivanan@accenture.com> | K27: 46116.104 | L27: 46114.717 | M27: 46120.979 | N27: 46115.944 | O27: Alekhyareddy, Osuru <osuru.alekhyareddy@accenture.com> | P27: 46130.229 | S27: 2 | U27: Yes | V27: Yes | W27: Rani Agurla, Sowmya <sowmya.rani.agurla@accenture.com> | X27: 46108.843 | Y27: CCB Approved; UAT Testing Not Required | Z27: AutomationProcess_29697\mySPIntegratedSolutionPlatform\GoRetro | AA27: AutomationProcess_29697\mySolutionPlannerRapidSolutioning | AD27: AMS VT | AE27: sowjanya.kari
A28: Addition of "Mergers and Acquisitions" column in PMO Reporting layer | B28: Platform Consolidation | C28: Analytics | D28: PMO reporting Layer | E28: 4458987 | F28: 4459023 | G28: As a user of the PMO Reporting layer report, I want to add a new column as "Mergers and Acquisitions" in report, so that I can see the newly added column data directly in the report. | H28: Active | I28: Cognilytics | J28: Kalaivanan, Devika <devika.kalaivanan@accenture.com> | K28: 46119.229 | M28: 46122.229 | O28: Satravada, Rakesh <r.a.satravada@accenture.com> | P28: 46130.979 | Q28: 4 | S28: 2 | W28: Rani Agurla, Sowmya <sowmya.rani.agurla@accenture.com> | X28: 46113.824 | Y28: CCB Approved; Po Input; UAT Testing Not Required | Z28: AutomationProcess_29697\mySPIntegratedSolutionPlatform\Cognilytics | AA28: AutomationProcess_29697\mySolutionPlannerRapidSolutioning | AD28: Analytics | AE28: anil.kadiri
A29: Angular upgrade version 19 to version 21 - 18th April | B29: Rapid Soln | C29: NextGen | D29: Drop 3 - Angular upgrade v19 to v21 | E29: 4429397 | F29: 4429521 | G29: As a myISP Solution Architect, I want to see the CDAT - MFE App migrated to Angular 21 | H29: PT In Test | I29: MYISP_Revamp_UI | J29: Kalia Moorthy, Rajarajeswari <r.kalia.moorthy@accenture.com> | K29: 46114.85 | L29: 46114.95 | O29: Mohandass, Pavithra <p.mohandass@accenture.com> | P29: 46130.229 | Q29: 3 | S29: 2 | U29: Yes | V29: Yes | W29: Kamble, Pallavi <pallavi.kamble@accenture.com> | X29: 46097.801 | Y29: Angular upgrade v19 to v21; CDAT - MFE; PT Regression; UAT Testing Not Required | Z29: AutomationProcess_29697\mySPIntegratedSolutionPlatform\MYISP_Revamp_UI | AA29: AutomationProcess_29697\mySolutionPlannerIntegratedSolutionPlatform | AD29: CDAT - MFE | AE29: vikrant.r.mohite
A30: Angular upgrade version 19 to version 21 - 18th April | B30: Rapid Soln | C30: NextGen | D30: Drop 3 - Angular upgrade v19 to v21 | E30: 4429397 | F30: 4429413 | G30: As a myISP Solution Architect, I want to see the Solution Components (AMS) MFE App migrated to Angular 21 | H30: PT In Test | I30: MYISP_Revamp_UI | J30: Krishnan, Pirtheebaa <pirtheebaa.krishnan@accenture.com> | K30: 46114.851 | L30: 46115.021 | O30: Veluri, Janardhan <janardhan.veluri@accenture.com> | P30: 46130.229 | Q30: 3 | S30: 2 | U30: Yes | V30: Yes | W30: Kamble, Pallavi <pallavi.kamble@accenture.com> | X30: 46097.77 | Y30: Angular upgrade v19 to v21; PT Regression; Solution Components (AMS)-MFE; UAT Testing Not Required | Z30: AutomationProcess_29697\mySPIntegratedSolutionPlatform\MYISP_Revamp_UI | AA30: AutomationProcess_29697\mySolutionPlannerIntegratedSolutionPlatform | AD30: Solution Components (AMS) – MFE | AE30: vikrant.r.mohite
A31: Standard Role Implementation in PCW & Online SI - April Release | B31: Rapid Soln | C31: NextGen SI | D31: STD Role | E31: 4373911 | F31: 4368812 | G31: As a SA, add Role Type field in Staffing Baseline (auto-populated from Std Location Type & Service Group) - OU changes | H31: PT In Test | I31: TechWizards | J31: Selvamani, Kavichandrika <k.b.selvamani@accenture.com> | K31: 46101.229 | L31: 46104.229 | M31: 46120.979 | O31: Bid, Manisa <manisa.bid@accenture.com> | P31: 46130.229 | Q31: 13 | S31: 2 | U31: Yes | V31: Yes | W31: Ganesan, Mathangi <mathangi.a.ganesan@accenture.com> | X31: 46069.456 | Z31: AutomationProcess_29697\mySPIntegratedSolutionPlatform\TechWizards | AA31: AutomationProcess_29697\mySolutionPlannerIntegratedSolutionPlatform\R58 and R59\Sprint148 | AD31: role type ou | AE31: mervinkumar.manickam
