Workbook

Sheet insprint pivot
H1: Insprint Yes/No | I1: Yes | L1: Insprint Yes/No | M1: (Multiple Items) | O1: Module count for Mar 28 insprint
H2: PT Lead | I2: (All) | O2: PT lead | P2: No of US for insprint | Q2: Modules Count | R2: Module names | S2: ETA for pipeline readiness for Prod | T2: Excluded code from
A3: Count of Parent Title | B3: Column Labels | L3: Row Labels | M3: Count of Parent Title | O3: Pirtheebaa | P3: 20 | Q3: 11 | R3: PCAT Dashboard Learn SA Team manager View MMS Details Opportunity Workflow Manage SA Review Approval Transition To Delivery Define Team WRWS Estimators/Calculators | S3: completed
A4: Row Labels | B4: No | C4: Yes | D4: (blank) | E4: Partial | F4: Grand Total | I4: Values | L4: Power BI report validation | M4: 60 | O4: Himanshu | P4: 9 | Q4: 1 | R4: PLD | T4: no
A5: Anand | B5: 16 | C5: 6 | E5: 8 | F5: 30 | H5: Insprint Tester | I5: Count of Parent Title | J5: Average of If insprint YES - % of completion | L5: Complex user story which involves multiple screen validation and multiple roles validation and requires more time to automate | M5: 39 | O5: Shini | P5: 46 | Q5: 2 | R5: BPMS and DCSO | S5: Mar 24 EOD | T5: no
A6: Devika | B6: 59 | E6: 4 | F6: 63 | H6: k.tamilzharasu | I6: 2 | J6: 0.8 | L6: Fresh Deal creation required everytime | M6: 27 | O6: Anand | P6: 4 | Q6: 1 | R6: SI Online | S6: completed
A7: Hajara | B7: 26 | C7: 13 | D7: 1 | E7: 23 | F7: 63 | H7: r.maheen.abu.backer | I7: 3 | J7: 0.55 | L7: IMS BAU | M7: 20 | O7: Nandini | P7: 10 | Q7: 4 | R7: Estimator Calculator Workflow, Value Shaping, Asset Calculator,Automation Calculator | S7: PR pending
A8: Himanshu | B8: 5 | E8: 7 | F8: 12 | H8: nitish.kumar.prusty | I8: 2 | J8: 0.525 | L8: Technical US - Full regression Required | M8: 17 | O8: Hajara | P8: 11 | Q8: 1 | R8: GEN AI | S8: Mar 26 EOD
A9: Jaya | B9: 13 | C9: 4 | E9: 15 | F9: 32 | H9: s.boya.kumarii | I9: 1 | J9: 0.45 | L9: Complex KDA metrics validation in excel | M9: 16 | O9: Leena | P9: 21 | Q9: 1 | R9: DSP | S9: In progress
A10: Kavi | B10: 17 | C10: 2 | E10: 7 | F10: 26 | H10: sairam.pamarthi | I10: 3 | J10: 0.43333333 | L10: LLM Dynamic response generation User story which is not partially automatable | M10: 15 | O10: Jaya | P10: 6 | Q10: 1 | R10: AMS_OCP_DCTA | S10: completed
A11: Leena | B11: 27 | C11: 16 | E11: 31 | F11: 74 | H11: lakshmi.e.j | I11: 7 | J11: 0.41428571 | L11: PCW User Story | M11: 15 | O11: Kavi | P11: 3 | Q11: 2 | R11: SI OCP, DCTA-MMP | S11: completed | T11: pending 2 stories will not be considered . They can be run stand alone by insprint testers
A12: Nandini | B12: 42 | C12: 65 | E12: 33 | F12: 140 | H12: n.sargurunathan | I12: 1 | J12: 0.4 | L12: 200+ nudges validation and resposne time greater than 15 mins | M12: 11 | O12: Devika | P12: 0 | Q12: 0
A13: Omkar | B13: 7 | F13: 7 | H13: santhwana.m.r | I13: 3 | J13: 0.36666667 | L13: BPMS BAU | M13: 11 | O13: Raji | P13: 0 | Q13: 0
A14: Pirtheebaa | B14: 10 | C14: 37 | E14: 6 | F14: 53 | H14: nithish.mode | I14: 7 | J14: 0.31428571 | L14: Agent SCA Testing | M14: 9
A15: Rajeswari | B15: 18 | C15: 6 | F15: 24 | H15: karnati.aruna.jyothi | I15: 1 | J15: 0.3 | L15: MDA Power BI to DSP Integration | M15: 8
A16: Shini | B16: 17 | C16: 36 | E16: 6 | F16: 59 | H16: r.e.muthusamy | I16: 1 | J16: 0.3 | L16: Everytime new User validation | M16: 8
A17: Surbhi | B17: 4 | D17: 2 | F17: 6 | H17: amresh.l.kumar | I17: 1 | J17: 0.3 | L17: external Integration validation | M17: 8
A18: Vaidheki | B18: 20 | D18: 1 | F18: 21 | H18: sai.Priyanka.vasa | I18: 1 | J18: 0.25 | L18: User story validation for SM and Above career level | M18: 7
A19: Grand Total | B19: 281 | C19: 185 | D19: 4 | E19: 140 | F19: 610 | H19: shaik.yasin | I19: 1 | J19: 0.25 | L19: Complex User story will be delivered April 28th and not enough time to complete Insprint | M19: 5
H20: gayatri.korikana | I20: 2 | J20: 0.25 | L20: (blank) | M20: 4
H21: ganga.m.reddy.padala | I21: 4 | J21: 0.25 | L21: Removed Screen Validation cannot be automated because x path will not be found | M21: 3
H22: jeba.momin | I22: 2 | J22: 0.25 | L22: Basic email validation after just login | M22: 2
H23: pujitha.r.gogireddy | I23: 4 | J23: 0.2375 | L23: Grand Total | M23: 285
H24: m.sheik.fusulee.a | I24: 6 | J24: 0.23333333
H25: naga.v.pachipulusu | I25: 3 | J25: 0.21666667
H26: vignesh.jagathisan | I26: 3 | J26: 0.2
H27: bandi.sunanda | I27: 5 | J27: 0.2
H28: vadde.bindu | I28: 1 | J28: 0.2
H29: Saranya.datla | I29: 4 | J29: 0.2
H30: nalluri.vishnupriya | I30: 1 | J30: 0.2
H31: shivaprasad.malekar | I31: 2 | J31: 0.2
H32: arun.thangapandian | I32: 5 | J32: 0.19
H33: pawan.m.kumar.singh | I33: 2 | J33: 0.175
H34: Mary.jacob | I34: 5 | J34: 0.16
H35: s.af.natarajan | I35: 2 | J35: 0.15
... H71: Grand Total | I71: 185 | J71: 0.17567568

Sheet insprint
I1: Insprint Yes/No | J1: No
I2: PT Lead | J2: (All)
A3: Count of Title | B3: Column Labels
A4: Lead | B4: No | C4: Yes | D4: (blank) | E4: Partial | F4: Grand Total | I4: Predefined Reason | J4: Count of Title
A5: Anand | B5: 16 | C5: 6 | E5: 9 | F5: 31 | I5: Power BI report validation | J5: 60
A6: Devika | B6: 59 | E6: 4 | F6: 63 | I6: Complex user story which involves multiple screen validation and multiple roles validation and requires more time to automate | J6: 39
A7: Hajara | B7: 26 | C7: 13 | D7: 1 | E7: 23 | F7: 63 | I7: Fresh Deal creation required everytime | J7: 27
A8: Himanshu | B8: 5 | E8: 7 | F8: 12 | I8: IMS BAU | J8: 20
A9: Jaya | B9: 13 | C9: 4 | E9: 15 | F9: 32 | I9: Complex KDA metrics validation in excel | J9: 17
A10: Kavi | B10: 18 | C10: 2 | E10: 7 | F10: 27 | I10: Technical US - Full regression Required | J10: 17
A11: Leena | B11: 27 | C11: 16 | E11: 31 | F11: 74 | I11: LLM Dynamic response generation User story which is not partially automatable | J11: 15
A12: Nandini | B12: 42 | C12: 65 | E12: 33 | F12: 140 | I12: PCW User Story | J12: 15
A13: Pirtheebaa | B13: 10 | C13: 37 | E13: 6 | F13: 53 | I13: 200+ nudges validation and resposne time greater than 15 mins | J13: 11
A14: Rajeswari | B14: 18 | C14: 6 | F14: 24 | I14: BPMS BAU | J14: 11
A15: Shini | B15: 17 | C15: 38 | E15: 6 | F15: 61 | I15: Agent SCA Testing | J15: 9
A16: Grand Total | B16: 251 | C16: 187 | D16: 1 | E16: 141 | F16: 580 | I16: MDA Power BI to DSP Integration | J16: 8
I17: external Integration validation | J17: 8
I18: Everytime new User validation | J18: 8
I19: User story validation for SM and Above career level | J19: 7
I20: Complex User story will be delivered April 28th and not enough time to complete Insprint | J20: 5
I21: Removed Screen Validation cannot be automated because x path will not be found | J21: 3
I22: Basic email validation after just login | J22: 2
I23: Grand Total | J23: 282
A26: Insprint Yes/No | B26: Yes
A27: If insprint YES - % of completion | B27: 0
C29: Values
A30: PT Lead | B30: Insprint Tester | C30: Count of Title | D30: Average of If insprint YES - % of completion
A31: Hajara | B31: sujana.panigrahi | C31: 2 | D31: 0
B32: reshma.sundar | C32: 1 | D32: 0
A33: Leena | B33: Naveen.arunachalam | C33: 4 | D33: 0
B34: prasanna.pandian | C34: 1 | D34: 0
B35: navya.majji | C35: 5 | D35: 0
A36: Nandini | B36: bhavana.reddy.alla | C36: 1 | D36: 0
B37: r.yuvanitharsana | C37: 1 | D37: 0
B38: guddeti.srilekha | C38: 1 | D38: 0
A39: Pirtheebaa | B39: Manisha.m.sharma | C39: 6 | D39: 0
A40: Shini | B40: lakshmi.e.j | C40: 4 | D40: 0
A41: Grand Total | C41: 26 | D41: 0

Sheet Milestone
A1: User story Freeze Date | B1: Cut off for PT hand over | C1: Cut off for UAT hand over | D1: UAT Completion | E1: Functional Bug closure | F1: Regression | G1: Regression bug Closure | H1: Code Freeze | I1: Initial GNG decision | J1: Final Go/No Go Decision | K1: Final Go-Live
A2: 46111 | B2: 46134 | C2: 46140 | D2: 46147 | E2: 46147 | F2: 29-April to 4-May | G2: 46148 | H2: 46148 | I2: 46147 | J2: 46150 | K2: 46151

Sheet Detail1
A1: Details for Count of Title - Pre defined No Reason: Excel Validation, Insprint Yes/No: No, PT Lead: Anand (+)
A3: Module (TextVerification) | B3: Parent Title | C3: Feature ID | D3: PT Lead | E3: Title | F3: ID | G3: Primary tester | H3: Secondary Tester | I3: Insprint Tester | J3: Insprint Yes/No | K3: If Insprint NO - Reason | L3: Pre defined No Reason | M3: Complexity | N3: In sprint test case count | O3: If insprint YES - % of completion | P3: Automated cases generated from GHC | Q3: Useful Automated cases from GHC | R3: Tester created automated count (not given by GHC) | S3: Reviwed Final automation count | T3: Coverage for automated test case from GHC% | U3: Accuracy of Automated Test case from GHC% | V3: Test Planning | W3: BA Review | X3: TFS upload | Y3: PT Status | Z3: Manual Test cases generated from GHC | AA3: Useful Test cases from GHC | AB3: Tester Created test case count | AC3: Reviwed Final Test case count | AD3: Coverage for Manual Test cases from GHC% | AE3: Accuracy for Manual test cases from GHC% | AF3: TFS state | AG3: Passed | AH3: Failed | AI3: Blocked | AJ3: Not Run | AK3: Total | AL3: Execution % | AM3: Pass % | AN3: Comments | AO3: Node Name | AP3: MPOC
A4: DCSO | B4: myISP - Digital DCSO Summary sections addition and Other changes | C4: 4446711 | D4: Shini | E4: As a Solution Architect, I want imported DCSO editable fields retained when Generate is clicked again for IMS/AMS/SI and mandatory Excel header comments added, so that my data is preserved and the template is self-guiding | F4: 4462742 | G4: Arun | J4: No | K4: Excel inport export functionality | L4: Excel Validation | V4: Not Started | W4: Not Started | X4: Not Started | Y4: Not Started | AF4: New | AG4: 0 | AH4: 0 | AI4: 0 | AJ4: 0 | AK4: 0 | AL4: 0 | AM4: 0 | AO4: TechStars | AP4: mohanraj.a.selvaraj
A5: DCSO | B5: myISP - Digital DCSO Summary sections addition and Other changes | C5: 4446711 | D5: Shini | E5: As a DCSO user, I want the Skill Reference field in the DCSO template to be editable, mandatory and location-validated, so that the correct skill reference is always captured accurately and incorrect entries are flagged before submission | F5: 4451600 | G5: Shital | I5: s.manmit.vanarase | J5: No | K5: Excel Export Import Functionality | L5: Excel Validation | V5: Completed | W5: Completed | X5: Not Started | Y5: Not Started | AF5: New | AG5: 0 | AH5: 0 | AI5: 0 | AJ5: 0 | AK5: 0 | AL5: 0 | AM5: 0 | AO5: TechStars | AP5: mohanraj.a.selvaraj
A6: PCW | B6: PCW - IPC Toolkit Cost Update | C6: 4368214 | D6: Anand | E6: As a PCW user, I want IPC API integrations updated to align with the Differentiation screen decommissioning so that auto-sync workflows function via the new Attach Calculator DB. | F6: 4467805 | G6: Sairam | H6: Naveen S | J6: No | K6: PCW User Story | L6: Excel Validation
A7: PCW | B7: PCW - IPC Toolkit Cost Update | C7: 4368214 | D7: Anand | E7: As a PCW user, I want to see 3 new IPC exemption reasons in the 'Reasons for not configuring IPC' dropdown on the Pricing sheet so that the exemption rationale is captured consistently between PCW and myISP | F7: 4467788 | G7: Naveen S | H7: Sairam | J7: No | K7: PCW User Story | L7: Excel Validation
A8: myISP SI | B8: Expand format limit for staffing OU | C8: 4445149 | D8: Anand | E8: As a Solution Architect, I want the offline utility for the Staffing Baseline to support exporting and importing up to 5000 records, so that I can efficiently manage large staffing datasets without system or UI limitations. | F8: 4033020 | G8: Viji | H8: Sairam | J8: No | K8: Offline Utility OU related(Excel) Functionality Cannot be Automated | L8: Excel Validation | V8: In Progress | W8: Not Started | X8: Not Started | Y8: Not Started | AF8: New | AG8: 0 | AH8: 0 | AI8: 0 | AJ8: 0 | AK8: 0 | AL8: 0 | AM8: 0 | AO8: TechAvengers | AP8: mervinkumar.manickam
A9: Solution Review Agent | B9: [Gen AI - SRA] - Addition of Weighted average, Score, RAG columns in the Review Output Document. | C9: 4393834 | D9: Hajara | E9: [Gen AI - SRA] - Solution to Win Excel Checklist Upgrade - As a myISP User, I should be able to view additional columns in the Review Agent Output document displaying accurate RAG insights for L2-level nudges. | F9: 4392744 | G9: Pratik | H9: Vignesh | I9: p.haribhau.tadke | J9: No | K9: Excel Related functionality cannot be automated | L9: Excel Validation | V9: Completed | W9: Not Started | X9: Not Started | Y9: Not Started | AF9: New | AG9: 0 | AH9: 0 | AI9: 0 | AJ9: 5 | AK9: 5 | AL9: 0 | AM9: 0 | AO9: Gen AI - Solution Review Agent | AP9: n.d.krishnakumar
A10: Review Agent | B10: [SSA - SRA] - Displaying appropriate error messages when DSP ingestion failed. | C10: 4447242 | D10: Hajara | E10: [SSA - SRA] - As a MyISP user, I want to see the exact reason for a DSP ingestion failure displayed in the error message. | F10: 4447244 | G10: Harshitha | H10: Reshma | I10: h.udhayakumar | J10: No | K10: Upload functionality not feasible to automate | L10: Excel Validation | V10: In Progress | W10: Not Started | X10: Not Started | Y10: Not Started | AF10: New | AG10: 0 | AH10: 0 | AI10: 0 | AJ10: 12 | AK10: 12 | AL10: 0 | AM10: 0 | AO10: Gen AI - Solution Review Agent | AP10: n.d.krishnakumar
A11: CDAT | B11: CDAT Gen AI Enhancements. | C11: 4443461 | D11: Hajara | E11: As a myISP user, I want the assessment output to be downloaded in both Excel and Word format, so that I can analyze nudge data, findings, gap analysis, and document processing status | F11: 4429175 | G11: Narmatha | H11: Komal | I11: n.g.senthil.kumar | J11: No | K11: This involves the data validation in excel file, which is not feasible as we need to validate for all nudges in all 3 SG | L11: Excel Validation | V11: Not Started | W11: Not Started | X11: Not Started | Y11: Not Started | AF11: Active | AG11: 0 | AH11: 0 | AI11: 0 | AJ11: 0 | AK11: 0 | AL11: 0 | AM11: 0 | AO11: GENAI-CDAT | AP11: n.d.krishnakumar
A12: Value Shaping | B12: Value Shaping CR | May Scope | C12: 4446213 | D12: Nandini | E12: VS - As a myISP user I want Total Value Potential summary included in PDF and Excel downloads, So that exported artifacts retain the same value insights seen in the application. | F12: 4439529 | G12: Yasin | H12: Bindu | J12: No | K12: cannot automate, verifying downloaded PDF and excel data with UI | L12: Excel Validation | V12: Completed | W12: In Progress | X12: Not Started | Y12: Not Started | Z12: 35 | AA12: 27 | AC12: 27 | AF12: Active | AG12: 0 | AH12: 0 | AI12: 0 | AJ12: 0 | AK12: 0 | AL12: 0 | AM12: 0 | AO12: Spartans | AP12: nityanand.giri
A13: Value Shaping | B13: Value Shaping CR | May Scope | C13: 4446213 | D13: Nandini | E13: VS - As a myISP User I want the Benchmark Target tooltip to show the actual benchmark source, So that I can validate benchmark credibility directly while reviewing KPI details. | F13: 4438585 | G13: Yasin | H13: Bindu | J13: No | K13: cannot automate, verifying downloaded excel data with UI tool tip | L13: Excel Validation | V13: Completed | W13: In Progress | X13: Not Started | Y13: Not Started | Z13: 35 | AA13: 27 | AC13: 27 | AF13: Active | AG13: 0 | AH13: 0 | AI13: 0 | AJ13: 0 | AK13: 0 | AL13: 0 | AM13: 0 | AO13: Spartans | AP13: nityanand.giri
A14: IPC Calculator | B14: IPC Calculator | Package and Cost screen UI changes | C14: 4313249 | D14: Nandini | E14: As a mySP user, I should be able to see an auto created version of IPC from WRWS with updated cost in standard package when solution version is created for the first time | F14: 4372864 | G14: Srilekha | H14: Pawan | J14: No | K14: This story has a lot of calculation with dependancy on excel based validations | L14: Excel Validation | V14: In Progress | W14: Not Started | X14: Not Started | Y14: Not Started | AF14: New | AG14: 0 | AH14: 0 | AI14: 0 | AJ14: 0 | AK14: 0 | AL14: 0 | AM14: 0 | AO14: TechWarriors | AP14: sowjanya.kari
A15: Mobilization Calculator | B15: Mobilization Calculator -Bottom Up CRs | C15: 4232673 | D15: Nandini | E15: As a Mobilization SME, i should be able to see the Phase Wise Cost Summary in the Ramp Summary export | F15: 4368362 | G15: Reshmi | H15: Pawan | J15: No | K15: Excel template Import/Export related US and data validation | L15: Excel Validation | V15: Completed | W15: Not Started | X15: Not Started | Y15: Not Started | AF15: New | AG15: 0 | AH15: 0 | AI15: 0 | AJ15: 19 | AK15: 19 | AL15: 0 | AM15: 0 | AO15: Everest | AP15: nityanand.giri
A16: IPC Calculator | B16: IPC Calculator | Package and Cost screen UI changes | C16: 4313249 | D16: Nandini | E16: As a mySP user, I want to see the updated UI of Package and Cost screen due to the updated cost of standard package | F16: 4354055 | G16: Srilekha | H16: Pawan | J16: No | K16: It is completly new UI changes which included calculations using excel sheet | L16: Excel Validation | V16: In Progress | W16: Not Started | X16: Not Started | Y16: Not Started | AF16: Active | AG16: 0 | AH16: 0 | AI16: 0 | AJ16: 0 | AK16: 0 | AL16: 0 | AM16: 0 | AO16: TitansPlus | AP16: nityanand.giri
A17: Value Shaping | B17: Value Shaping –Enhancements | C17: 4330994 | D17: Nandini | E17: Value Shaping - As a myISP user, I should be able to download output (Global View) as excel from summary screen of SVP page, so that it can be used for other purposes | F17: 4318913 | G17: Bindu | H17: Yasin | J17: No | K17: cannot automate, verifying downloaded excel data with UI | L17: Excel Validation | V17: In Progress | W17: Not Started | X17: Not Started | Y17: Not Started | AF17: Active | AG17: 0 | AH17: 0 | AI17: 0 | AJ17: 0 | AK17: 0 | AL17: 0 | AM17: 0 | AO17: Spartans | AP17: nityanand.giri
A18: Value Shaping | B18: Value Shaping –Enhancements | C18: 4330994 | D18: Nandini | E18: Value Shaping - As a myISP user, I should be able to download output (Benchmark and size of prize View) as excel from summary screen of SVP page, so that it can be used for other purposes | F18: 4165234 | G18: Yasin | H18: Bindu | J18: No | K18: cannot automate, verifying downloaded excel data with UI | L18: Excel Validation | V18: Completed | W18: In Progress | X18: Not Started | Y18: Not Started | Z18: 35 | AA18: 29 | AC18: 29 | AF18: Active | AG18: 0 | AH18: 0 | AI18: 0 | AJ18: 0 | AK18: 0 | AL18: 0 | AM18: 0 | AO18: Spartans | AP18: nityanand.giri
A19: Value Shaping | B19: Value Shaping –Enhancements | C19: 4330994 | D19: Nandini | E19: Value Shaping - As a myISP user, I should be able to download output (Tree View) as excel from summary screen of SVP page, so that it can be used for other purposes | F19: 4165232 | G19: Yasin | H19: Bindu | J19: No | K19: cannot automate, verifying downloaded excel data with UI | L19: Excel Validation | V19: Completed | W19: In Progress | X19: Not Started | Y19: Not Started | Z19: 35 | AA19: 22 | AC19: 22 | AF19: Active | AG19: 0 | AH19: 0 | AI19: 0 | AJ19: 0 | AK19: 0 | AL19: 0 | AM19: 0 | AO19: Spartans | AP19: nityanand.giri
A20: Value Shaping | B20: Value Shaping –Enhancements | C20: 4330994 | D20: Nandini | E20: Value Shaping -As a myISP user, I should be able to download output (Tech Transformation View) as excel from summary screen of SVP page, so that it can be used for other purposes | F20: 4165224 | G20: Bindu | H20: Yasin | J20: No | K20: cannot automate, verifying downloaded excel data with UI | L20: Excel Validation | V20: Completed | W20: In Progress | X20: Not Started | Y20: Not Started | AF20: Active | AG20: 0 | AH20: 0 | AI20: 0 | AJ20: 0 | AK20: 0 | AL20: 0 | AM20: 0 | AO20: Spartans | AP20: nityanand.giri
A21: Value Shaping | B21: Value Shaping –Enhancements | C21: 4330994 | D21: Nandini | E21: Value Shaping - As a myISP user, I should be able to download output (Value Led AM View) as excel from summary screen of SVP page, so that it can be used for other purposes | F21: 4165212 | G21: Bindu | H21: Yasin | J21: No | K21: cannot automate, verifying downloaded excel data with UI | L21: Excel Validation | V21: Completed | W21: In Progress | X21: Not Started | Y21: Not Started | AF21: Active | AG21: 0 | AH21: 0 | AI21: 0 | AJ21: 0 | AK21: 0 | AL21: 0 | AM21: 0 | AO21: Spartans | AP21: nityanand.giri
A22: Value Shaping | B22: Value Shaping –Enhancements | C22: 4330994 | D22: Nandini | E22: Value Shaping - As a myISP user, I should be able to download output (360 Dimension View) as excel from summary screen of SVP page, so that it can be used for other purposes | F22: 4165210 | G22: Yasin | H22: Bindu | J22: No | K22: cannot automate, verifying downloaded excel data with UI | L22: Excel Validation | V22: Completed | W22: In Progress | X22: Not Started | Y22: Not Started | Z22: 57 | AA22: 32 | AC22: 32 | AF22: Active | AG22: 0 | AH22: 0 | AI22: 0 | AJ22: 0 | AK22: 0 | AL22: 0 | AM22: 0 | AO22: Spartans | AP22: nityanand.giri
A23: Calculator | B23: Attach Calculator | C23: 4372279 | D23: Nandini | E23: [Attach Calculator] AMS As a myISP user, I want to implement Document download functionality in Attach calculator, so that the Attach Calculator experience aligns with defined business standards | F23: 4367506 | G23: Amalarasi | H23: Sunanda | J23: No | K23: cannot automate, verifying downloaded excel data with UI | L23: Excel Validation | V23: In Progress | W23: Not Started | X23: Not Started | Y23: Not Started | AF23: Active | AG23: 0 | AH23: 0 | AI23: 0 | AJ23: 0 | AK23: 0 | AL23: 0 | AM23: 0 | AO23: TitansPlus | AP23: nityanand.giri
A24: SI | B24: Dynamic Target Pricing - Remaining Scope - May Release | C24: 4422839 | D24: Anand | E24: SI | As a SA, Role Type should be mandatory for applicable SSGs on Staffing Baseline - OU | F24: 4449779 | G24: Viji | H24: Sairam | J24: No | K24: Offline Utility OU related(Excel) Functionality Cannot be Automated | L24: Excel Validation | V24: In Progress | W24: Not Started | X24: Not Started | Y24: Not Started | AF24: In Development | AG24: 0 | AH24: 0 | AI24: 0 | AJ24: 0 | AK24: 0 | AL24: 0 | AM24: 0 | AO24: TechAvengers | AP24: mervinkumar.manickam
A25: CON-CAS - PCW | B25: Standard Role Implementation in PCW & Online SI - May Release | C25: 4436131 | D25: Anand | E25: PCW - Add Technology Role and Standard Role Columns in Staffing Baseline for CON-CAS | F25: 4450157 | G25: Naveen S | H25: Viji | J25: No | K25: PCW User Story | L25: Excel Validation | V25: In Progress | W25: Not Started | X25: Not Started | Y25: Not Started | AF25: New | AG25: 0 | AH25: 0 | AI25: 0 | AJ25: 0 | AK25: 0 | AL25: 0 | AM25: 0 | AO25: Tech Ensemble | AP25: mervinkumar.manickam
A26: AMS OCP | B26: AMS-OCP: AMS - Cluster based KDA Phase 1 - OCP KDA UI and Excel reports | C26: 4438595 | D26: Jaya | E26: AMS-OCP-View KDA Excel: As a mySolutionPlanner user, I want the KDA Excel download to include one additional tab per configured cluster showing the cluster-specific KDA matrix, So that use can view the updated View KDA excel report. | F26: 4449948 | G26: Ayush | H26: Anu | J26: No | K26: Export excels Validation | L26: Excel Validation | V26: Not Started | W26: Not Started | X26: Not Started | Y26: Not Started | AF26: Active | AG26: 0 | AH26: 0 | AI26: 0 | AJ26: 0 | AK26: 0 | AL26: 0 | AM26: 0 | AO26: CreativeCoders | AP26: K.devaraj
A27: BPMS OCP | B27: BPMS Negotiation Contingency | C27: 4446028 | D27: Jaya | E27: BPMS - As a myISP SA, I want to enter a negotiation contingency % in Solution Workbench so that the system calculates and displays the negotiation contingency value in Financials and sends it to all downstream modules. | F27: 4444316 | G27: Anu | H27: Ayush | J27: No | K27: cannot be automated, it involves calculation and excel reports validation | L27: Excel Validation | V27: Completed | W27: Completed | X27: Not Started | Y27: In Progress | Z27: 20 | AA27: 18 | AB27: 2 | AC27: 20 | AD27: 0.95 | AE27: 1 | AF27: PT In Test | AG27: 5 | AH27: 0 | AI27: 0 | AJ27: 15 | AK27: 20 | AL27: 0.25 | AM27: 1 | AO27: CreativeCoders | AP27: K.devaraj
A28: AMS | B28: AMS: Increasing Staffing records in LBS UI for OU report | C28: 4443033 | D28: Jaya | E28: AMS: As a mySolutionPlanner user, I want the Staffing screen LBS tab to display up to 4,000 records in the UI, So that the UI record display limit is aligned with the OU export and import limit of 4,000 records. | F28: 4443034 | G28: Priyanka | H28: Ayush | J28: No | K28: Export and import report of OU staffing cannot be validated | L28: Excel Validation | M28: Complex | V28: Completed | W28: In Progress | X28: Not Started | Y28: Not Started | Z28: 15 | AF28: New | AG28: 0 | AH28: 0 | AI28: 0 | AJ28: 0 | AK28: 0 | AL28: 0 | AM28: 0 | AO28: TechMavericks | AP28: Francis.Deepak
A29: BPMS DCTA | B29: BPMS Negotiation Contingency | C29: 4446028 | D29: Jaya | E29: As a myISP SA I want the Negotiation Contingency to be displayed on the Financials screen for DCTA route deals So that I can review the contingency buffer applied to pricing without switching to BPMS, enabling complete financial visibility in one view. | F29: 4440929 | G29: Jothika | H29: Anu | J29: No | K29: cannot be automated, it involves calculation and excel reports validation | L29: Excel Validation | V29: Completed | W29: Completed | X29: Not Started | Y29: In Progress | Z29: 20 | AA29: 20 | AB29: 0 | AC29: 20 | AD29: 1 | AE29: 1 | AF29: PT In Test | AG29: 5 | AH29: 0 | AI29: 0 | AJ29: 15 | AK29: 20 | AL29: 0.25 | AM29: 1 | AO29: Simulators | AP29: K.devaraj
A30: IMS Multi tower pricing | B30: IMS Multi Tower pricing (IMS+SI+CON) | C30: 4439712 | D30: Jaya | E30: IMS-OCP > CY/FY/MOM/Graph view reports: s a mySolutionPlanner user, I want the CY, FY, Month-on-Month (MoM), and Graph View reports to be enabled and available for SI (SI+CON) in addition to IMS, accessible at the deal level only (IMS or SI+CON) | F30: 4439840 | G30: Sriram | H30: Jothika | J30: No | K30: Excel Parts cannot be validated | L30: Excel Validation | V30: Not Started | W30: Not Started | X30: Not Started | Y30: Not Started | AF30: Active | AG30: 0 | AH30: 0 | AI30: 0 | AJ30: 0 | AK30: 0 | AL30: 0 | AM30: 0 | AO30: CodingCrusaders | AP30: K.devaraj
A31: DCSO | B31: myISP DCSO - Delivery Lead Assignments | C31: 4446526 | D31: Shini | E31: As a Delivery Lead, I want to be able to download and import DCSO files from the DCSO screen so that I can review, share and upload DCSO data without depending on other team members. | F31: 4445991 | G31: Arun | H31: Pavithra | I31: arun.thangapandian | J31: No | K31: Export Import Functionality | L31: Excel Validation | V31: Not Started | W31: Not Started | X31: Not Started | Y31: Not Started | AF31: New | AG31: 0 | AH31: 0 | AI31: 0 | AJ31: 0 | AK31: 0 | AL31: 0 | AM31: 0 | AO31: TechStars | AP31: mohanraj.a.selvaraj
A32: DCSO | B32: myISP - Digital DCSO Reports | C32: 4462171 | D32: Shini | E32: As a Solution Architect, I want to export DCSO Report data for offline sharing and analysis | F32: 4462198 | G32: Jeba | H32: Sakshi | I32: jeba.momin | J32: No | K32: Export data functionality | L32: Excel Validation | V32: Not Started | W32: Not Started | X32: Not Started | Y32: Not Started | AF32: New | AG32: 0 | AH32: 0 | AI32: 0 | AJ32: 0 | AK32: 0 | AL32: 0 | AM32: 0 | AO32: SolutionDataLake | AP32: vishal.v.nadpurohit
A33: DCSO | B33: myISP - Digital DCSO Summary sections addition and Other changes | C33: 4446711 | D33: Shini | E33: As a Solution Architect, I want Transition and SD resource line items to be merged into a single row when they belong to the same group in the DCSO report so that the report is concise and easier to review | F33: 4425029 | G33: Arun | H33: Shital | I33: arun.thangapandian | J33: No | K33: Export Import Functionality | L33: Excel Validation | V33: Not Started | W33: Not Started | X33: Not Started | Y33: Not Started | AF33: New | AG33: 0 | AH33: 0 | AI33: 0 | AJ33: 0 | AK33: 0 | AL33: 0 | AM33: 0 | AO33: TechStars | AP33: mohanraj.a.selvaraj
A34: DCSO | B34: myISP- Digital DCSO - Publish functionality | C34: 4420374 | D34: Shini | E34: **As a** Solution Architect **I want** the system to validate that each resource line's FTE Start Date is at least 16 calendar days ahead of the Publish Date when I click Publish **So that** Publish is successful | F34: 4422310 | G34: Mahesh | H34: Nithish | J34: No | K34: Excel sheet validation | L34: Excel Validation | V34: Completed | W34: Not Started | X34: Not Started | Y34: Not Started | AF34: In Development | AG34: 0 | AH34: 0 | AI34: 0 | AJ34: 0 | AK34: 0 | AL34: 0 | AM34: 0 | AO34: TechStars | AP34: mohanraj.a.selvaraj
A35: DCSO | B35: myISP- Digital DCSO - Publish functionality | C35: 4420374 | D35: Shini | E35: **As a** Solution Architect **I want** the Publish icon to be enabled only after a DCSO has been successfully imported **So that** I cannot accidentally publish incomplete or unimported DCSO data to the HR tool | F35: 4278131 | G35: Mahesh | H35: Nithish | J35: No | K35: Import Functionaity | L35: Excel Validation | V35: Completed | W35: Not Started | X35: Not Started | Y35: Not Started | AF35: In Development | AG35: 0 | AH35: 0 | AI35: 0 | AJ35: 0 | AK35: 4 | AL35: 0 | AM35: 0 | AO35: TechStars | AP35: mohanraj.a.selvaraj
A36: SI DCTA | B36: Billable expense parameter split in Financial UI | C36: 4446026 | D36: Kavi | E36: As a myISP SA, I want to view 6 billable expense metrics on the KDA screen for the DCTA route (same as OCP), so that I can accurately assess financials with and without billable expense for DCTA engagements. | F36: 4435817 | G36: Sohana | H36: Amresh | J36: No | K36: Require excel report validation | L36: Excel Validation | V36: Not Started | W36: Not Started | X36: Not Started | Y36: Not Started | AF36: Active | AG36: 0 | AH36: 0 | AI36: 0 | AJ36: 0 | AK36: 0 | AL36: 0 | AM36: 0 | AO36: Simulators | AP36: K.devaraj
A37: SI KDA | B37: WFH - ATCI and WFH ATCP to include updated logic from DNP | C37: 4250760 | D37: Kavi | E37: As a mysolution planner Solution Architect, I want the WFO details to fetch from SI DNP screen and update in SI KDA(DATA/MMP-FFP/OCP/DCTA KDA) So that user can view updated logic for WFH metrics in view KDA | F37: 4429069 | G37: Sai/Bhavana | H37: Sathya | J37: No | K37: Involves calculation & excel report validation is not possible | L37: Excel Validation | V37: Completed | W37: Completed | X37: Not Started | Y37: Not Started | Z37: 14 | AA37: 12 | AB37: 0 | AC37: 12 | AD37: 1 | AE37: 0.8 | AF37: Active | AG37: 0 | AH37: 0 | AI37: 0 | AJ37: 12 | AK37: 12 | AL37: 0 | AM37: 0 | AO37: Insurgents | AP37: K.devaraj
A38: IPC Calculator | B38: IPC Calculator | New Exemption Reasons | C38: 4428652 | D38: Kavi | E38: As a myISP user, I want Harmonized KDA to reflect the same IPC RAG outcome for the three new exemption reasons so that downstream governance reporting remains aligned. | F38: 4428664 | G38: Amresh | H38: Sohana | J38: No | K38: Require excel report validation | L38: Excel Validation | V38: Not Started | W38: Not Started | X38: Not Started | Y38: Not Started | AF38: Ready for Test | AG38: 0 | AH38: 0 | AI38: 0 | AJ38: 0 | AK38: 0 | AL38: 0 | AM38: 0 | AO38: Insurgents | AP38: K.devaraj
A39: Differentiation | B39: Differentiation Decommission | C39: 4372017 | D39: Kavi | E39: SI only- As a Solution Architect I want the Harmonized KDA report to consume Attach Calculator index score in place of Differentiation So that Harmonized KDA report data remains accurate after the Differentiation screen is decommissioned | F39: 4445144 | G39: Amresh | H39: Sohana | J39: No | K39: Require excel report validation | L39: Excel Validation | V39: Not Started | W39: Not Started | X39: Not Started | Y39: Not Started | AF39: Active | AG39: 0 | AH39: 0 | AI39: 0 | AJ39: 0 | AK39: 0 | AL39: 0 | AM39: 0 | AO39: Simulators | AP39: K.devaraj
A40: SI KDA | B40: WFH - ATCI and WFH ATCP to include updated logic from DNP | C40: 4250760 | D40: Kavi | E40: As a mysolution planner Solution Architect, I want the WFH ATCI and WFH ATCP fields in SI KDA(OCP KDA route) to include the updated logic from DNP, So that user can view updated logic for WFH metrics | F40: 4371721 | G40: Sai/Bhavana | H40: Sathya | J40: No | K40: Involves calculation & excel report validation is not possible | L40: Excel Validation | V40: Completed | W40: Completed | X40: Not Started | Y40: Not Started | Z40: 17 | AA40: 16 | AB40: 0 | AC40: 16 | AD40: 1 | AE40: 0.9 | AF40: Active | AG40: 0 | AH40: 0 | AI40: 0 | AJ40: 16 | AK40: 16 | AL40: 0 | AM40: 0 | AO40: Insurgents | AP40: K.devaraj
A41: SI KDA | B41: WFH - ATCI and WFH ATCP to include updated logic from DNP | C41: 4250760 | D41: Kavi | E41: As a Solution Architect , I want the YearonYear (YoY) values received from DNP to be updated in SI WFH metrics and displayed for existing deals, So that existing records correctly reflect YoY data from DNP | F41: 4367388 | G41: Sai/Bhavana | H41: Sathya | J41: No | K41: Involves calculation &excel report validation of YOY Split for all KDAs is not possible | L41: Excel Validation | V41: Completed | W41: Completed | X41: Not Started | Y41: Not Started | Z41: 16 | AA41: 14 | AB41: 0 | AC41: 14 | AD41: 1 | AE41: 0.8 | AF41: Active | AG41: 0 | AH41: 0 | AI41: 0 | AJ41: 14 | AK41: 14 | AL41: 0 | AM41: 0 | AO41: Insurgents | AP41: K.devaraj
...

Sheet PT status
A1: Module (TextVerification) | B1: Parent Title | C1: Feature ID | D1: PT Lead | E1: Title | F1: ID | G1: Primary Tester | H1: Secondary Tester | I1: Insprint Tester | J1: Insprint Yes/No | K1: If Insprint NO/Partial - Reason | L1: Pre defined No Reason | M1: Complexity | N1: In sprint test case count | O1: If insprint YES - % of completion | P1: Automated cases generated from GHC | Q1: Useful Automated cases from GHC | R1: Tester created automated count (not given by GHC) | S1: Reviewed Final automation count | T1: Coverage for automated test case from GHC% | U1: Accuracy of Automated Test case from GHC% | V1: Test Planning | W1: BA Review | X1: TFS upload | Y1: PT Status | Z1: Manual Test cases generated from GHC | AA1: Useful Test cases from GHC | AB1: Tester Created test case count | AC1: Reviwed Final Test case count | AD1: Coverage for Manual Test cases from GHC% | AE1: Accuracy for Manual test cases from GHC% | AF1: TFS state | AG1: Passed | AH1: Failed | AI1: Blocked | AJ1: Not Run | AK1: Total | AL1: Execution % | AM1: Pass % | AN1: Comments | AO1: Node Name | AP1: MPOC
A2: =_xlfn.XLOOKUP(F2,'TFS Details'!F:F,'TFS Details'!D:D) -> Learn | B2: =_xlfn.XLOOKUP(F2,'TFS Details'!F:F,'TFS Details'!A:A) -> Services - Learn & Launch enhancements with BPMS support button | C2: =_xlfn.XLOOKUP(F2,'TFS Details'!F:F,'TFS Details'!E:E) -> 4443474 | D2: Pirtheebaa | E2: As a myISP user, I want to see "BPMS" as a support option alongside AMS, SI, and IMS in both the "Email" and "Raise a Ticket" support sections on all 10-step screens. So that I can easily raise BPMS-related support requests. | F2: 4435598 | G2: Mary | H2: Janardhan/Sadhik | I2: Mary.jacob | J2: Partial | K2: Email Functionality included.Till email functionality we can automate | L2: Email validation | M2: Medium | N2: 5 | O2: 0.05 | P2: 20 | Q2: 5 | R2: 1 | V2: Completed | W2: Completed | X2: Completed | Y2: Completed | Z2: 55 | AA2: 11 | AB2: 0 | AC2: 11 | AD2: 0.95 | AE2: 0.8 | AF2: =_xlfn.XLOOKUP(F2,'TFS Details'!F:F,'TFS Details'!H:H) -> Test Complete | AG2: 11 | AH2: 0 | AI2: 0 | AJ2: 0 | AK2: =SUM(AG2:AJ2) -> 11 | AL2: =IF(AG2+AH2=0,0,SUM(AG2:AH2)/AK2) -> 1 | AM2: =IF(AG2=0,0,AG2/(SUM(AG2:AI2))) -> 1 | AO2: =_xlfn.XLOOKUP(F2,'TFS Details'!F:F,'TFS Details'!I:I) -> MYISP_Revamp_UI | AP2: =_xlfn.XLOOKUP(AO2,'TFS Details'!I:I,'TFS Details'!AE:AE) -> vikrant.r.mohite
A3: =_xlfn.XLOOKUP(F3,'TFS Details'!F:F,'TFS Details'!D:D) -> Common | B3: =_xlfn.XLOOKUP(F3,'TFS Details'!F:F,'TFS Details'!A:A) -> Security-specific services when the Opportunity RDE is set to "Security" | C3: =_xlfn.XLOOKUP(F3,'TFS Details'!F:F,'TFS Details'!E:E) -> 4443757 | D3: Pirtheebaa | E3: As an myISP user, I want the Scope Services/Offerings section to display only the security-specific services when the Opportunity RDE is set to "Security", So that users see only relevant AMS and SI security services. | F3: 4443754 | G3: Mary | H3: Janardhan/Sadhik | I3: Mary.jacob | J3: Yes | M3: Medium | N3: 5 | O3: 0.05 | P3: 20 | Q3: 5 | R3: 0 | V3: Completed | W3: Not Started | X3: Completed | Y3: Not Started | Z3: 50 | AA3: 9 | AB3: 1 | AC3: 10 | AD3: 0.95 | AE3: 0.8 | AF3: =_xlfn.XLOOKUP(F3,'TFS Details'!F:F,'TFS Details'!H:H) -> Active | AG3: 0 | AH3: 0 | AI3: 0 | AJ3: 10 | AK3: =SUM(AG3:AJ3) -> 10 | AL3: =IF(AG3+AH3=0,0,SUM(AG3:AH3)/AK3) -> 0 | AM3: =IF(AG3=0,0,AG3/(SUM(AG3:AI3))) -> 0 | AO3: =_xlfn.XLOOKUP(F3,'TFS Details'!F:F,'TFS Details'!I:I) -> TechWarriors | AP3: =_xlfn.XLOOKUP(AO3,'TFS Details'!I:I,'TFS Details'!AE:AE) -> Supriya.a.dhingra
A4: =_xlfn.XLOOKUP(F4,'TFS Details'!F:F,'TFS Details'!D:D) -> Common | B4: =_xlfn.XLOOKUP(F4,'TFS Details'!F:F,'TFS Details'!A:A) -> Market Maker Enterprise Solution Architect role from MMS in MMS Team Details | C4: =_xlfn.XLOOKUP(F4,'TFS Details'!F:F,'TFS Details'!E:E) -> 4443779 | D4: Pirtheebaa | E4: As a myISP User, I should be able to view the Market Maker Enterprise Solution Architect role from MMS in MMS Team Details so that team visibility and consistent across myISP | F4: 4443764 | G4: Mary | H4: Janardhan/Sadhik | I4: Mary.jacob | J4: Partial | K4: Partial as this US includes scenario where data should flow from MMS .Data available in UI can be verified in insprint automation | L4: external Integration validation | M4: Simple | N4: 5 | O4: 0.1 | P4: 20 | Q4: 5 | R4: 1 | V4: Completed | W4: Completed | X4: Completed | Y4: Completed | Z4: 40 | AA4: 7 | AB4: 0 | AC4: 7 | AD4: 0.95 | AE4: 0.8 | AF4: =_xlfn.XLOOKUP(F4,'TFS Details'!F:F,'TFS Details'!H:H) -> PT In Test | AG4: 7 | AH4: 0 | AI4: 0 | AJ4: 0 | AK4: =SUM(AG4:AJ4) -> 7 | AL4: =IF(AG4+AH4=0,0,SUM(AG4:AH4)/AK4) -> 1 | AM4: =IF(AG4=0,0,AG4/(SUM(AG4:AI4))) -> 1 | AO4: =_xlfn.XLOOKUP(F4,'TFS Details'!F:F,'TFS Details'!I:I) -> GoRetro | AP4: =_xlfn.XLOOKUP(AO4,'TFS Details'!I:I,'TFS Details'!AE:AE) -> sowjanya.kari
A5: =_xlfn.XLOOKUP(F5,'TFS Details'!F:F,'TFS Details'!D:D) -> PMO | B5: =_xlfn.XLOOKUP(F5,'TFS Details'!F:F,'TFS Details'!A:A) -> [PMO] URL update for Manage and Dashboard screens | C5: =_xlfn.XLOOKUP(F5,'TFS Details'!F:F,'TFS Details'!E:E) -> 4440976 | D5: Pirtheebaa | E5: [PMO] As a PMO user, I should be able to navigate to Manage / Dashboard screen with the new URL from Opportunity Workflow page | F5: 4443502 | G5: Vinayak | H5: Saranya | I5: Vinayak.Sangale | J5: Yes | M5: Simple | O5: 0.1 | V5: Completed | W5: Completed | X5: Completed | Y5: Not Started | AF5: =_xlfn.XLOOKUP(F5,'TFS Details'!F:F,'TFS Details'!H:H) -> Active | AG5: 0 | AH5: 0 | AI5: 0 | AJ5: 7 | AK5: =SUM(AG5:AJ5) -> 7 | AL5: =IF(AG5+AH5=0,0,SUM(AG5:AH5)/AK5) -> 0 | AM5: =IF(AG5=0,0,AG5/(SUM(AG5:AI5))) -> 0 | AO5: =_xlfn.XLOOKUP(F5,'TFS Details'!F:F,'TFS Details'!I:I) -> TechWarriors | AP5: =_xlfn.XLOOKUP(AO5,'TFS Details'!I:I,'TFS Details'!AE:AE) -> Supriya.a.dhingra
A6: =_xlfn.XLOOKUP(F6,'TFS Details'!F:F,'TFS Details'!D:D) -> PMO | B6: =_xlfn.XLOOKUP(F6,'TFS Details'!F:F,'TFS Details'!A:A) -> [PMO] URL update for Manage and Dashboard screens | C6: =_xlfn.XLOOKUP(F6,'TFS Details'!F:F,'TFS Details'!E:E) -> 4440976 | D6: Pirtheebaa | E6: [PMO] As a PMO user, I should be able to navigate to Manage / Dashboard screen with the new URL from Define Team | F6: 4443510 | G6: Vinayak | H6: Saranya | I6: Vinayak.Sangale | J6: Yes | M6: Simple | O6: 0.1 | V6: Completed | W6: Completed | X6: Completed | Y6: In Progress | AF6: =_xlfn.XLOOKUP(F6,'TFS Details'!F:F,'TFS Details'!H:H) -> PT In Test | AG6: 8 | AH6: 0 | AI6: 0 | AJ6: 4 | AK6: =SUM(AG6:AJ6) -> 12 | AL6: =IF(AG6+AH6=0,0,SUM(AG6:AH6)/AK6) -> 0.66666667 | AM6: =IF(AG6=0,0,AG6/(SUM(AG6:AI6))) -> 1 | AO6: =_xlfn.XLOOKUP(F6,'TFS Details'!F:F,'TFS Details'!I:I) -> TechPhantoms | AP6: =_xlfn.XLOOKUP(AO6,'TFS Details'!I:I,'TFS Details'!AE:AE) -> sowjanya.kari
A7: =_xlfn.XLOOKUP(F7,'TFS Details'!F:F,'TFS Details'!D:D) -> PMO | B7: =_xlfn.XLOOKUP(F7,'TFS Details'!F:F,'TFS Details'!A:A) -> [PMO] URL update for Manage and Dashboard screens | C7: =_xlfn.XLOOKUP(F7,'TFS Details'!F:F,'TFS Details'!E:E) -> 4440976 | D7: Pirtheebaa | E7: [PMO] As a PMO user, I should be able to navigate to Manage / Dashboard screen with the new URL from WRWS | F7: 4443516 | G7: Vinayak | H7: Saranya | I7: Vinayak.Sangale | J7: Yes | M7: Simple | O7: 0.1 | V7: Completed | W7: Completed | X7: Completed | Y7: Not Started | AF7: =_xlfn.XLOOKUP(F7,'TFS Details'!F:F,'TFS Details'!H:H) -> New | AG7: 0 | AH7: 0 | AI7: 0 | AJ7: 6 | AK7: =SUM(AG7:AJ7) -> 6 | AL7: =IF(AG7+AH7=0,0,SUM(AG7:AH7)/AK7) -> 0 | AM7: =IF(AG7=0,0,AG7/(SUM(AG7:AI7))) -> 0 | AO7: =_xlfn.XLOOKUP(F7,'TFS Details'!F:F,'TFS Details'!I:I) -> TechWarriors | AP7: =_xlfn.XLOOKUP(AO7,'TFS Details'!I:I,'TFS Details'!AE:AE) -> Supriya.a.dhingra
A8: =_xlfn.XLOOKUP(F8,'TFS Details'!F:F,'TFS Details'!D:D) -> PMO | B8: =_xlfn.XLOOKUP(F8,'TFS Details'!F:F,'TFS Details'!A:A) -> [PMO] URL update for Manage and Dashboard screens | C8: =_xlfn.XLOOKUP(F8,'TFS Details'!F:F,'TFS Details'!E:E) -> 4440976 | D8: Pirtheebaa | E8: [PMO] As a PMO user, I should be able to navigate to Manage screen with the new URL | F8: 4440990 | G8: Vinayak | H8: Saranya | I8: Saranya.datla | J8: Yes | M8: Simple | N8: 2 | O8: 0.2 | V8: Completed | W8: Completed | X8: Completed | Y8: Not Started | AF8: =_xlfn.XLOOKUP(F8,'TFS Details'!F:F,'TFS Details'!H:H) -> In Development | AG8: 0 | AH8: 0 | AI8: 0 | AJ8: 12 | AK8: =SUM(AG8:AJ8) -> 12 | AL8: =IF(AG8+AH8=0,0,SUM(AG8:AH8)/AK8) -> 0 | AM8: =IF(AG8=0,0,AG8/(SUM(AG8:AI8))) -> 0 | AO8: =_xlfn.XLOOKUP(F8,'TFS Details'!F:F,'TFS Details'!I:I) -> GoRetro | AP8: =_xlfn.XLOOKUP(AO8,'TFS Details'!I:I,'TFS Details'!AE:AE) -> sowjanya.kari
A9: =_xlfn.XLOOKUP(F9,'TFS Details'!F:F,'TFS Details'!D:D) -> PMO | B9: =_xlfn.XLOOKUP(F9,'TFS Details'!F:F,'TFS Details'!A:A) -> [PMO] URL update for Manage and Dashboard screens | C9: =_xlfn.XLOOKUP(F9,'TFS Details'!F:F,'TFS Details'!E:E) -> 4440976 | D9: Pirtheebaa | E9: [PMO] As a PMO user, I should be able to navigate to PMO Dashboard screen with the new URL | F9: 4441001 | G9: Vinayak | H9: Saranya | I9: Saranya.datla | J9: Yes | M9: Medium | N9: 2 | O9: 0.2 | V9: Completed | W9: Completed | X9: Completed | Y9: Not Started | AF9: =_xlfn.XLOOKUP(F9,'TFS Details'!F:F,'TFS Details'!H:H) -> In Development | AG9: 0 | AH9: 0 | AI9: 0 | AJ9: 4 | AK9: =SUM(AG9:AJ9) -> 4 | AL9: =IF(AG9+AH9=0,0,SUM(AG9:AH9)/AK9) -> 0 | AM9: =IF(AG9=0,0,AG9/(SUM(AG9:AI9))) -> 0 | AO9: =_xlfn.XLOOKUP(F9,'TFS Details'!F:F,'TFS Details'!I:I) -> GoRetro | AP9: =_xlfn.XLOOKUP(AO9,'TFS Details'!I:I,'TFS Details'!AE:AE) -> sowjanya.kari
A10: =_xlfn.XLOOKUP(F10,'TFS Details'!F:F,'TFS Details'!D:D) -> myCalendar | B10: =_xlfn.XLOOKUP(F10,'TFS Details'!F:F,'TFS Details'!A:A) -> myCalendar: Simplify calender funtionality for Solution Architect | C10: =_xlfn.XLOOKUP(F10,'TFS Details'!F:F,'TFS Details'!E:E) -> 4447848 | D10: Pirtheebaa | E10: **As a** Solution Architect, **I want** to verify that all fields sent from myCalendar to the SA Bandwidth Report continue to function correctly after the myCalendar revamp changes, **So that** the SA Bandwidth Report accurately reflects all related data | F10: 4467824 | G10: Mary | H10: Janardhan/Sadhik | I10: Vinayak.Sangale | J10: Yes | M10: Medium | O10: 0.05 | V10: Completed | W10: Not Started | X10: Completed | Y10: Not Started | Z10: 56 | AA10: 37 | AB10: 0 | AC10: 37 | AD10: 0.95 | AE10: 0.8 | AF10: =_xlfn.XLOOKUP(F10,'TFS Details'!F:F,'TFS Details'!H:H) -> Active | AG10: 0 | AH10: 0 | AI10: 0 | AJ10: 37 | AK10: =SUM(AG10:AJ10) -> 37 | AL10: =IF(AG10+AH10=0,0,SUM(AG10:AH10)/AK10) -> 0 | AM10: =IF(AG10=0,0,AG10/(SUM(AG10:AI10))) -> 0
A11: =_xlfn.XLOOKUP(F11,'TFS Details'!F:F,'TFS Details'!D:D) -> BPMS Onboarding | B11: =_xlfn.XLOOKUP(F11,'TFS Details'!F:F,'TFS Details'!A:A) -> Raise Request Email Template Standardization - Deal Value and Date Format | C11: =_xlfn.XLOOKUP(F11,'TFS Details'!F:F,'TFS Details'!E:E) -> 4441965 | D11: Pirtheebaa | E11: As a Business User, I should receive Raise Request emails with standardized deal value and date formats so that information is clear and consistent | F11: 4441959 | G11: Vinayak | H11: Saranya | J11: No | K11: All the Acceptance Criteria validation is required particularly in Email body templete so can not be automatable | L11: Basic email validation after just login | V11: Completed | W11: Completed | X11: Completed | Y11: In Progress | AF11: =_xlfn.XLOOKUP(F11,'TFS Details'!F:F,'TFS Details'!H:H) -> PT In Test | AG11: 5 | AH11: 0 | AI11: 0 | AJ11: 2 | AK11: =SUM(AG11:AJ11) -> 7 | AL11: =IF(AG11+AH11=0,0,SUM(AG11:AH11)/AK11) -> 0.71428571 | AM11: =IF(AG11=0,0,AG11/(SUM(AG11:AI11))) -> 1 | AO11: =_xlfn.XLOOKUP(F11,'TFS Details'!F:F,'TFS Details'!I:I) -> TechPhantoms | AP11: =_xlfn.XLOOKUP(AO11,'TFS Details'!I:I,'TFS Details'!AE:AE) -> sowjanya.kari
A12: =_xlfn.XLOOKUP(F12,'TFS Details'!F:F,'TFS Details'!D:D) -> Common | B12: =_xlfn.XLOOKUP(F12,'TFS Details'!F:F,'TFS Details'!A:A) -> Enter special characters, spaces, and bullet-point text for all 5 Opportunity on a Page questions | C12: =_xlfn.XLOOKUP(F12,'TFS Details'!F:F,'TFS Details'!E:E) -> 4441971 | D12: Pirtheebaa | E12: As a Business User, I should be able to enter special characters, spaces, and bullet-point text for all 5 Opportunity on a Page questions so that I can capture complete client context clearly | F12: 4441970 | G12: Mary | H12: Janardhan/Sadhik | I12: Mary.jacob | J12: Yes | M12: Medium | N12: 5 | O12: 0.05 | P12: 20 | Q12: 5 | R12: 1 | V12: Completed | W12: Not Started | X12: Completed | Y12: Not Started | Z12: 70 | AA12: 7 | AB12: 0 | AC12: 7 | AD12: 0.95 | AE12: 0.8 | AF12: =_xlfn.XLOOKUP(F12,'TFS Details'!F:F,'TFS Details'!H:H) -> Active | AG12: 0 | AH12: 0 | AI12: 0 | AJ12: 7 | AK12: =SUM(AG12:AJ12) -> 7 | AL12: =IF(AG12+AH12=0,0,SUM(AG12:AH12)/AK12) -> 0 | AM12: =IF(AG12=0,0,AG12/(SUM(AG12:AI12))) -> 0 | AO12: =_xlfn.XLOOKUP(F12,'TFS Details'!F:F,'TFS Details'!I:I) -> TechWarriors | AP12: =_xlfn.XLOOKUP(AO12,'TFS Details'!I:I,'TFS Details'!AE:AE) -> Supriya.a.dhingra
A13: =_xlfn.XLOOKUP(F13,'TFS Details'!F:F,'TFS Details'!D:D) -> Common | B13: =_xlfn.XLOOKUP(F13,'TFS Details'!F:F,'TFS Details'!A:A) -> Stage Update Date on the Timeline screen | C13: =_xlfn.XLOOKUP(F13,'TFS Details'!F:F,'TFS Details'!E:E) -> 4441973 | D13: Pirtheebaa | E13: As a Business User, I should see Stage Update Date on the Timeline screen under View MMS Details so that the latest stage change information is visible and fetched from the correct DB mapping | F13: 4441972 | G13: Mary | H13: Janardhan/Sadhik | I13: Mary.jacob | J13: Partial | K13: DB Change in UI we can just check the date is displaying or not as part of insprint | L13: Technical US - Full regression Required | M13: Simple | N13: 5 | O13: 0.4 | P13: 31 | Q13: 5 | R13: 0 | V13: Completed | W13: Completed | X13: Completed | Y13: Completed | Z13: 36 | AA13: 7 | AB13: 0 | AC13: 7 | AD13: 0.95 | AE13: 0.8 | AF13: =_xlfn.XLOOKUP(F13,'TFS Details'!F:F,'TFS Details'!H:H) -> Test Complete | AG13: 7 | AH13: 0 | AI13: 0 | AJ13: 0 | AK13: =SUM(AG13:AJ13) -> 7 | AL13: =IF(AG13+AH13=0,0,SUM(AG13:AH13)/AK13) -> 1 | AM13: =IF(AG13=0,0,AG13/(SUM(AG13:AI13))) -> 1 | AO13: =_xlfn.XLOOKUP(F13,'TFS Details'!F:F,'TFS Details'!I:I) -> GoRetro | AP13: =_xlfn.XLOOKUP(AO13,'TFS Details'!I:I,'TFS Details'!AE:AE) -> sowjanya.kari
A14: =_xlfn.XLOOKUP(F14,'TFS Details'!F:F,'TFS Details'!D:D) -> common | B14: =_xlfn.XLOOKUP(F14,'TFS Details'!F:F,'TFS Details'!A:A) -> Deal Hierarchy info text at the right-bottom of the MMS Details screen | C14: =_xlfn.XLOOKUP(F14,'TFS Details'!F:F,'TFS Details'!E:E) -> 4441977 | D14: Pirtheebaa | E14: As a Business User, I should see the Deal Hierarchy info text at the right-bottom of the MMS Details screen so that the message is visible without disturbing the data grid | F14: 4441975 | G14: Mary | H14: Janardhan/Sadhik | I14: Mary.jacob | J14: Yes | M14: Simple | N14: 5 | O14: 0.25 | P14: 21 | Q14: 5 | R14: 0 | V14: Completed | W14: Completed | X14: Completed | Y14: Completed | Z14: 56 | AA14: 14 | AB14: 0 | AC14: 14 | AD14: 0.95 | AE14: 0.8 | AF14: =_xlfn.XLOOKUP(F14,'TFS Details'!F:F,'TFS Details'!H:H) -> Test Complete | AG14: 14 | AH14: 0 | AI14: 0 | AJ14: 0 | AK14: =SUM(AG14:AJ14) -> 14 | AL14: =IF(AG14+AH14=0,0,SUM(AG14:AH14)/AK14) -> 1 | AM14: =IF(AG14=0,0,AG14/(SUM(AG14:AI14))) -> 1 | AO14: =_xlfn.XLOOKUP(F14,'TFS Details'!F:F,'TFS Details'!I:I) -> GoRetro | AP14: =_xlfn.XLOOKUP(AO14,'TFS Details'!I:I,'TFS Details'!AE:AE) -> sowjanya.kari
A15: =_xlfn.XLOOKUP(F15,'TFS Details'!F:F,'TFS Details'!D:D) -> PMO | B15: =_xlfn.XLOOKUP(F15,'TFS Details'!F:F,'TFS Details'!A:A) -> [PMO] URL update for Manage and Dashboard screens | C15: =_xlfn.XLOOKUP(F15,'TFS Details'!F:F,'TFS Details'!E:E) -> 4440976 | D15: Pirtheebaa | E15: [PMO] As a PMO user, I should be able to navigate to PMOInterimCreation(Sample Deal) screen with the new URL | F15: 4441883 | G15: Vinayak | H15: Saranya | I15: Saranya.datla | J15: Yes | M15: Medium | N15: 2 | O15: 0.2 | V15: Completed | W15: Completed | X15: Completed | Y15: Not Started | AF15: =_xlfn.XLOOKUP(F15,'TFS Details'!F:F,'TFS Details'!H:H) -> In Development | AG15: 0 | AH15: 0 | AI15: 0 | AJ15: 7 | AK15: =SUM(AG15:AJ15) -> 7 | AL15: =IF(AG15+AH15=0,0,SUM(AG15:AH15)/AK15) -> 0 | AM15: =IF(AG15=0,0,AG15/(SUM(AG15:AI15))) -> 0 | AO15: =_xlfn.XLOOKUP(F15,'TFS Details'!F:F,'TFS Details'!I:I) -> GoRetro | AP15: =_xlfn.XLOOKUP(AO15,'TFS Details'!I:I,'TFS Details'!AE:AE) -> sowjanya.kari
A16: =_xlfn.XLOOKUP(F16,'TFS Details'!F:F,'TFS Details'!D:D) -> SA Team manager | B16: =_xlfn.XLOOKUP(F16,'TFS Details'!F:F,'TFS Details'!A:A) -> SA Team manager UI updates.1. Capability to be autopopulate for Operations 2. Dependency of Deployment field for capability in left side slicer. | C16: =_xlfn.XLOOKUP(F16,'TFS Details'!F:F,'TFS Details'!E:E) -> 4441867 | D16: Pirtheebaa | E16: As a SA Team Manager user, I want Deployment, Capability, and Alignment fields to behave conditionally and dependently on the SA Team Manager screen so that selections are accurate and consistent. | F16: 4441886 | G16: Manisha | H16: Namrata | I16: Manisha.m.sharma | J16: Yes | M16: Medium | O16: 0 | V16: Completed | W16: Completed | X16: Not Started | Y16: In Progress | AF16: =_xlfn.XLOOKUP(F16,'TFS Details'!F:F,'TFS Details'!H:H) -> PT In Test | AG16: 0 | AH16: 0 | AI16: 0 | AJ16: 25 | AK16: =SUM(AG16:AJ16) -> 25 | AL16: =IF(AG16+AH16=0,0,SUM(AG16:AH16)/AK16) -> 0 | AM16: =IF(AG16=0,0,AG16/(SUM(AG16:AI16))) -> 0 | AO16: =_xlfn.XLOOKUP(F16,'TFS Details'!F:F,'TFS Details'!I:I) -> GoRetro | AP16: =_xlfn.XLOOKUP(AO16,'TFS Details'!I:I,'TFS Details'!AE:AE) -> sowjanya.kari
A17: =_xlfn.XLOOKUP(F17,'TFS Details'!F:F,'TFS Details'!D:D) -> SA Team manager | B17: =_xlfn.XLOOKUP(F17,'TFS Details'!F:F,'TFS Details'!A:A) -> SA Team manager UI updates.1. Capability to be autopopulate for Operations 2. Dependency of Deployment field for capability in left side slicer. | C17: =_xlfn.XLOOKUP(F17,'TFS Details'!F:F,'TFS Details'!E:E) -> 4441867 | D17: Pirtheebaa | E17: As a user registering through the Register Now pop‑up, I want conditional auto‑population and searchable alignment for Operations deployment so that I can complete registration accurately. | F17: 4441890 | G17: Manisha | H17: Namrata | J17: No | K17: Register Now is 1 time activity, which can't be enabled everytime in all the env's. Not feasible to automate | L17: Everytime new User validation | V17: Completed | W17: Completed | X17: Not Started | Y17: In Progress | AF17: =_xlfn.XLOOKUP(F17,'TFS Details'!F:F,'TFS Details'!H:H) -> Test Complete | AG17: 0 | AH17: 0 | AI17: 0 | AJ17: 0 | AK17: =SUM(AG17:AJ17) -> 0 | AL17: =IF(AG17+AH17=0,0,SUM(AG17:AH17)/AK17) -> 0 | AM17: =IF(AG17=0,0,AG17/(SUM(AG17:AI17))) -> 0 | AO17: =_xlfn.XLOOKUP(F17,'TFS Details'!F:F,'TFS Details'!I:I) -> GoRetro | AP17: =_xlfn.XLOOKUP(AO17,'TFS Details'!I:I,'TFS Details'!AE:AE) -> sowjanya.kari
A18: =_xlfn.XLOOKUP(F18,'TFS Details'!F:F,'TFS Details'!D:D) -> SA Team manager | B18: =_xlfn.XLOOKUP(F18,'TFS Details'!F:F,'TFS Details'!A:A) -> SA Team manager UI updates.1. Capability to be autopopulate for Operations 2. Dependency of Deployment field for capability in left side slicer. | C18: =_xlfn.XLOOKUP(F18,'TFS Details'!F:F,'TFS Details'!E:E) -> 4441867 | D18: Pirtheebaa | E18: As a PMO , I want conditional auto‑population and searchable alignment for Operations in pending user requests tab so that requests are reviewed and processed accurately. | F18: 4441892 | G18: Manisha | H18: Namrata | J18: No | K18: Register Now is 1 time activity, which can't be enabled everytime in all the env's. Not feasible to automate | L18: Everytime new User validation | V18: Completed | W18: Completed | X18: Not Started | Y18: In Progress | AF18: =_xlfn.XLOOKUP(F18,'TFS Details'!F:F,'TFS Details'!H:H) -> Test Complete | AG18: 0 | AH18: 0 | AI18: 0 | AJ18: 0 | AK18: =SUM(AG18:AJ18) -> 0 | AL18: =IF(AG18+AH18=0,0,SUM(AG18:AH18)/AK18) -> 0 | AM18: =IF(AG18=0,0,AG18/(SUM(AG18:AI18))) -> 0 | AO18: =_xlfn.XLOOKUP(F18,'TFS Details'!F:F,'TFS Details'!I:I) -> GoRetro | AP18: =_xlfn.XLOOKUP(AO18,'TFS Details'!I:I,'TFS Details'!AE:AE) -> sowjanya.kari
A19: =_xlfn.XLOOKUP(F19,'TFS Details'!F:F,'TFS Details'!D:D) -> myISP | B19: =_xlfn.XLOOKUP(F19,'TFS Details'!F:F,'TFS Details'!A:A) -> SI - Estimators/Calculators(Opp level screen) & Attach Estimates(Version level screen) - feedback alignment | C19: =_xlfn.XLOOKUP(F19,'TFS Details'!F:F,'TFS Details'!E:E) -> 4445141 | D19: Pirtheebaa | E19: As a Solution Architect, I want the Estimators screen's Create and Edit Estimator popups to have improved usability, So that I can efficiently view, enter, and review workstream hours without confusion or excessive scrolling. | F19: 4424629 | G19: Manisha | H19: Namrata | J19: No | K19: Realted to design changes need to check the column gaps between the grid .Not feasible to automate | L19: Everytime new User validation | V19: Completed | W19: Completed | X19: Not Started | Y19: Not Started | AF19: =_xlfn.XLOOKUP(F19,'TFS Details'!F:F,'TFS Details'!H:H) -> Active | AG19: 0 | AH19: 0 | AI19: 0 | AJ19: 0 | AK19: =SUM(AG19:AJ19) -> 0 | AL19: =IF(AG19+AH19=0,0,SUM(AG19:AH19)/AK19) -> 0 | AM19: =IF(AG19=0,0,AG19/(SUM(AG19:AI19))) -> 0 | AO19: =_xlfn.XLOOKUP(F19,'TFS Details'!F:F,'TFS Details'!I:I) -> TechWarriors | AP19: =_xlfn.XLOOKUP(AO19,'TFS Details'!I:I,'TFS Details'!AE:AE) -> Supriya.a.dhingra
A20: =_xlfn.XLOOKUP(F20,'TFS Details'!F:F,'TFS Details'!D:D) -> SA Team manager | B20: =_xlfn.XLOOKUP(F20,'TFS Details'!F:F,'TFS Details'!A:A) -> New user Registration for Song changes in SA team manager | C20: =_xlfn.XLOOKUP(F20,'TFS Details'!F:F,'TFS Details'!E:E) -> 4425959 | D20: Pirtheebaa | E20: As a PMO, I want Full Time SA, Reports to Lead, and Comments to be mandatory in Pending User Request tab so that incomplete registrations are not processed | F20: 4425965 | G20: Manisha | H20: Namrata | J20: No | K20: Register Now is 1 time activity, which can't be enabled everytime in all the env's. Not feasible to automate | L20: Everytime new User validation | V20: Completed | W20: Completed | X20: Not Started | Y20: In Progress | AF20: =_xlfn.XLOOKUP(F20,'TFS Details'!F:F,'TFS Details'!H:H) -> Test Complete | AG20: 0 | AH20: 0 | AI20: 0 | AJ20: 0 | AK20: =SUM(AG20:AJ20) -> 0 | AL20: =IF(AG20+AH20=0,0,SUM(AG20:AH20)/AK20) -> 0 | AM20: =IF(AG20=0,0,AG20/(SUM(AG20:AI20))) -> 0 | AO20: =_xlfn.XLOOKUP(F20,'TFS Details'!F:F,'TFS Details'!I:I) -> GoRetro | AP20: =_xlfn.XLOOKUP(AO20,'TFS Details'!I:I,'TFS Details'!AE:AE) -> sowjanya.kari
A21: =_xlfn.XLOOKUP(F21,'TFS Details'!F:F,'TFS Details'!D:D) -> SA Team manager | B21: =_xlfn.XLOOKUP(F21,'TFS Details'!F:F,'TFS Details'!A:A) -> New user Registration for Song changes in SA team manager | C21: =_xlfn.XLOOKUP(F21,'TFS Details'!F:F,'TFS Details'!E:E) -> 4425959 | D21: Pirtheebaa | E21: As an SA Team Manager, I want Full Time SA, Reports to Lead, and Comments to be mandatory in the SA Team Manager tab so that incomplete registrations are not processed | F21: 4425971 | G21: Manisha | H21: Namrata | I21: namrata.g.umardand | J21: Yes | M21: Complex | O21: 0.05 | V21: Completed | W21: Completed | X21: Not Started | Y21: In Progress | AF21: =_xlfn.XLOOKUP(F21,'TFS Details'!F:F,'TFS Details'!H:H) -> Test Complete | AG21: 0 | AH21: 0 | AI21: 0 | AJ21: 20 | AK21: =SUM(AG21:AJ21) -> 20 | AL21: =IF(AG21+AH21=0,0,SUM(AG21:AH21)/AK21) -> 0 | AM21: =IF(AG21=0,0,AG21/(SUM(AG21:AI21))) -> 0 | AO21: =_xlfn.XLOOKUP(F21,'TFS Details'!F:F,'TFS Details'!I:I) -> GoRetro | AP21: =_xlfn.XLOOKUP(AO21,'TFS Details'!I:I,'TFS Details'!AE:AE) -> sowjanya.kari
A22: =_xlfn.XLOOKUP(F22,'TFS Details'!F:F,'TFS Details'!D:D) -> myISP Enhancements | B22: =_xlfn.XLOOKUP(F22,'TFS Details'!F:F,'TFS Details'!A:A) -> March Release NextGen Enhancements | C22: =_xlfn.XLOOKUP(F22,'TFS Details'!F:F,'TFS Details'!E:E) -> 4365826 | D22: Pirtheebaa | E22: As a myISP User, I want to Add "Sync All from MMS" button for an Opportunity in (Opportunity On A Page) under WRWS to sync all 5 answers from MMS to myISP so that user can get the answers in in one go. | F22: 4358782 | G22: Vinayak | H22: Saranya | I22: Vinayak.Sangale | J22: Yes | M22: Medium | O22: 0.1 | V22: Completed | W22: Completed | X22: Completed | Y22: Not Started | AF22: =_xlfn.XLOOKUP(F22,'TFS Details'!F:F,'TFS Details'!H:H) -> Active | AG22: 0 | AH22: 0 | AI22: 0 | AJ22: 24 | AK22: =SUM(AG22:AJ22) -> 24 | AL22: =IF(AG22+AH22=0,0,SUM(AG22:AH22)/AK22) -> 0 | AM22: =IF(AG22=0,0,AG22/(SUM(AG22:AI22))) -> 0 | AO22: =_xlfn.XLOOKUP(F22,'TFS Details'!F:F,'TFS Details'!I:I) -> TechWarriors | AP22: =_xlfn.XLOOKUP(AO22,'TFS Details'!I:I,'TFS Details'!AE:AE) -> Supriya.a.dhingra
A23: =_xlfn.XLOOKUP(F23,'TFS Details'!F:F,'TFS Details'!D:D) -> WRWS | B23: =_xlfn.XLOOKUP(F23,'TFS Details'!F:F,'TFS Details'!A:A) -> Estimator/Calculator - Expand-Collapse icon Type and Position | C23: =_xlfn.XLOOKUP(F23,'TFS Details'!F:F,'TFS Details'!E:E) -> 4174547 | D23: Pirtheebaa | E23: As a myISP user I should be able to see expand and collapse icon in WRWS screen as per UI revamp standards | F23: 4174624 | G23: Vinayak | H23: Saranya | I23: Mary.jacob | J23: Yes | M23: Simple | N23: 15 | O23: 0.4 | P23: 28 | Q23: 14 | R23: 1 | S23: 15 | T23: 0.95 | U23: 0.9 | V23: Completed | W23: Completed | X23: Completed | Y23: Not Started | AF23: =_xlfn.XLOOKUP(F23,'TFS Details'!F:F,'TFS Details'!H:H) -> Active | AG23: 0 | AH23: 0 | AI23: 0 | AJ23: 10 | AK23: =SUM(AG23:AJ23) -> 10 | AL23: =IF(AG23+AH23=0,0,SUM(AG23:AH23)/AK23) -> 0 | AM23: =IF(AG23=0,0,AG23/(SUM(AG23:AI23))) -> 0 | AO23: =_xlfn.XLOOKUP(F23,'TFS Details'!F:F,'TFS Details'!I:I) -> TechWarriors | AP23: =_xlfn.XLOOKUP(AO23,'TFS Details'!I:I,'TFS Details'!AE:AE) -> Supriya.a.dhingra
A24: =_xlfn.XLOOKUP(F24,'TFS Details'!F:F,'TFS Details'!D:D) -> myISP Enhancements | B24: =_xlfn.XLOOKUP(F24,'TFS Details'!F:F,'TFS Details'!A:A) -> March Release NextGen Enhancements | C24: =_xlfn.XLOOKUP(F24,'TFS Details'!F:F,'TFS Details'!E:E) -> 4365826 | D24: Pirtheebaa | E24: As a myISP User, I want to view the definitions of the various "Service "on Hover in Service / Offerings section under WRWS so that acceptance criteria are achieved | F24: 4271493 | G24: Vinayak | H24: Saranya | I24: Saranya.datla | J24: Yes | M24: Medium | N24: 2 | O24: 0.2 | V24: Completed | W24: Completed | X24: Completed | Y24: Not Started | AF24: =_xlfn.XLOOKUP(F24,'TFS Details'!F:F,'TFS Details'!H:H) -> Active | AG24: 0 | AH24: 0 | AI24: 0 | AJ24: 9 | AK24: =SUM(AG24:AJ24) -> 9 | AL24: =IF(AG24+AH24=0,0,SUM(AG24:AH24)/AK24) -> 0 | AM24: =IF(AG24=0,0,AG24/(SUM(AG24:AI24))) -> 0 | AO24: =_xlfn.XLOOKUP(F24,'TFS Details'!F:F,'TFS Details'!I:I) -> TechWarriors | AP24: =_xlfn.XLOOKUP(AO24,'TFS Details'!I:I,'TFS Details'!AE:AE) -> Supriya.a.dhingra
